Workbook

Sheet NOTE
A2: NOTE
A3: This is the Excel sheet for the leaching analysis for c-Se-PS-MNPs 10 ppm in rear water
A4: 1) "Leaching test 10 ppm c-Se" sheet are the measured weights during the 35 days test, dilutions for the ICP-MS are also included
A5: 2) "Concentrations analysis" sheet provide the post ICP-MS calculations for Figure 4 ab and Figure S9

Sheet Leaching test 10 ppm c-Se
A1: Dilutions | B1: C-Se-PS-MNPs | G1: Day 0 | K1: Day 3 | P1: Day 7 | U1: Day 14 | Z1: Day 21 | AE1: Day 28 | AJ1: Day 35
B2: C1 (ppm) | C2: C2(ppm) | D2: V1 (mL) | E2: V2 (mL) | G2: Weight (g) | H2: extracted (g) | I2: actual (g) | J2: new weight | K2: Weight (g) | L2: Adjusted weight (g) | M2: extracted (g) | N2: Actual (g) | O2: New weight | P2: Weight (g) | Q2: Adjusted weight (g) | R2: extracted (g) | S2: Actual (g) | T2: New weight | U2: Weight (g) | V2: Adjusted weight (g) | W2: extracted (g) | X2: Actual (g) | Y2: New weight | Z2: Weight (g) | AA2: Adjusted weight (g) | AB2: extracted (g) | AC2: Actual (g) | AD2: New weight | AE2: Weight (g) | AF2: Adjusted weight (g) | AG2: extracted (g) | AH2: Actual (g) | AI2: New weight | AJ2: Weight (g) | AK2: Adjusted weight (g) | AL2: extracted (g) | AM2: Actual (g) | AN2: New weight
A3: Blk1 | B3: - | G3: 116.59 | H3: 5.11 | I3: 4.92 | J3: 111.47 | K3: 111.23 | L3: 111.46 | M3: 5.03 | N3: 4.79 | O3: =L3-M3 -> 106.43 | P3: 106.14 | Q3: 106.43 | R3: 4.96 | S3: 4.83 | T3: 101.44 | U3: 100.88 | V3: 101.51 | W3: 5.05 | X3: 4.92 | Y3: 96.46 | Z3: 95.35 | AA3: 96.5 | AB3: 5.03 | AC3: 5.06 | AD3: 91.45 | AE3: 90.61 | AF3: 91.43 | AG3: 5.01 | AH3: 4.92 | AI3: 86.42 | AJ3: 84.69 | AK3: 86.45 | AL3: 5.02 | AM3: 4.96 | AN3: 81.45
A4: Blk2 | B4: - | G4: 116.7 | H4: 5.02 | I4: 4.93 | J4: 111.64 | K4: 111.49 | L4: 111.64 | M4: 5.04 | N4: 4.86 | O4: =L4-M4 -> 106.6 | P4: 106.4 | Q4: 106.59 | R4: 4.96 | S4: 4.71 | T4: 101.62 | U4: 100.93 | V4: 101.55 | W4: 5.02 | X4: 4.87 | Y4: 96.53 | Z4: 95.75 | AA4: 96.52 | AB4: 5 | AC4: 4.88 | AD4: 91.5 | AE4: 90.21 | AF4: 91.52 | AG4: 5.02 | AH4: 4.93 | AI4: 83.43 | AJ4: 85.61 | AK4: 86.42 | AL4: 5.04 | AM4: 4.86 | AN4: 81.35
A5: 0.5S1 | B5: 426 | C5: 10 | D5: =C5*E5/B5 -> 2.3474178 | E5: 100 | G5: 116.33 | H5: 5.02 | I5: 4.67 | J5: 111.27 | K5: 111 | L5: 111.27 | M5: 5.04 | N5: 4.82 | O5: =L5-M5 -> 106.23 | P5: 105.96 | Q5: 106.24 | R5: 4.97 | S5: 5.24 | T5: 101.27 | U5: 100.76 | V5: 101.27 | W5: 5.04 | X5: 4.95 | Y5: 96.25 | Z5: 95.59 | AA5: 96.37 | AB5: 4.96 | AC5: 4.83 | AD5: 91.39 | AE5: 90.59 | AF5: 91.36 | AG5: 5.03 | AH5: 5.02 | AI5: 86.46 | AJ5: 85.64 | AK5: 86.46 | AL5: 5.07 | AM5: 5.02 | AN5: 81.38
A6: 0.5S2 | B6: 426 | C6: 10 | D6: =C6*E6/B6 -> 2.3474178 | E6: 100 | G6: 116.62 | H6: 5.02 | I6: 4.85 | J6: 111.58 | K6: 111.42 | L6: 111.59 | M6: 5.02 | N6: 4.8 | O6: =L6-M6 -> 106.57 | P6: 106.34 | Q6: 106.55 | R6: 4.99 | S6: 4.75 | T6: 101.57 | U6: 100.86 | V6: 101.59 | W6: 4.96 | X6: 4.89 | Y6: 96.6 | Z6: 95.47 | AA6: 96.57 | AB6: 4.93 | AC6: 4.85 | AD6: 91.63 | AE6: 90.69 | AF6: 91.57 | AG6: 5.04 | AH6: 5.05 | AI6: 86.48 | AJ6: 85.19 | AK6: 86.49 | AL6: 5.04 | AM6: 4.89 | AN6: 81.4
A7: 0.5S3 | B7: 327.3 | C7: 10 | D7: =C7*E7/B7 -> 3.0553009 | E7: 100 | G7: 116.65 | H7: 5.03 | I7: 4.82 | J7: 111.62 | K7: 111.47 | L7: 111.62 | M7: 5.03 | N7: 4.82 | O7: =L7-M7 -> 106.59 | P7: 106.96 | Q7: 106.5 | R7: 4.96 | S7: 4.87 | T7: 101.62 | U7: 101.22 | V7: 101.71 | W7: 5.04 | X7: 4.79 | Y7: 96.66 | Z7: 96.07 | AA7: 96.7 | AB7: 5 | AC7: 4.98 | AD7: 91.67 | AE7: 89.33 | AF7: 91.72 | AG7: 5 | AH7: 4.98 | AI7: 86.68 | AJ7: 85.74 | AK7: 86.59 | AL7: 5.02 | AM7: 5 | AN7: 81.56
A8: 1S1 | B8: 381 | C8: 10 | D8: =C8*E8/B8 -> 2.6246719 | E8: 100 | G8: 116.51 | H8: 5.01 | I8: 4.7 | J8: 111.5 | K8: 111.15 | L8: 111.49 | M8: 5.03 | N8: 4.69 | O8: =L8-M8 -> 106.46 | P8: 106.1 | Q8: 106.43 | R8: 4.97 | S8: 4.79 | T8: 101.44 | U8: 100.92 | V8: 101.53 | W8: 5.01 | X8: 4.94 | Y8: 96.5 | Z8: 95.91 | AA8: 96.49 | AB8: 5.03 | AC8: 4.89 | AD8: 91.44 | AE8: 90.46 | AF8: 91.48 | AG8: 4.97 | AH8: 4.94 | AI8: 86.47 | AJ8: 85.29 | AK8: 86.4 | AL8: 5.03 | AM8: 4.86 | AN8: 81.33
A9: 1S2 | B9: 381 | C9: 10 | D9: =C9*E9/B9 -> 2.6246719 | E9: 100 | G9: 116.65 | H9: 5.01 | I9: 4.93 | J9: 111.6 | K9: 111.39 | L9: 111.6 | M9: 5.02 | N9: 4.89 | O9: =L9-M9 -> 106.58 | P9: 106.29 | Q9: 106.55 | R9: 4.96 | S9: 4.89 | T9: 101.57 | U9: 101.19 | V9: 101.54 | W9: 5.02 | X9: 5.03 | Y9: 96.52 | Z9: 95.84 | AA9: 96.48 | AB9: 5 | AC9: 5 | AD9: 91.43 | AE9: 90.31 | AF9: 91.46 | AG9: 5.03 | AH9: 5.04 | AI9: 86.41 | AJ9: 84.57 | AK9: 86.43 | AL9: 5.03 | AM9: 4.92 | AN9: 81.38
A10: 1S3 | B10: 573.9 | C10: 10 | D10: =C10*E10/B10 -> 1.7424638 | E10: 100 | G10: 116.49 | H10: 5 | I10: 4.87 | J10: 111.52 | K10: 111.39 | L10: 111.53 | M10: 5.03 | N10: 4.79 | O10: =L10-M10 -> 106.5 | P10: 106.22 | Q10: 106.49 | R10: 4.96 | S10: 4.84 | T10: 101.51 | U10: 101.27 | V10: 101.52 | W10: 5.01 | X10: 5.03 | Y10: 96.5 | Z10: 95.34 | AA10: 96.5 | AB10: 4.99 | AC10: 4.84 | AD10: 91.55 | AE10: 90.52 | AF10: 91.36 | AG10: 5.02 | AH10: 5.03 | AI10: 86.49 | AJ10: 85.74 | AK10: 86.45 | AL10: 5.05 | AM10: 4.98 | AN10: 81.37
A11: 3S1 | B11: 573 | C11: 10 | D11: =C11*E11/B11 -> 1.7452007 | E11: 100 | G11: 116.89 | H11: 5.01 | I11: 4.72 | J11: 111.89 | K11: 111.76 | L11: 111.89 | M11: 5.02 | N11: 4.76 | O11: =L11-M11 -> 106.87 | P11: 106.69 | Q11: 106.89 | R11: 4.97 | S11: 4.77 | T11: 101.87 | U11: 101.47 | V11: 101.85 | W11: 5.03 | X11: 4.95 | Y11: 96.81 | Z11: 96.15 | AA11: 96.79 | AB11: 5.01 | AC11: 4.99 | AD11: 91.74 | AE11: 90.88 | AF11: 91.88 | AG11: 5.02 | AH11: 4.91 | AI11: 86.84 | AJ11: 85.94 | AK11: 86.86 | AL11: 5.03 | AM11: 4.89 | AN11: 81.82
A12: 3S2 | B12: 573 | C12: 10 | D12: =C12*E12/B12 -> 1.7452007 | E12: 100 | G12: 116.34 | H12: 5.03 | I12: 4.83 | J12: 111.3 | K12: 111.16 | L12: 111.3 | M12: 5.03 | N12: 4.84 | O12: =L12-M12 -> 106.27 | P12: 106.08 | Q12: 106.27 | R12: 4.95 | S12: 4.79 | T12: 101.3 | U12: 100.89 | V12: 101.26 | W12: 5.01 | X12: 4.88 | Y12: 96.24 | Z12: 96.79 | AA12: 96.36 | AB12: 5.01 | AC12: 4.88 | AD12: 91.33 | AE12: 90.57 | AF12: 91.31 | AG12: 5 | AH12: 5.14 | AI12: 81.26 | AJ12: 80.49 | AK12: 81.17 | AL12: 5.03 | AM12: 5 | AN12: 76.14
A13: 3S3 | B13: 573 | C13: 10 | D13: =C13*E13/B13 -> 1.7452007 | E13: 100 | G13: 116.48 | H13: 5.01 | I13: 4.73 | J13: 111.45 | K13: 111.22 | L13: 111.45 | M13: 5.02 | N13: 4.74 | O13: =L13-M13 -> 106.43 | P13: 106.17 | Q13: 106.41 | R13: 4.98 | S13: 4.85 | T13: 101.42 | U13: 100.99 | V13: 101.42 | W13: 5.01 | X13: 4.87 | Y13: 96.39 | Z13: 95.61 | AA13: 96.44 | AB13: 4.98 | AC13: 4.95 | AD13: 91.43 | AE13: 89.09 | AF13: 91.4 | AG13: 5.05 | AH13: 5.02 | AI13: 86.36 | AJ13: 85.29 | AK13: 86.33 | AL13: 5.1 | AM13: 5.06 | AN13: 81.21
T14: Leftover rear water was accidentally added
A15: 2% HNO3 (aq) to be added for ICP-MS | AF15: Extracted amount spilled, extracted a 2nd time
A16: Days | B16: 0 | D16: 3 | F16: 7 | H16: 14 | J16: 21 | L16: 28 | N16: 35
B17: From extracted (g) | C17: Actual (g) | D17: From extracted (g) | E17: Actual (g) | F17: From extracted (g) | G17: Actual (g) | H17: From extracted (g) | I17: Actual (g) | J17: From extracted (g) | K17: Actual (g) | L17: From extracted (g) | M17: Actual (g) | N17: From extracted (g) | O17: Actual (g)
A18: Blk1 | B18: =N3 -> 4.79 | C18: 4.8662 | D18: =N3 -> 4.79 | E18: 4.8139 | F18: =S3 -> 4.83 | G18: 4.8261 | H18: =X3 -> 4.92 | I18: 5.1979 | J18: =AC3 -> 5.06 | K18: 5.1508 | L18: =AH3 -> 4.92 | M18: 4.9144 | N18: =AM3 -> 4.96 | O18: 4.9606
A19: Blk2 | B19: =N4 -> 4.86 | C19: 4.8592 | D19: =N4 -> 4.86 | E19: 4.8607 | F19: =S4 -> 4.71 | G19: 4.7189 | H19: =X4 -> 4.87 | I19: 4.8694 | J19: =AC4 -> 4.88 | K19: 4.8979 | L19: =AH4 -> 4.93 | M19: 4.9288 | N19: =AM4 -> 4.86 | O19: 4.8656
A20: 0.5S1 | B20: =N5 -> 4.82 | C20: 4.8157 | D20: =N5 -> 4.82 | E20: 4.8275 | F20: =S5 -> 5.24 | G20: 5.2643 | H20: =X5 -> 4.95 | I20: 5.0983 | J20: =AC5 -> 4.83 | K20: 4.8396 | L20: =AH5 -> 5.02 | M20: 5.244 | N20: =AM5 -> 5.02 | O20: 5.1507
A21: 0.5S2 | B21: =N6 -> 4.8 | C21: 4.8289 | D21: =N6 -> 4.8 | E21: 4.8012 | F21: =S6 -> 4.75 | G21: 4.8527 | H21: =X6 -> 4.89 | I21: 4.885 | J21: =AC6 -> 4.85 | K21: 4.8409 | L21: =AH6 -> 5.05 | M21: 5.0388 | N21: =AM6 -> 4.89 | O21: 4.8711
A22: 0.5S3 | B22: =N7 -> 4.82 | C22: 4.8207 | D22: =N7 -> 4.82 | E22: 4.8304 | F22: =S7 -> 4.87 | G22: 4.8713 | H22: =X7 -> 4.79 | I22: 4.8073 | J22: =AC7 -> 4.98 | K22: 4.9952 | L22: =AH7 -> 4.98 | M22: 4.9774 | N22: =AM7 -> 5 | O22: 4.9976
A23: 1S1 | B23: =N8 -> 4.69 | C23: 4.7034 | D23: =N8 -> 4.69 | E23: 4.7081 | F23: =S8 -> 4.79 | G23: 4.794 | H23: =X8 -> 4.94 | I23: 4.9439 | J23: =AC8 -> 4.89 | K23: 4.8894 | L23: =AH8 -> 4.94 | M23: 4.9541 | N23: =AM8 -> 4.86 | O23: 4.8503
A24: 1S2 | B24: =N9 -> 4.89 | C24: 5.0073 | D24: =N9 -> 4.89 | E24: 5.0065 | F24: =S9 -> 4.89 | G24: 4.893 | H24: =X9 -> 5.03 | I24: 5.0255 | J24: =AC9 -> 5 | K24: 4.9916 | L24: =AH9 -> 5.04 | M24: 5.0399 | N24: =AM9 -> 4.92 | O24: 4.9208
A25: 1S3 | B25: =N10 -> 4.79 | C25: 4.629 | D25: =N10 -> 4.79 | E25: 4.7966 | F25: =S10 -> 4.84 | G25: 4.8361 | H25: =X10 -> 5.03 | I25: 5.0216 | J25: =AC10 -> 4.84 | K25: 4.8419 | L25: =AH10 -> 5.03 | M25: 5.0307 | N25: =AM10 -> 4.98 | O25: 4.9853
A26: 3S1 | B26: =N11 -> 4.76 | C26: 4.786 | D26: =N11 -> 4.76 | E26: 4.9325 | F26: =S11 -> 4.77 | G26: 4.7787 | H26: =X11 -> 4.95 | I26: 5.25 | J26: =AC11 -> 4.99 | K26: 4.982 | L26: =AH11 -> 4.91 | M26: 5.0157 | N26: =AM11 -> 4.89 | O26: 4.882
A27: 3S2 | B27: =N12 -> 4.84 | C27: 4.8372 | D27: =N12 -> 4.84 | E27: 4.8486 | F27: =S12 -> 4.79 | G27: 4.7903 | H27: =X12 -> 4.88 | I27: 4.902 | J27: =AC12 -> 4.88 | K27: 4.8851 | L27: =AH12 -> 5.14 | M27: 5.1381 | N27: =AM12 -> 5 | O27: 4.9921
A28: 3S3 | B28: =N13 -> 4.74 | C28: 4.7586 | D28: =N13 -> 4.74 | E28: 4.7322 | F28: =S13 -> 4.85 | G28: 4.8505 | H28: =X13 -> 4.87 | I28: 5.1776 | J28: =AC13 -> 4.95 | K28: 4.9475 | L28: =AH13 -> 5.02 | M28: 5.0103 | N28: =AM13 -> 5.06 | O28: 5.0469
G29: Some spilled 3S3 day 7 weight after spilling was 4.4152 (was well mixed) | M29: 4
B30: Dilution factors (Extracted+actual)/extracted
B31: Days | C31: 0 | D31: 3 | E31: 7 | F31: 14 | G31: 21 | H31: 28 | I31: 35
B32: Blk1 | C32: =(C18+B18)/(B18) -> 2.0159081 | D32: =(D18+E18)/D18 -> 2.0049896 | E32: =(F18+G18)/F18 -> 1.9991925 | F32: =(H18+I18)/H18 -> 2.0564837 | G32: =(J18+K18)/J18 -> 2.0179447 | H32: =(L18+M18)/L18 -> 1.9988618 | I32: =(O18+N18)/N18 -> 2.000121
B33: Blk2 | C33: =(C19+B19)/(B19) -> 1.9998354 | D33: =(D19+E19)/D19 -> 2.000144 | E33: =(F19+G19)/F19 -> 2.0018896 | F33: =(H19+I19)/H19 -> 1.9998768 | G33: =(J19+K19)/J19 -> 2.003668 | H33: =(L19+M19)/L19 -> 1.9997566 | I33: =(O19+N19)/N19 -> 2.0011523
B34: 0.5S1 | C34: =(C20+B20)/(B20) -> 1.9991079 | D34: =(D20+E20)/D20 -> 2.001556 | E34: =(F20+G20)/F20 -> 2.0046374 | F34: =(H20+I20)/H20 -> 2.0299596 | G34: =(J20+K20)/J20 -> 2.0019876 | H34: =(L20+M20)/L20 -> 2.0446215 | I34: =(O20+N20)/N20 -> 2.0260359
B35: 0.5S2 | C35: =(C21+B21)/(B21) -> 2.0060208 | D35: =(D21+E21)/D21 -> 2.00025 | E35: =(F21+G21)/F21 -> 2.0216211 | F35: =(H21+I21)/H21 -> 1.9989775 | G35: =(J21+K21)/J21 -> 1.9981237 | H35: =(L21+M21)/L21 -> 1.9977822 | I35: =(O21+N21)/N21 -> 1.996135
B36: 0.5S3 | C36: =(C22+B22)/(B22) -> 2.0001452 | D36: =(D22+E22)/D22 -> 2.0021577 | E36: =(F22+G22)/F22 -> 2.0002669 | F36: =(H22+I22)/H22 -> 2.0036117 | G36: =(J22+K22)/J22 -> 2.0030522 | H36: =(L22+M22)/L22 -> 1.9994779 | I36: =(O22+N22)/N22 -> 1.99952
B37: 1S1 | C37: =(C23+B23)/(B23) -> 2.0028571 | D37: =(D23+E23)/D23 -> 2.0038593 | E37: =(F23+G23)/F23 -> 2.0008351 | F37: =(H23+I23)/H23 -> 2.0007895 | G37: =(J23+K23)/J23 -> 1.9998773 | H37: =(L23+M23)/L23 -> 2.0028543 | I37: =(O23+N23)/N23 -> 1.9980041
B38: 1S2 | C38: =(C24+B24)/(B24) -> 2.0239877 | D38: =(D24+E24)/D24 -> 2.0238241 | E38: =(F24+G24)/F24 -> 2.0006135 | F38: =(H24+I24)/H24 -> 1.9991054 | G38: =(J24+K24)/J24 -> 1.99832 | H38: =(L24+M24)/L24 -> 1.9999802 | I38: =(O24+N24)/N24 -> 2.0001626
B39: 1S3 | C39: =(C25+B25)/(B25) -> 1.9663883 | D39: =(D25+E25)/D25 -> 2.0013779 | E39: =(F25+G25)/F25 -> 1.9991942 | F39: =(H25+I25)/H25 -> 1.99833 | G39: =(J25+K25)/J25 -> 2.0003926 | H39: =(L25+M25)/L25 -> 2.0001392 | I39: =(O25+N25)/N25 -> 2.0010643
B40: 3S1 | C40: =(C26+B26)/(B26) -> 2.0054622 | D40: =(D26+E26)/D26 -> 2.0362395 | E40: =(F26+G26)/F26 -> 2.0018239 | F40: =(H26+I26)/H26 -> 2.0606061 | G40: =(J26+K26)/J26 -> 1.9983968 | H40: =(L26+M26)/L26 -> 2.0215275 | I40: =(O26+N26)/N26 -> 1.998364
...

Sheet Concentrations
B1: TABLE 1
B2: Sample Id | C2: R | D2: Acquisition Time | E2: QC Status | F2: Dataset File | G2: Method File | H2: Se 82/82 (ug/L) | I2: Y (IS) 89/89 (IS) | N2: Table 2 redistributed data | U2: Table 3
A3: 1 | B3: Blank | C3: R | D3: 09/03/2025 16:34:20 | F3: C:\Users\Public\Documents\PerkinElmer Syngistix\ICPMS\DataSet\Externe\Externe_2025\Frank20250903\Blank.013 | G3: C:\Users\Public\Documents\PerkinElmer Syngistix\ICPMS\Method\ExterneMeth\FrankLi20250903.mth | I3: 1 | N3: Day 0 | O3: R1 | P3: R2 | Q3: R3 | R3: Average (from Table 2) | S3: stdev | U3: Day 21 | V3: R1 | W3: R2 | X3: R3 | Y3: Average (From table 3) | Z3: stdev
A4: 2 | B4: STD1 | C4: R | D4: 09/03/2025 16:35:33 | F4: C:\Users\Public\Documents\PerkinElmer Syngistix\ICPMS\DataSet\Externe\Externe_2025\Frank20250903\STD1.014 | G4: C:\Users\Public\Documents\PerkinElmer Syngistix\ICPMS\Method\ExterneMeth\FrankLi20250903.mth | H4: 0.201 | I4: 1.0241101 | N4: 0.25% w/w | O4: =H30 -> 0.56618087 | P4: =H31 -> 0.59341467 | Q4: =H32 -> 0.53147327 | R4: =AVERAGE(O4:Q4) -> 0.5636896 | S4: =STDEV(O4:Q4) -> 0.031045757 | U4: 0.25% w/w | V4: =H41 -> 0.50036382 | W4: =H42 -> 0.46307502 | X4: =H43 -> 0.38541737 | Y4: =AVERAGE(V4:X4) -> 0.44961874 | Z4: =STDEV(V4:X4) -> 0.058642777
A5: 3 | B5: STD2 | C5: R | D5: 09/03/2025 16:36:45 | F5: C:\Users\Public\Documents\PerkinElmer Syngistix\ICPMS\DataSet\Externe\Externe_2025\Frank20250903\STD2.015 | G5: C:\Users\Public\Documents\PerkinElmer Syngistix\ICPMS\Method\ExterneMeth\FrankLi20250903.mth | H5: 0.48428718 | I5: 1.106713 | N5: 0.72%/w/w | O5: =H33 -> 0.56484815 | P5: =H34 -> 0.54272744 | Q5: =H35 -> 0.5520008 | R5: =AVERAGE(O5:Q5) -> 0.55319213 | S5: =STDEV(O5:Q5) -> 0.011108372 | U5: 0.72%/w/w | V5: =H44 -> 0.73886725 | W5: =H48 -> 0.55211759 | X5: =H49 -> 0.61094182 | Y5: =AVERAGE(V5:X5) -> 0.63397555 | Z5: =STDEV(V5:X5) -> 0.095481794
A6: 4 | B6: STD3 | C6: R | D6: 09/03/2025 16:37:56 | F6: C:\Users\Public\Documents\PerkinElmer Syngistix\ICPMS\DataSet\Externe\Externe_2025\Frank20250903\STD3.016 | G6: C:\Users\Public\Documents\PerkinElmer Syngistix\ICPMS\Method\ExterneMeth\FrankLi20250903.mth | H6: 1.9867018 | I6: 1.0339867 | N6: 2.74% w/w | O6: =H36 -> 0.83255449 | P6: =H37 -> 0.58210028 | Q6: =H38 -> 0.62612185 | R6: =AVERAGE(O6:Q6) -> 0.68025887 | S6: =STDEV(O6:Q6) -> 0.13371589 | U6: 2.74% w/w | V6: =H50 -> 0.63507638 | W6: =H51 -> 0.68377988 | X6: =H52 -> 0.65506146 | Y6: =AVERAGE(V6:X6) -> 0.65797257 | Z6: =STDEV(V6:X6) -> 0.024481901
A7: 5 | B7: STD4 | C7: R | D7: 09/03/2025 16:39:09 | F7: C:\Users\Public\Documents\PerkinElmer Syngistix\ICPMS\DataSet\Externe\Externe_2025\Frank20250903\STD4.017 | G7: C:\Users\Public\Documents\PerkinElmer Syngistix\ICPMS\Method\ExterneMeth\FrankLi20250903.mth | H7: 10.001407 | I7: 0.9910942 | N7: Blk | O7: =H28 -> 0.48952887 | P7: =H29 -> 0.54123216 | R7: =AVERAGE(O7:P7) -> 0.51538052 | S7: =STDEV(O7:P7) -> 0.036559748 | U7: Blk | V7: =H39 -> 0.50390442 | W7: =H40 -> 0.47868557 | Y7: =AVERAGE(V7:W7) -> 0.491295 | Z7: =STDEV(V7:W7) -> 0.017832418
A8: 6 | B8: STD5 | C8: R | D8: 09/03/2025 16:40:19 | F8: C:\Users\Public\Documents\PerkinElmer Syngistix\ICPMS\DataSet\Externe\Externe_2025\Frank20250903\STD5.018 | G8: C:\Users\Public\Documents\PerkinElmer Syngistix\ICPMS\Method\ExterneMeth\FrankLi20250903.mth | H8: 19.862374 | I8: 1.0040203
A9: 7 | B9: STD6 | C9: R | D9: 09/03/2025 16:41:29 | F9: C:\Users\Public\Documents\PerkinElmer Syngistix\ICPMS\DataSet\Externe\Externe_2025\Frank20250903\STD6.019 | G9: C:\Users\Public\Documents\PerkinElmer Syngistix\ICPMS\Method\ExterneMeth\FrankLi20250903.mth | H9: 39.569615 | I9: 1.0092318 | N9: Day 3 | O9: R1 | P9: R2 | Q9: R3 | U9: Day 28 | V9: R1 | W9: R2 | X9: R3
A10: 8 | B10: =HYPERLINK("#'Calibration Curves 8'!A1", "Calibration Curves") -> Calibration Curves | C10: R | D10: 09/03/2025 16:41:29 | N10: 0.25% w/w | O10: =H55 -> 0.49349617 | P10: =H56 -> 0.50321781 | Q10: =H57 -> 0.53769063 | R10: =AVERAGE(O10:Q10) -> 0.5114682 | S10: =STDEV(O10:Q10) -> 0.023223681 | U10: 0.25% w/w | V10: =H102 -> 0.48050658 | W10: =H103 -> 0.56585686 | X10: =H104 -> 0.52994358 | Y10: =AVERAGE(V10:X10) -> 0.52543567 | Z10: =STDEV(V10:X10) -> 0.042853339
A11: 9 | B11: BlankR | C11: R | D11: 09/03/2025 16:42:41 | F11: C:\Users\Public\Documents\PerkinElmer Syngistix\ICPMS\DataSet\Externe\Externe_2025\Frank20250903\BlankR.020 | G11: C:\Users\Public\Documents\PerkinElmer Syngistix\ICPMS\Method\ExterneMeth\FrankLi20250903.mth | H11: 0.058369177 | I11: 1.0334564 | N11: 0.72%/w/w | O11: =H58 -> 0.63552911 | P11: =H59 -> 0.55280247 | Q11: =H60 -> 0.51954171 | R11: =AVERAGE(O11:Q11) -> 0.5692911 | S11: =STDEV(O11:Q11) -> 0.059725839 | U11: 0.72%/w/w | V11: =H105 -> 0.58910976 | W11: =H106 -> 0.61410973 | X11: =H123 -> 0.5081371 | Y11: =AVERAGE(V11:X11) -> 0.57045219 | Z11: =STDEV(V11:X11) -> 0.0553952
A12: 10 | B12: QCS27 | C12: R | D12: 09/03/2025 16:43:52 | E12: Passed | F12: C:\Users\Public\Documents\PerkinElmer Syngistix\ICPMS\DataSet\Externe\Externe_2025\Frank20250903\QCS27.021 | G12: C:\Users\Public\Documents\PerkinElmer Syngistix\ICPMS\Method\ExterneMeth\FrankLi20250903.mth | H12: 10.223826 | I12: 0.98344605 | N12: 2.74% w/w | O12: =H61 -> 0.60987922 | P12: =H62 -> 0.62777175 | Q12: =H63 -> 0.63381187 | R12: =AVERAGE(O12:Q12) -> 0.62382095 | S12: =STDEV(O12:Q12) -> 0.012445868 | U12: 2.74% w/w | V12: =H124 -> 0.65921134 | W12: =H109 -> 0.70399494 | X12: =H110 -> 0.68632427 | Y12: =AVERAGE(V12:X12) -> 0.68317685 | Z12: =STDEV(V12:X12) -> 0.022557094
A13: 11 | B13: BlankR | C13: R | D13: 09/03/2025 16:45:04 | F13: C:\Users\Public\Documents\PerkinElmer Syngistix\ICPMS\DataSet\Externe\Externe_2025\Frank20250903\BlankR.022 | G13: C:\Users\Public\Documents\PerkinElmer Syngistix\ICPMS\Method\ExterneMeth\FrankLi20250903.mth | H13: 0.037737772 | I13: 1.0027078 | N13: Blk | O13: =H53 -> 0.50579368 | P13: =H54 -> 0.38877322 | R13: =AVERAGE(O13:P13) -> 0.44728345 | S13: =STDEV(O13:P13) -> 0.082745966 | U13: Blk | V13: =H96 -> 0.63644954 | W13: =H97 -> 0.49592437 | Y13: =AVERAGE(V13:W13) -> 0.56618696 | Z13: =STDEV(V13:W13) -> 0.099366297
A14: 12 | B14: Blank | C14: R | D14: 09/03/2025 16:48:27 | F14: C:\Users\Public\Documents\PerkinElmer Syngistix\ICPMS\DataSet\Externe\Externe_2025\Frank20250903\Blank.024 | G14: C:\Users\Public\Documents\PerkinElmer Syngistix\ICPMS\Method\ExterneMeth\FrankLi20250903.mth | I14: 1
A15: 13 | B15: STD1 | C15: R | D15: 09/03/2025 16:49:38 | F15: C:\Users\Public\Documents\PerkinElmer Syngistix\ICPMS\DataSet\Externe\Externe_2025\Frank20250903\STD1.025 | G15: C:\Users\Public\Documents\PerkinElmer Syngistix\ICPMS\Method\ExterneMeth\FrankLi20250903.mth | H15: 0.201 | I15: 0.96855983 | N15: Day 7 | O15: R1 | P15: R2 | Q15: R3 | U15: Day 35 | V15: R1 | W15: R2 | X15: R3
A16: 14 | B16: STD2 | C16: R | D16: 09/03/2025 16:50:50 | F16: C:\Users\Public\Documents\PerkinElmer Syngistix\ICPMS\DataSet\Externe\Externe_2025\Frank20250903\STD2.026 | G16: C:\Users\Public\Documents\PerkinElmer Syngistix\ICPMS\Method\ExterneMeth\FrankLi20250903.mth | H16: 0.49223056 | I16: 0.95580347 | N16: 0.25% w/w | O16: =H66 -> 0.54275652 | P16: =H67 -> 0.5163643 | Q16: =H79 -> 0.59102417 | R16: =AVERAGE(O16:Q16) -> 0.55004833 | S16: =STDEV(O16:Q16) -> 0.037860298 | U16: 0.25% w/w | V16: =H111 -> 0.5088191 | W16: =H112 -> 0.46647987 | X16: =H113 -> 0.53423372 | Y16: =AVERAGE(V16:X16) -> 0.50317756 | Z16: =STDEV(V16:X16) -> 0.034227424
A17: 15 | B17: STD3 | C17: R | D17: 09/03/2025 16:52:01 | F17: C:\Users\Public\Documents\PerkinElmer Syngistix\ICPMS\DataSet\Externe\Externe_2025\Frank20250903\STD3.027 | G17: C:\Users\Public\Documents\PerkinElmer Syngistix\ICPMS\Method\ExterneMeth\FrankLi20250903.mth | H17: 1.9785255 | I17: 0.99820384 | N17: 0.72%/w/w | O17: =H80 -> 0.59706791 | P17: =H81 -> 0.58422825 | Q17: =H82 -> 0.55806923 | R17: =AVERAGE(O17:Q17) -> 0.57978846 | S17: =STDEV(O17:Q17) -> 0.019874808 | U17: 0.72%/w/w | V17: =H114 -> 0.49140746 | W17: =H115 -> 0.49271685 | X17: =H125 -> 0.57547638 | Y17: =AVERAGE(V17:X17) -> 0.5198669 | Z17: =STDEV(V17:X17) -> 0.048163675
A18: 16 | B18: STD4 | C18: R | D18: 09/03/2025 16:53:14 | F18: C:\Users\Public\Documents\PerkinElmer Syngistix\ICPMS\DataSet\Externe\Externe_2025\Frank20250903\STD4.028 | G18: C:\Users\Public\Documents\PerkinElmer Syngistix\ICPMS\Method\ExterneMeth\FrankLi20250903.mth | H18: 9.9885675 | I18: 0.97475511 | N18: 2.74% w/w | O18: =H129 -> 0.63249302 | P18: =H84 -> 0.5902002 | Q18: =H85 -> 0.58157033 | R18: =AVERAGE(O18:Q18) -> 0.60142118 | S18: =STDEV(O18:Q18) -> 0.027252758 | U18: 2.74% w/w | V18: =H117 -> 0.5577581 | W18: =H118 -> 0.45961813 | X18: =H119 -> 0.67336224 | Y18: =AVERAGE(V18:X18) -> 0.56357949 | Z18: =STDEV(V18:X18) -> 0.1069909
A19: 17 | B19: STD5 | C19: R | D19: 09/03/2025 16:54:24 | F19: C:\Users\Public\Documents\PerkinElmer Syngistix\ICPMS\DataSet\Externe\Externe_2025\Frank20250903\STD5.029 | G19: C:\Users\Public\Documents\PerkinElmer Syngistix\ICPMS\Method\ExterneMeth\FrankLi20250903.mth | H19: 18.542213 | I19: 1.1459318 | N19: Blk | O19: =H64 -> 0.47937911 | P19: =H65 -> 0.51668332 | R19: =AVERAGE(O19:P19) -> 0.49803122 | S19: =STDEV(O19:P19) -> 0.026378054 | U19: Blk | V19: =H111 -> 0.5088191 | W19: =H112 -> 0.46647987 | Y19: =AVERAGE(V19:W19) -> 0.48764949 | Z19: =STDEV(V19:W19) -> 0.029938363
A20: 18 | B20: STD6 | C20: R | D20: 09/03/2025 16:55:34 | F20: C:\Users\Public\Documents\PerkinElmer Syngistix\ICPMS\DataSet\Externe\Externe_2025\Frank20250903\STD6.030 | G20: C:\Users\Public\Documents\PerkinElmer Syngistix\ICPMS\Method\ExterneMeth\FrankLi20250903.mth | H20: 41.47328 | I20: 1.00685
A21: 19 | B21: =HYPERLINK("#'Calibration Curves 19'!A1", "Calibration Curves") -> Calibration Curves | C21: R | D21: 09/03/2025 16:55:34 | N21: Day 14 | O21: R1 | P21: R2 | Q21: R3
A22: 20 | B22: BlankR | C22: R | D22: 09/03/2025 16:56:46 | F22: C:\Users\Public\Documents\PerkinElmer Syngistix\ICPMS\DataSet\Externe\Externe_2025\Frank20250903\BlankR.031 | G22: C:\Users\Public\Documents\PerkinElmer Syngistix\ICPMS\Method\ExterneMeth\FrankLi20250903.mth | H22: 0.00427884 | I22: 1.0429828 | N22: 0.25% w/w | O22: =H88 -> 0.58378215 | P22: =H89 -> 0.51331492 | Q22: =H90 -> 0.50376694 | R22: =AVERAGE(O22:Q22) -> 0.53362134 | S22: =STDEV(O22:Q22) -> 0.043702071
A23: 21 | B23: QCS27 | C23: R | D23: 09/03/2025 16:57:57 | E23: Passed | F23: C:\Users\Public\Documents\PerkinElmer Syngistix\ICPMS\DataSet\Externe\Externe_2025\Frank20250903\QCS27.032 | G23: C:\Users\Public\Documents\PerkinElmer Syngistix\ICPMS\Method\ExterneMeth\FrankLi20250903.mth | H23: 9.9883288 | I23: 0.96705419 | N23: 0.72%/w/w | O23: =H91 -> 0.51588777 | P23: =H92 -> 0.58774996 | Q23: =H93 -> 0.53595822 | R23: =AVERAGE(O23:Q23) -> 0.54653198 | S23: =STDEV(O23:Q23) -> 0.0370796
A24: 22 | B24: BlankR | C24: R | D24: 09/03/2025 16:59:09 | F24: C:\Users\Public\Documents\PerkinElmer Syngistix\ICPMS\DataSet\Externe\Externe_2025\Frank20250903\BlankR.033 | G24: C:\Users\Public\Documents\PerkinElmer Syngistix\ICPMS\Method\ExterneMeth\FrankLi20250903.mth | H24: 0.0012008239 | I24: 0.9789021 | N24: 2.74% w/w | O24: =H94 -> 0.6517368 | P24: =H95 -> 0.59431498 | Q24: =H96 -> 0.63644954 | R24: =AVERAGE(O24:Q24) -> 0.62750044 | S24: =STDEV(O24:Q24) -> 0.02973855
A25: 23 | B25: 1__0p5E_3xUF | C25: R | D25: 09/03/2025 17:00:19 | F25: C:\Users\Public\Documents\PerkinElmer Syngistix\ICPMS\DataSet\Externe\Externe_2025\Frank20250903\1__0p5E_3xUF.034 | G25: C:\Users\Public\Documents\PerkinElmer Syngistix\ICPMS\Method\ExterneMeth\FrankLi20250903.mth | H25: 0.23685454 | I25: 0.92757512 | N25: Blk | O25: =H86 -> 0.44185546 | P25: =H87 -> 0.52306908 | R25: =AVERAGE(O25:P25) -> 0.48246227 | S25: =STDEV(O25:P25) -> 0.0574267
A26: 24 | B26: 2__1pct_3xwash_Ctrl | C26: R | D26: 09/03/2025 17:01:30 | F26: C:\Users\Public\Documents\PerkinElmer Syngistix\ICPMS\DataSet\Externe\Externe_2025\Frank20250903\2__1pct_3xwash_Ctrl.035 | G26: C:\Users\Public\Documents\PerkinElmer Syngistix\ICPMS\Method\ExterneMeth\FrankLi20250903.mth | H26: 0.62954156 | I26: 0.93302499
A27: 25 | B27: 3__3pct_3xwash_Ctrl | C27: R | D27: 09/03/2025 17:02:41 | F27: C:\Users\Public\Documents\PerkinElmer Syngistix\ICPMS\DataSet\Externe\Externe_2025\Frank20250903\3__3pct_3xwash_Ctrl.036 | G27: C:\Users\Public\Documents\PerkinElmer Syngistix\ICPMS\Method\ExterneMeth\FrankLi20250903.mth | H27: 0.88792764 | I27: 0.97176702
A28: 26 | B28: 4_D0_Blk1 | C28: R | D28: 09/03/2025 17:03:52 | F28: C:\Users\Public\Documents\PerkinElmer Syngistix\ICPMS\DataSet\Externe\Externe_2025\Frank20250903\4_D0_Blk1.037 | G28: C:\Users\Public\Documents\PerkinElmer Syngistix\ICPMS\Method\ExterneMeth\FrankLi20250903.mth | H28: 0.48952887 | I28: 0.93059577 | N28: Table 4 theoretical Se concentration
A29: 27 | B29: 5_D0_Blk2 | C29: R | D29: 09/03/2025 17:05:03 | F29: C:\Users\Public\Documents\PerkinElmer Syngistix\ICPMS\DataSet\Externe\Externe_2025\Frank20250903\5_D0_Blk2.038 | G29: C:\Users\Public\Documents\PerkinElmer Syngistix\ICPMS\Method\ExterneMeth\FrankLi20250903.mth | H29: 0.54123216 | I29: 0.90360656 | N29: Total Se in c-Se-PS-MNPs | O29: 0.3% w/w | P29: 0.7% w/w | Q29: 2.3% w/w
A30: 28 | B30: 6_D0_0p5S1 | C30: R | D30: 09/03/2025 17:06:15 | F30: C:\Users\Public\Documents\PerkinElmer Syngistix\ICPMS\DataSet\Externe\Externe_2025\Frank20250903\6_D0_0p5S1.039 | G30: C:\Users\Public\Documents\PerkinElmer Syngistix\ICPMS\Method\ExterneMeth\FrankLi20250903.mth | H30: 0.56618087 | I30: 0.91954008 | N30: Se-PS- concentration (ppm) | O30: 10 | P30: 10 | Q30: 10
A31: 29 | B31: 7_D0_0p5S2 | C31: R | D31: 09/03/2025 17:07:26 | F31: C:\Users\Public\Documents\PerkinElmer Syngistix\ICPMS\DataSet\Externe\Externe_2025\Frank20250903\7_D0_0p5S2.040 | G31: C:\Users\Public\Documents\PerkinElmer Syngistix\ICPMS\Method\ExterneMeth\FrankLi20250903.mth | H31: 0.59341467 | I31: 0.90714529 | N31: %weight | O31: 0.0025 | P31: 0.0072 | Q31: 0.0274
A32: 30 | B32: 8_D0_0p5S3 | C32: R | D32: 09/03/2025 17:08:37 | F32: C:\Users\Public\Documents\PerkinElmer Syngistix\ICPMS\DataSet\Externe\Externe_2025\Frank20250903\8_D0_0p5S3.041 | G32: C:\Users\Public\Documents\PerkinElmer Syngistix\ICPMS\Method\ExterneMeth\FrankLi20250903.mth | H32: 0.53147327 | I32: 0.92346741 | N32: Total Se in c-Se-PS-MNPs (ppb) | O32: =O31*O30*1000 -> 25 | P32: =P31*P30*1000 -> 72 | Q32: =Q31*Q30*1000 -> 274
A33: 31 | B33: 9_D0_1S1 | C33: R | D33: 09/03/2025 17:09:49 | F33: C:\Users\Public\Documents\PerkinElmer Syngistix\ICPMS\DataSet\Externe\Externe_2025\Frank20250903\9_D0_1S1.042 | G33: C:\Users\Public\Documents\PerkinElmer Syngistix\ICPMS\Method\ExterneMeth\FrankLi20250903.mth | H33: 0.56484815 | I33: 0.9424598
A34: 32 | B34: 10_D0_1S2 | C34: R | D34: 09/03/2025 17:11:01 | F34: C:\Users\Public\Documents\PerkinElmer Syngistix\ICPMS\DataSet\Externe\Externe_2025\Frank20250903\10_D0_1S2.043 | G34: C:\Users\Public\Documents\PerkinElmer Syngistix\ICPMS\Method\ExterneMeth\FrankLi20250903.mth | H34: 0.54272744 | I34: 0.92503818
A35: 33 | B35: 11_D0_1S3 | C35: R | D35: 09/03/2025 17:12:14 | F35: C:\Users\Public\Documents\PerkinElmer Syngistix\ICPMS\DataSet\Externe\Externe_2025\Frank20250903\11_D0_1S3.044 | G35: C:\Users\Public\Documents\PerkinElmer Syngistix\ICPMS\Method\ExterneMeth\FrankLi20250903.mth | H35: 0.5520008 | I35: 0.91597887 | N35: Table 5 Adjusted true concentrations with DF from "leaching test 10 ppm c-Se sheet
A36: 34 | B36: 12_D0_3S1 | C36: R | D36: 09/03/2025 17:13:26 | F36: C:\Users\Public\Documents\PerkinElmer Syngistix\ICPMS\DataSet\Externe\Externe_2025\Frank20250903\12_D0_3S1.045 | G36: C:\Users\Public\Documents\PerkinElmer Syngistix\ICPMS\Method\ExterneMeth\FrankLi20250903.mth | H36: 0.83255449 | I36: 0.92599607
A37: 35 | B37: 13_D0_3S2 | C37: R | D37: 09/03/2025 17:14:37 | F37: C:\Users\Public\Documents\PerkinElmer Syngistix\ICPMS\DataSet\Externe\Externe_2025\Frank20250903\13_D0_3S2.046 | G37: C:\Users\Public\Documents\PerkinElmer Syngistix\ICPMS\Method\ExterneMeth\FrankLi20250903.mth | H37: 0.58210028 | I37: 0.94167571 | N37: Day 0 | O37: R1 | P37: R2 | Q37: R3 | R37: Average | S37: stdev | U37: Day 21 | V37: R1 | W37: R2 | X37: R3 | Y37: Average | Z37: stdev
A38: 36 | B38: 14_D0_3S3 | C38: R | D38: 09/03/2025 17:15:48 | F38: C:\Users\Public\Documents\PerkinElmer Syngistix\ICPMS\DataSet\Externe\Externe_2025\Frank20250903\14_D0_3S3.047 | G38: C:\Users\Public\Documents\PerkinElmer Syngistix\ICPMS\Method\ExterneMeth\FrankLi20250903.mth | H38: 0.62612185 | I38: 0.92483019 | N38: 0.25% w/w | O38: =O4*'Leaching test 10 ppm c-Se'!C34 -> 1.1318566 | P38: =P4*'Leaching test 10 ppm c-Se'!C35 -> 1.1904022 | Q38: =Q4*'Leaching test 10 ppm c-Se'!C36 -> 1.0630237 | R38: =AVERAGE(O38:Q38) -> 1.1284275 | S38: =STDEV(O38:Q38) -> 0.063758431 | U38: 0.25% w/w | V38: =V4*'Leaching test 10 ppm c-Se'!G34 -> 1.0017221 | W38: =W4*'Leaching test 10 ppm c-Se'!G35 -> 0.92528118 | X38: =X4*'Leaching test 10 ppm c-Se'!G36 -> 0.77201111 | Y38: =AVERAGE(V38:X38) -> 0.89967148 | Z38: =STDEV(V38:X38) -> 0.11697727
A39: 37 | B39: 15_D21_Blk1 | C39: R | D39: 09/03/2025 17:17:02 | F39: C:\Users\Public\Documents\PerkinElmer Syngistix\ICPMS\DataSet\Externe\Externe_2025\Frank20250903\15_D1_Blk1.048 | G39: C:\Users\Public\Documents\PerkinElmer Syngistix\ICPMS\Method\ExterneMeth\FrankLi20250903.mth | H39: 0.50390442 | I39: 0.9259127 | N39: 0.72%/w/w | O39: =O5*'Leaching test 10 ppm c-Se'!C37 -> 1.1313101 | P39: =P5*'Leaching test 10 ppm c-Se'!C38 -> 1.0984737 | Q39: =Q5*'Leaching test 10 ppm c-Se'!C39 -> 1.0854479 | R39: =AVERAGE(O39:Q39) -> 1.1050772 | S39: =STDEV(O39:Q39) -> 0.023633482 | U39: 0.72%/w/w | V39: =V5*'Leaching test 10 ppm c-Se'!G37 -> 1.4776438 | W39: =W5*'Leaching test 10 ppm c-Se'!G38 -> 1.1033076 | X39: =X5*'Leaching test 10 ppm c-Se'!G39 -> 1.2221235 | Y39: =AVERAGE(V39:X39) -> 1.2676916 | Z39: =STDEV(V39:X39) -> 0.19128315
A40: 38 | B40: 16_D21_Blk2 | C40: R | D40: 09/03/2025 17:18:13 | F40: C:\Users\Public\Documents\PerkinElmer Syngistix\ICPMS\DataSet\Externe\Externe_2025\Frank20250903\16_D1_Blk2.049 | G40: C:\Users\Public\Documents\PerkinElmer Syngistix\ICPMS\Method\ExterneMeth\FrankLi20250903.mth | H40: 0.47868557 | I40: 0.93393243 | N40: 2.74% w/w | O40: =O12*'Leaching test 10 ppm c-Se'!C40 -> 1.2230897 | P40: =P6*'Leaching test 10 ppm c-Se'!C41 -> 1.1638638 | Q40: =P6*'Leaching test 10 ppm c-Se'!C42 -> 1.1664848 | R40: =AVERAGE(O40:Q40) -> 1.1844794 | S40: =STDEV(O40:Q40) -> 0.03346316 | U40: 2.74% w/w | V40: =V6*'Leaching test 10 ppm c-Se'!G40 -> 1.2691346 | W40: =W6*'Leaching test 10 ppm c-Se'!G41 -> 1.3682744 | X40: =X6*'Leaching test 10 ppm c-Se'!G42 -> 1.3097921 | Y40: =AVERAGE(V40:X40) -> 1.3157337 | Z40: =STDEV(V40:X40) -> 0.049836226
...
