Workbook

Sheet Description
A1: NOTE
A2: This Excel file is for the NTA Se-PS-NPs analysis
A3: Raw data from the NTA are summarized in 0R1, 0R2,… 8.7R1
A4: Adjusted concentrations to 1.6e8 NPs/ml and plotting for Figure 3a are in "Fig3a for sp-ICP-MS plot"
A5: FigS8a for the unprocessed concentrations of Se-PS-NPs after sequenetial centrifugation are in "Fig S8a"
A6: Concentrations raw data, average and stdev are in "For sp-ICP-MS (table 2)"

Sheet For sp-ICP-MS (table 2)
A1: Size [nm] - 1 - Scatter | B1: Concentration [particles/ml] - 1 - Scatter | C1: Size [nm] - 2 - Scatter | D1: Concentration [particles/ml] - 2 - Scatter | E1: Size [nm] - 3 - Scatter | F1: Concentration [particles/ml] - 3 - Scatter | K1: Size [nm] - 1 - Scatter | L1: Concentration [particles/ml] - 1 - Scatter | M1: Size [nm] - 2 - Scatter | N1: Concentration [particles/ml] - 2 - Scatter | O1: Size [nm] - 3 - Scatter | P1: Concentration [particles/ml] - 3 - Scatter
A2: 2.5 | B2: 0 | C2: 2.5 | D2: 0 | E2: 2.5 | F2: 0 | K2: 2.5 | L2: 0 | M2: 2.5 | N2: 0 | O2: 2.5 | P2: 0 | T2: #,Sample,Include,Type,Mode [nm],Mean [nm],Standard deviation [nm],D10 [nm],D50 [nm],D90 [nm],Concentration [particles/ml]
A3: 7.5 | B3: 0 | C3: 7.5 | D3: 0 | E3: 7.5 | F3: 0 | K3: 7.5 | L3: 0 | M3: 7.5 | N3: 0 | O3: 7.5 | P3: 0 | T3: 1 | U3: Th_0.5E_For_ICP-MS_V5_4 | V3: TRUE | W3: Size Scatter | X3: 237.5 | Y3: 236 | Z3: 103 | AA3: 123 | AB3: 220 | AC3: 364 | AD3: 151000000 | AE3: 12200000
A4: 12.5 | B4: 0 | C4: 12.5 | D4: 0 | E4: 12.5 | F4: 0 | K4: 12.5 | L4: 0 | M4: 12.5 | N4: 0 | O4: 12.5 | P4: 0 | T4: 2 | U4: Th_0.5E_For_ICP-MS_V5_3 | V4: TRUE | W4: Size Scatter | X4: 197.5 | Y4: 244 | Z4: 108 | AA4: 127 | AB4: 227 | AC4: 376 | AD4: 164000000 | AE4: 26900000
A5: 17.5 | B5: 0 | C5: 17.5 | D5: 0 | E5: 17.5 | F5: 0 | K5: 17.5 | L5: 0 | M5: 17.5 | N5: 0 | O5: 17.5 | P5: 0 | T5: 3 | U5: Th_0.5E_For_ICP-MS_V5_1 | V5: TRUE | W5: Size Scatter | X5: 182.5 | Y5: 240 | Z5: 108 | AA5: 124 | AB5: 221 | AC5: 373 | AD5: 155000000 | AE5: 15500000
A6: 22.5 | B6: 0 | C6: 22.5 | D6: 0 | E6: 22.5 | F6: 0 | K6: 22.5 | L6: 0 | M6: 22.5 | N6: 0 | O6: 22.5 | P6: 0
A7: 27.5 | B7: 9021.7999 | C7: 27.5 | D7: 0 | E7: 27.5 | F7: 9016.1642 | K7: 27.5 | L7: 4600.7223 | M7: 27.5 | N7: 0 | O7: 27.5 | P7: 9956.735
A8: 32.5 | B8: 18945.78 | C8: 32.5 | D8: 16423.877 | E8: 32.5 | F8: 28851.726 | K8: 32.5 | L8: 11961.878 | M8: 32.5 | N8: 0 | O8: 32.5 | P8: 15387.681 | T8: # | U8: Sample | V8: Include | W8: Type | X8: Mode [nm] | Y8: Mean [nm] | Z8: Standard deviation [nm] | AA8: D10 [nm] | AB8: D50 [nm] | AC8: D90 [nm] | AD8: Concentration [particles/ml]
A9: 37.5 | B9: 19847.96 | C9: 37.5 | D9: 41972.13 | E9: 37.5 | F9: 33359.808 | K9: 37.5 | L9: 21163.322 | M9: 37.5 | N9: 20089.466 | O9: 37.5 | P9: 43447.571 | T9: 1 | U9: Th_1H_For_ICP-MS_V5_3 | V9: TRUE | W9: Size Scatter | X9: 202.5 | Y9: 243 | Z9: 106 | AA9: 127 | AB9: 225 | AC9: 383 | AD9: 170000000 | AE9: 26000000
A10: 42.5 | B10: 19847.96 | C10: 42.5 | D10: 19161.19 | E10: 42.5 | F10: 45982.438 | K10: 42.5 | L10: 32205.056 | M10: 42.5 | N10: 32873.672 | O10: 42.5 | P10: 59740.41 | T10: 2 | U10: Th_1H_For_ICP-MS_V5_2 | V10: TRUE | W10: Size Scatter | X10: 177.5 | Y10: 242 | Z10: 107 | AA10: 131 | AB10: 223 | AC10: 379 | AD10: 150000000 | AE10: 21500000
A11: 47.5 | B11: 67663.5 | C11: 47.5 | D11: 111317.39 | E11: 47.5 | F11: 91063.259 | K11: 47.5 | L11: 76371.99 | M11: 47.5 | N11: 40178.932 | O11: 47.5 | P11: 108618.93 | T11: 3 | U11: Th_1H_For_ICP_20250519_V3_1 | V11: TRUE | W11: Size Scatter | X11: 177.5 | Y11: 244 | Z11: 115 | AA11: 125 | AB11: 224 | AC11: 382 | AD11: 155000000 | AE11: 12500000
A12: 52.5 | B12: 127207.38 | C12: 52.5 | D12: 125003.95 | E12: 52.5 | F12: 128931.15 | K12: 52.5 | L12: 144462.68 | M12: 52.5 | N12: 92228.912 | O12: 52.5 | P12: 134868.5
A13: 57.5 | B13: 152468.42 | C13: 57.5 | D13: 188874.59 | E13: 57.5 | F13: 121718.22 | K13: 57.5 | L13: 149983.55 | M13: 57.5 | N13: 136060.47 | O13: 57.5 | P13: 203660.49 | Y13: Mean (nm) | Z13: SD (nm) | AA13: SD of SD | AC13: SD of mean | AD13: SD of mean
A14: 62.5 | B14: 155174.96 | C14: 62.5 | D14: 247270.59 | E14: 62.5 | F14: 252452.6 | K14: 62.5 | L14: 264081.46 | M14: 62.5 | N14: 186284.14 | O14: 62.5 | P14: 240771.96 | U14: Concentrations for manuscript | Y14: =AVERAGE(Y3:Y5) -> 240 | Z14: =AVERAGE(Z3:Z5) -> 106.33333 | AA14: =STDEV(Z3:Z5) -> 2.8867513 | AC14: 8 | AD14: 14
A15: 67.5 | B15: 289599.78 | C15: 67.5 | D15: 370449.67 | E15: 67.5 | F15: 330893.23 | K15: 67.5 | L15: 283404.49 | M15: 67.5 | N15: 313213.04 | O15: 67.5 | P15: 272452.48 | V15: average | W15: stdev | Y15: =AVERAGE(Y9:Y11) -> 243 | Z15: =AVERAGE(Z9:Z11) -> 109.33333 | AA15: =STDEV(Z9:Z11) -> 4.9328829 | AC15: 8 | AD15: 10
A16: 72.5 | B16: 406883.18 | C16: 72.5 | D16: 397822.8 | E16: 72.5 | F16: 408432.24 | K16: 72.5 | L16: 506079.45 | M16: 72.5 | N16: 382613.01 | O16: 72.5 | P16: 497836.75 | U16: 0.5%ww | V16: =AVERAGE(AD3:AD5) -> 1.5666667e+08 | W16: =AVERAGE(AE3:AE5) -> 18200000 | AC16: 12 | AD16: 7
A17: 77.5 | B17: 461013.98 | C17: 77.5 | D17: 612245.64 | E17: 77.5 | F17: 787111.14 | K17: 77.5 | L17: 454551.36 | M17: 77.5 | N17: 390831.43 | O17: 77.5 | P17: 538568.85 | U17: 1%ww | V17: =AVERAGE(AD9:AD11) -> 1.5833333e+08 | W17: =AVERAGE(AE9:AE11) -> 20000000 | AB17: Average | AC17: =AVERAGE(AC14:AC16) -> 9.3333333 | AD17: =AVERAGE(AD14:AD16) -> 10.333333
A18: 82.5 | B18: 735276.7 | C18: 82.5 | D18: 651480.46 | E18: 82.5 | F18: 824979.03 | K18: 82.5 | L18: 679066.61 | M18: 82.5 | N18: 537849.8 | O18: 82.5 | P18: 698781.77 | U18: 3%ww | V18: =SUM('3R1'!R27*'3R1'!R31,'3R1'!T27*'3R1'!T31,'3R1'!V27*'3R1'!V31)/('3R1'!R31+'3R1'!T31+'3R1'!V31) -> 1.6237011e+08 | W18: =AVERAGE('3R1'!R32,'3R1'!T32,'3R1'!V32) -> 14490000 | X18: Extracted from previous data 3R2
A19: 87.5 | B19: 992397.99 | C19: 87.5 | D19: 1163358 | E19: 87.5 | F19: 983663.52 | K19: 87.5 | L19: 778442.21 | M19: 87.5 | N19: 841018.1 | O19: 87.5 | P19: 1011966.3
A20: 92.5 | B20: 1063670.2 | C20: 92.5 | D20: 1162445.5 | E20: 92.5 | F20: 1242427.4 | K20: 92.5 | L20: 1036082.7 | M20: 92.5 | N20: 924115.44 | O20: 92.5 | P20: 1093430.5 | U20: Average | V20: =AVERAGE(V16:V18) -> 1.5912337e+08 | W20: =AVERAGE(W16:W18) -> 17563333
A21: 97.5 | B21: 1520173.3 | C21: 97.5 | D21: 1467199.7 | E21: 97.5 | F21: 1466929.9 | K21: 97.5 | L21: 1211830.2 | M21: 97.5 | N21: 981644.36 | O21: 97.5 | P21: 1080758.3
A22: 102.5 | B22: 1320791.5 | C22: 102.5 | D22: 1478148.9 | E22: 102.5 | F22: 1553485.1 | K22: 102.5 | L22: 1534800.9 | M22: 102.5 | N22: 1014518 | O22: 102.5 | P22: 1328771.5
A23: 107.5 | B23: 2071405.3 | C23: 107.5 | D23: 1427964.9 | E23: 107.5 | F23: 1725693.8 | K23: 107.5 | L23: 2027998.4 | M23: 107.5 | N23: 1256504.8 | O23: 107.5 | P23: 1587646.7
A24: 112.5 | B24: 1896382.3 | C24: 112.5 | D24: 1924330.9 | E24: 112.5 | F24: 1649056.4 | K24: 112.5 | L24: 1638777.3 | M24: 112.5 | N24: 1162449.6 | O24: 112.5 | P24: 1519759.8
A25: 117.5 | B25: 2453027.4 | C25: 117.5 | D25: 2178901 | E25: 117.5 | F25: 2328875.2 | K25: 117.5 | L25: 2494511.6 | M25: 117.5 | N25: 1871973 | O25: 117.5 | P25: 2295480
A26: 122.5 | B26: 2818410.3 | C26: 122.5 | D26: 2065758.8 | E26: 122.5 | F26: 2337891.4 | K26: 122.5 | L26: 2764113.9 | M26: 122.5 | N26: 1796180.9 | O26: 122.5 | P26: 2657543.1
A27: 127.5 | B27: 3205445.5 | C27: 127.5 | D27: 2421609.4 | E27: 127.5 | F27: 2590344 | K27: 127.5 | L27: 2769634.8 | M27: 127.5 | N27: 2470091.2 | O27: 127.5 | P27: 2551639.6
A28: 132.5 | B28: 2699322.5 | C28: 132.5 | D28: 2366863.2 | E28: 132.5 | F28: 2650752.3 | K28: 132.5 | L28: 2984028.5 | M28: 132.5 | N28: 3096517.2 | O28: 132.5 | P28: 2272851.1
A29: 137.5 | B29: 2668648.4 | C29: 137.5 | D29: 2777460.1 | E29: 137.5 | F29: 2091750.1 | K29: 137.5 | L29: 2553400.9 | M29: 137.5 | N29: 2749517.4 | O29: 137.5 | P29: 2963486.4
A30: 142.5 | B30: 3440914.5 | C30: 142.5 | D30: 3766542.5 | E30: 142.5 | F30: 2341497.9 | K30: 142.5 | L30: 3298717.9 | M30: 142.5 | N30: 2541317.5 | O30: 142.5 | P30: 2605949.1
A31: 147.5 | B31: 3028618.2 | C31: 147.5 | D31: 3029292.9 | E31: 147.5 | F31: 2911319.4 | K31: 147.5 | L31: 3468024.4 | M31: 147.5 | N31: 3501046 | O31: 147.5 | P31: 2670215.3
A32: 152.5 | B32: 3162140.9 | C32: 152.5 | D32: 2814870 | E32: 152.5 | F32: 2808535.2 | K32: 152.5 | L32: 3252710.6 | M32: 152.5 | N32: 2712077.9 | O32: 152.5 | P32: 2910987.3
... A201: 997.5 | B201: 0 | C201: 997.5 | D201: 0 | E201: 997.5 | F201: 0 | K201: 997.5 | L201: 0 | M201: 997.5 | N201: 0 | O201: 997.5 | P201: 0

Sheet Fig 3a For sp-ICP-MS plot
B1: 0.3% w/w | C1: 0.3% w/w | D1: 0.3% w/w | E1: 0.7% w/w | F1: 0.7% w/w | G1: 0.7% w/w | H1: 2.7% w/w | I1: 2.7% w/w | J1: 2.7% w/w | S1: Average for Fig 1
A2: Size (nm) | B2: Concentration (NP/mL) | C2: Concentration (NP/mL) | D2: Concentration (NP/mL) | E2: Concentration (NP/mL) | F2: Concentration (NP/mL) | G2: Concentration (NP/mL) | H2: Concentration (NP/mL) | I2: Concentration (NP/mL) | J2: Concentration (NP/mL) | T2: Size (nm) | U2: 0.25% w/w | V2: 0.7% w/w | W2: 2.7% w/w
A3: ='0R1'!A2 -> 2.5 | B3: {='For sp-ICP-MS (table 2)'!$B$2:$B$201} -> 0 | C3: {='For sp-ICP-MS (table 2)'!$D$2:$D$201} -> 0 | D3: {='For sp-ICP-MS (table 2)'!$F$2:$F$201} -> 0 | E3: {='For sp-ICP-MS (table 2)'!$L$2:$L$201} -> 0 | F3: {='For sp-ICP-MS (table 2)'!$N$2:$N$201} -> 0 | G3: {='For sp-ICP-MS (table 2)'!$P$2:$P$201} -> 0 | H3: ='3R1'!B2 -> 0 | I3: ='3R1'!D2 -> 0 | J3: ='3R1'!F2 -> 0 | T3: 2.5 | U3: =AVERAGE(B3:D3) -> 0 | V3: =AVERAGE(E3:G3) -> 0 | W3: =AVERAGE(H3:J3) -> 0
A4: ='0R1'!A3 -> 7.5 | B4: 0 | C4: 0 | D4: 0 | E4: 0 | F4: 0 | G4: 0 | H4: ='3R1'!B3 -> 0 | I4: ='3R1'!D3 -> 0 | J4: ='3R1'!F3 -> 0 | T4: 7.5 | U4: =AVERAGE(B4:D4) -> 0 | V4: =AVERAGE(E4:G4) -> 0 | W4: =AVERAGE(H4:J4) -> 0
A5: ='0R1'!A4 -> 12.5 | B5: 0 | C5: 0 | D5: 0 | E5: 0 | F5: 0 | G5: 0 | H5: ='3R1'!B4 -> 0 | I5: ='3R1'!D4 -> 0 | J5: ='3R1'!F4 -> 0 | T5: 12.5 | U5: =AVERAGE(B5:D5) -> 0 | V5: =AVERAGE(E5:G5) -> 0 | W5: =AVERAGE(H5:J5) -> 0
A6: ='0R1'!A5 -> 17.5 | B6: 0 | C6: 0 | D6: 0 | E6: 0 | F6: 0 | G6: 0 | H6: ='3R1'!B5 -> 0 | I6: ='3R1'!D5 -> 0 | J6: ='3R1'!F5 -> 4453.9087 | T6: 17.5 | U6: =AVERAGE(B6:D6) -> 0 | V6: =AVERAGE(E6:G6) -> 0 | W6: =AVERAGE(H6:J6) -> 1484.6362
A7: ='0R1'!A6 -> 22.5 | B7: 0 | C7: 0 | D7: 0 | E7: 0 | F7: 0 | G7: 0 | H7: ='3R1'!B6 -> 0 | I7: ='3R1'!D6 -> 9726.6166 | J7: ='3R1'!F6 -> 0 | T7: 22.5 | U7: =AVERAGE(B7:D7) -> 0 | V7: =AVERAGE(E7:G7) -> 0 | W7: =AVERAGE(H7:J7) -> 3242.2055
A8: ='0R1'!A7 -> 27.5 | B8: 9021.7999 | C8: 0 | D8: 9016.1642 | E8: 4600.7223 | F8: 0 | G8: 9956.735 | H8: ='3R1'!B7 -> 0 | I8: ='3R1'!D7 -> 15032.044 | J8: ='3R1'!F7 -> 0 | T8: 27.5 | U8: =AVERAGE(B8:D8) -> 6012.6547 | V8: =AVERAGE(E8:G8) -> 4852.4858 | W8: =AVERAGE(H8:J8) -> 5010.6813
A9: ='0R1'!A8 -> 32.5 | B9: 18945.78 | C9: 16423.877 | D9: 28851.726 | E9: 11961.878 | F9: 0 | G9: 15387.681 | H9: ='3R1'!B8 -> 5410.2643 | I9: ='3R1'!D8 -> 13263.568 | J9: ='3R1'!F8 -> 9798.5992 | T9: 32.5 | U9: =AVERAGE(B9:D9) -> 21407.127 | V9: =AVERAGE(E9:G9) -> 9116.5198 | W9: =AVERAGE(H9:J9) -> 9490.8105
A10: ='0R1'!A9 -> 37.5 | B10: 19847.96 | C10: 41972.13 | D10: 33359.808 | E10: 21163.322 | F10: 20089.466 | G10: 43447.571 | H10: ='3R1'!B9 -> 14427.372 | I10: ='3R1'!D9 -> 20337.471 | J10: ='3R1'!F9 -> 62354.722 | T10: 37.5 | U10: =AVERAGE(B10:D10) -> 31726.633 | V10: =AVERAGE(E10:G10) -> 28233.453 | W10: =AVERAGE(H10:J10) -> 32373.188
A11: ='0R1'!A10 -> 42.5 | B11: 19847.96 | C11: 19161.19 | D11: 45982.438 | E11: 32205.056 | F11: 32873.672 | G11: 59740.41 | H11: ='3R1'!B10 -> 43282.115 | I11: ='3R1'!D10 -> 78697.171 | J11: ='3R1'!F10 -> 57010.032 | T11: 42.5 | U11: =AVERAGE(B11:D11) -> 28330.529 | V11: =AVERAGE(E11:G11) -> 41606.379 | W11: =AVERAGE(H11:J11) -> 59663.106
A12: ='0R1'!A11 -> 47.5 | B12: 67663.5 | C12: 111317.39 | D12: 91063.259 | E12: 76371.99 | F12: 40178.932 | G12: 108618.93 | H12: ='3R1'!B11 -> 104598.44 | I12: ='3R1'!D11 -> 151204.68 | J12: ='3R1'!F11 -> 165685.4 | T12: 47.5 | U12: =AVERAGE(B12:D12) -> 90014.716 | V12: =AVERAGE(E12:G12) -> 75056.616 | W12: =AVERAGE(H12:J12) -> 140496.17
A13: ='0R1'!A12 -> 52.5 | B13: 127207.38 | C13: 125003.95 | D13: 128931.15 | E13: 144462.68 | F13: 92228.912 | G13: 134868.5 | H13: ='3R1'!B12 -> 126239.5 | I13: ='3R1'!D12 -> 183037.24 | J13: ='3R1'!F12 -> 137180.39 | T13: 52.5 | U13: =AVERAGE(B13:D13) -> 127047.49 | V13: =AVERAGE(E13:G13) -> 123853.36 | W13: =AVERAGE(H13:J13) -> 148819.04
A14: ='0R1'!A13 -> 57.5 | B14: 152468.42 | C14: 188874.59 | D14: 121718.22 | E14: 149983.55 | F14: 136060.47 | G14: 203660.49 | H14: ='3R1'!B13 -> 178538.72 | I14: ='3R1'!D13 -> 308599.02 | J14: ='3R1'!F13 -> 185282.6 | T14: 57.5 | U14: =AVERAGE(B14:D14) -> 154353.74 | V14: =AVERAGE(E14:G14) -> 163234.84 | W14: =AVERAGE(H14:J14) -> 224140.11
A15: ='0R1'!A14 -> 62.5 | B15: 155174.96 | C15: 247270.59 | D15: 252452.6 | E15: 264081.46 | F15: 186284.14 | G15: 240771.96 | H15: ='3R1'!B14 -> 267808.08 | I15: ='3R1'!D14 -> 397907.04 | J15: ='3R1'!F14 -> 321572.21 | T15: 62.5 | U15: =AVERAGE(B15:D15) -> 218299.38 | V15: =AVERAGE(E15:G15) -> 230379.18 | W15: =AVERAGE(H15:J15) -> 329095.78
... A202: ='0R1'!A201 -> 997.5 | B202: 0 | C202: 0 | D202: 0 | E202: 0 | F202: 0 | G202: 0 | H202: ='3R1'!B201 -> 0 | I202: ='3R1'!D201 -> 0 | J202: ='3R1'!F201 -> 0 | T202: 997.5 | U202: =AVERAGE(B202:D202) -> 0 | V202: =AVERAGE(E202:G202) -> 0 | W202: =AVERAGE(H202:J202) -> 0

Sheet Fig S8a
A1: Size (nm) | B1: 0R1 | C1: 0R2 | D1: 0R3 | E1: R1 | F1: R2 | G1: R3 | H1: R1 | I1: R2 | J1: R3 | K1: R1 | L1: R2 | M1: R3 | X1: average for Fig 1 | Y1: =A1 -> Size (nm) | Z1: 0.25% w/w | AA1: 0.7% w/w | AB1: 2.7% w/w
A2: ='0R1'!A2 -> 2.5 | B2: =AVERAGE('0R1'!B2,'0R1'!D2,'0R1'!F2) -> 0 | C2: =AVERAGE('0R2'!B2,'0R2'!D2,'0R2'!F2) -> 0 | D2: =AVERAGE('0R3'!B2,'0R3'!D2,'0R3'!F2) -> 0 | E2: =AVERAGE('0.5R1'!B2,'0.5R1'!D2,'0.5R1'!F2) -> 0 | F2: =AVERAGE('0.5R2'!B2,'0.5R2'!D2,'0.5R2'!F2) -> 0 | G2: =AVERAGE('0.5R3'!B2,'0.5R3'!D2,'0.5R3'!F2) -> 0 | H2: =AVERAGE('1R1'!B2,'1R1'!D2,'1R1'!F2) -> 0 | I2: =AVERAGE('1R2'!B2,'1R2'!D2,'1R2'!F2) -> 0 | J2: =AVERAGE('1R3'!B2,'1R3'!D2,'1R3'!F2) -> 0 | K2: =AVERAGE('3R1'!B2,'3R1'!D2,'3R1'!F2) -> 0 | L2: =AVERAGE('3R2'!B2,'3R2'!D2,'3R2'!F2) -> 0 | M2: =AVERAGE('3R3'!B2,'3R3'!D2,'3R3'!F2) -> 0 | Y2: =A2 -> 2.5 | Z2: =AVERAGE(E2:G2) -> 0 | AA2: =AVERAGE(H2:J2) -> 0 | AB2: =AVERAGE(K2:M2) -> 0
A3: ='0R1'!A3 -> 7.5 | B3: =AVERAGE('0R1'!B3,'0R1'!D3,'0R1'!F3) -> 0 | C3: =AVERAGE('0R2'!B3,'0R2'!D3,'0R2'!F3) -> 0 | D3: =AVERAGE('0R3'!B3,'0R3'!D3,'0R3'!F3) -> 0 | E3: =AVERAGE('0.5R1'!B3,'0.5R1'!D3,'0.5R1'!F3) -> 0 | F3: =AVERAGE('0.5R2'!B3,'0.5R2'!D3,'0.5R2'!F3) -> 0 | G3: =AVERAGE('0.5R3'!B3,'0.5R3'!D3,'0.5R3'!F3) -> 0 | H3: =AVERAGE('1R1'!B3,'1R1'!D3,'1R1'!F3) -> 0 | I3: =AVERAGE('1R2'!B3,'1R2'!D3,'1R2'!F3) -> 0 | J3: =AVERAGE('1R3'!B3,'1R3'!D3,'1R3'!F3) -> 0 | K3: =AVERAGE('3R1'!B3,'3R1'!D3,'3R1'!F3) -> 0 | L3: =AVERAGE('3R2'!B3,'3R2'!D3,'3R2'!F3) -> 0 | M3: =AVERAGE('3R3'!B3,'3R3'!D3,'3R3'!F3) -> 0 | Y3: =A3 -> 7.5 | Z3: =AVERAGE(E3:G3) -> 0 | AA3: =AVERAGE(H3:J3) -> 0 | AB3: =AVERAGE(K3:M3) -> 0
A4: ='0R1'!A4 -> 12.5 | B4: =AVERAGE('0R1'!B4,'0R1'!D4,'0R1'!F4) -> 0 | C4: =AVERAGE('0R2'!B4,'0R2'!D4,'0R2'!F4) -> 0 | D4: =AVERAGE('0R3'!B4,'0R3'!D4,'0R3'!F4) -> 0 | E4: =AVERAGE('0.5R1'!B4,'0.5R1'!D4,'0.5R1'!F4) -> 0 | F4: =AVERAGE('0.5R2'!B4,'0.5R2'!D4,'0.5R2'!F4) -> 2266.9736 | G4: =AVERAGE('0.5R3'!B4,'0.5R3'!D4,'0.5R3'!F4) -> 1443.8077 | H4: =AVERAGE('1R1'!B4,'1R1'!D4,'1R1'!F4) -> 0 | I4: =AVERAGE('1R2'!B4,'1R2'!D4,'1R2'!F4) -> 0 | J4: =AVERAGE('1R3'!B4,'1R3'!D4,'1R3'!F4) -> 0 | K4: =AVERAGE('3R1'!B4,'3R1'!D4,'3R1'!F4) -> 0 | L4: =AVERAGE('3R2'!B4,'3R2'!D4,'3R2'!F4) -> 1474.0359 | M4: =AVERAGE('3R3'!B4,'3R3'!D4,'3R3'!F4) -> 0 | Y4: =A4 -> 12.5 | Z4: =AVERAGE(E4:G4) -> 1236.9271 | AA4: =AVERAGE(H4:J4) -> 0 | AB4: =AVERAGE(K4:M4) -> 491.34528
A5: ='0R1'!A5 -> 17.5 | B5: =AVERAGE('0R1'!B5,'0R1'!D5,'0R1'!F5) -> 0 | C5: =AVERAGE('0R2'!B5,'0R2'!D5,'0R2'!F5) -> 0 | D5: =AVERAGE('0R3'!B5,'0R3'!D5,'0R3'!F5) -> 0 | E5: =AVERAGE('0.5R1'!B5,'0.5R1'!D5,'0.5R1'!F5) -> 0 | F5: =AVERAGE('0.5R2'!B5,'0.5R2'!D5,'0.5R2'!F5) -> 1484.506 | G5: =AVERAGE('0.5R3'!B5,'0.5R3'!D5,'0.5R3'!F5) -> 1420.3892 | H5: =AVERAGE('1R1'!B5,'1R1'!D5,'1R1'!F5) -> 0 | I5: =AVERAGE('1R2'!B5,'1R2'!D5,'1R2'!F5) -> 0 | J5: =AVERAGE('1R3'!B5,'1R3'!D5,'1R3'!F5) -> 1758.8873 | K5: =AVERAGE('3R1'!B5,'3R1'!D5,'3R1'!F5) -> 1484.6362 | L5: =AVERAGE('3R2'!B5,'3R2'!D5,'3R2'!F5) -> 4273.6366 | M5: =AVERAGE('3R3'!B5,'3R3'!D5,'3R3'!F5) -> 1466.5909 | Y5: =A5 -> 17.5 | Z5: =AVERAGE(E5:G5) -> 968.29841 | AA5: =AVERAGE(H5:J5) -> 586.29577 | AB5: =AVERAGE(K5:M5) -> 2408.2879
A6: ='0R1'!A6 -> 22.5 | B6: =AVERAGE('0R1'!B6,'0R1'!D6,'0R1'!F6) -> 1694.0087 | C6: =AVERAGE('0R2'!B6,'0R2'!D6,'0R2'!F6) -> 3313.7249 | D6: =AVERAGE('0R3'!B6,'0R3'!D6,'0R3'!F6) -> 0 | E6: =AVERAGE('0.5R1'!B6,'0.5R1'!D6,'0.5R1'!F6) -> 1843.5127 | F6: =AVERAGE('0.5R2'!B6,'0.5R2'!D6,'0.5R2'!F6) -> 8012.539 | G6: =AVERAGE('0.5R3'!B6,'0.5R3'!D6,'0.5R3'!F6) -> 5940.2851 | H6: =AVERAGE('1R1'!B6,'1R1'!D6,'1R1'!F6) -> 0 | I6: =AVERAGE('1R2'!B6,'1R2'!D6,'1R2'!F6) -> 0 | J6: =AVERAGE('1R3'!B6,'1R3'!D6,'1R3'!F6) -> 1744.9727 | K6: =AVERAGE('3R1'!B6,'3R1'!D6,'3R1'!F6) -> 3242.2055 | L6: =AVERAGE('3R2'!B6,'3R2'!D6,'3R2'!F6) -> 15480.567 | M6: =AVERAGE('3R3'!B6,'3R3'!D6,'3R3'!F6) -> 1466.5909 | Y6: =A6 -> 22.5 | Z6: =AVERAGE(E6:G6) -> 5265.4456 | AA6: =AVERAGE(H6:J6) -> 581.65756 | AB6: =AVERAGE(K6:M6) -> 6729.788
A7: ='0R1'!A7 -> 27.5 | B7: =AVERAGE('0R1'!B7,'0R1'!D7,'0R1'!F7) -> 1657.6628 | C7: =AVERAGE('0R2'!B7,'0R2'!D7,'0R2'!F7) -> 3313.7249 | D7: =AVERAGE('0R3'!B7,'0R3'!D7,'0R3'!F7) -> 1716.8182 | E7: =AVERAGE('0.5R1'!B7,'0.5R1'!D7,'0.5R1'!F7) -> 0 | F7: =AVERAGE('0.5R2'!B7,'0.5R2'!D7,'0.5R2'!F7) -> 4936.1456 | G7: =AVERAGE('0.5R3'!B7,'0.5R3'!D7,'0.5R3'!F7) -> 1443.8077 | H7: =AVERAGE('1R1'!B7,'1R1'!D7,'1R1'!F7) -> 0 | I7: =AVERAGE('1R2'!B7,'1R2'!D7,'1R2'!F7) -> 0 | J7: =AVERAGE('1R3'!B7,'1R3'!D7,'1R3'!F7) -> 9444.5897 | K7: =AVERAGE('3R1'!B7,'3R1'!D7,'3R1'!F7) -> 5010.6813 | L7: =AVERAGE('3R2'!B7,'3R2'!D7,'3R2'!F7) -> 16690.174 | M7: =AVERAGE('3R3'!B7,'3R3'!D7,'3R3'!F7) -> 2053.2273 | Y7: =A7 -> 27.5 | Z7: =AVERAGE(E7:G7) -> 2126.6511 | AA7: =AVERAGE(H7:J7) -> 3148.1966 | AB7: =AVERAGE(K7:M7) -> 7918.0274
A8: ='0R1'!A8 -> 32.5 | B8: =AVERAGE('0R1'!B8,'0R1'!D8,'0R1'!F8) -> 10357.47 | C8: =AVERAGE('0R2'!B8,'0R2'!D8,'0R2'!F8) -> 14665.599 | D8: =AVERAGE('0R3'!B8,'0R3'!D8,'0R3'!F8) -> 5896.6585 | E8: =AVERAGE('0.5R1'!B8,'0.5R1'!D8,'0.5R1'!F8) -> 8108.9119 | F8: =AVERAGE('0.5R2'!B8,'0.5R2'!D8,'0.5R2'!F8) -> 17243.001 | G8: =AVERAGE('0.5R3'!B8,'0.5R3'!D8,'0.5R3'!F8) -> 6550.3438 | H8: =AVERAGE('1R1'!B8,'1R1'!D8,'1R1'!F8) -> 2195.7485 | I8: =AVERAGE('1R2'!B8,'1R2'!D8,'1R2'!F8) -> 9518.1523 | J8: =AVERAGE('1R3'!B8,'1R3'!D8,'1R3'!F8) -> 20998.114 | K8: =AVERAGE('3R1'!B8,'3R1'!D8,'3R1'!F8) -> 9490.8105 | L8: =AVERAGE('3R2'!B8,'3R2'!D8,'3R2'!F8) -> 32259.704 | M8: =AVERAGE('3R3'!B8,'3R3'!D8,'3R3'!F8) -> 7779.9768 | Y8: =A8 -> 32.5 | Z8: =AVERAGE(E8:G8) -> 10634.086 | AA8: =AVERAGE(H8:J8) -> 10904.005 | AB8: =AVERAGE(K8:M8) -> 16510.164
A9: ='0R1'!A9 -> 37.5 | B9: =AVERAGE('0R1'!B9,'0R1'!D9,'0R1'!F9) -> 32841.018 | C9: =AVERAGE('0R2'!B9,'0R2'!D9,'0R2'!F9) -> 28511.169 | D9: =AVERAGE('0R3'!B9,'0R3'!D9,'0R3'!F9) -> 15239.055 | E9: =AVERAGE('0.5R1'!B9,'0.5R1'!D9,'0.5R1'!F9) -> 28880.862 | F9: =AVERAGE('0.5R2'!B9,'0.5R2'!D9,'0.5R2'!F9) -> 21205.764 | G9: =AVERAGE('0.5R3'!B9,'0.5R3'!D9,'0.5R3'!F9) -> 14515.893 | H9: =AVERAGE('1R1'!B9,'1R1'!D9,'1R1'!F9) -> 2561.7065 | I9: =AVERAGE('1R2'!B9,'1R2'!D9,'1R2'!F9) -> 15435.925 | J9: =AVERAGE('1R3'!B9,'1R3'!D9,'1R3'!F9) -> 34233.889 | K9: =AVERAGE('3R1'!B9,'3R1'!D9,'3R1'!F9) -> 32373.188 | L9: =AVERAGE('3R2'!B9,'3R2'!D9,'3R2'!F9) -> 72914.384 | M9: =AVERAGE('3R3'!B9,'3R3'!D9,'3R3'!F9) -> 5108.3164 | Y9: =A9 -> 37.5 | Z9: =AVERAGE(E9:G9) -> 21534.173 | AA9: =AVERAGE(H9:J9) -> 17410.507 | AB9: =AVERAGE(K9:M9) -> 36798.63
A10: ='0R1'!A10 -> 42.5 | B10: =AVERAGE('0R1'!B10,'0R1'!D10,'0R1'!F10) -> 36163.613 | C10: =AVERAGE('0R2'!B10,'0R2'!D10,'0R2'!F10) -> 41731.211 | D10: =AVERAGE('0R3'!B10,'0R3'!D10,'0R3'!F10) -> 17598.149 | E10: =AVERAGE('0.5R1'!B10,'0.5R1'!D10,'0.5R1'!F10) -> 32134.337 | F10: =AVERAGE('0.5R2'!B10,'0.5R2'!D10,'0.5R2'!F10) -> 67869.814 | G10: =AVERAGE('0.5R3'!B10,'0.5R3'!D10,'0.5R3'!F10) -> 44375.047 | H10: =AVERAGE('1R1'!B10,'1R1'!D10,'1R1'!F10) -> 1744.9948 | I10: =AVERAGE('1R2'!B10,'1R2'!D10,'1R2'!F10) -> 30221.385 | J10: =AVERAGE('1R3'!B10,'1R3'!D10,'1R3'!F10) -> 47783.247 | K10: =AVERAGE('3R1'!B10,'3R1'!D10,'3R1'!F10) -> 59663.106 | L10: =AVERAGE('3R2'!B10,'3R2'!D10,'3R2'!F10) -> 99782.735 | M10: =AVERAGE('3R3'!B10,'3R3'!D10,'3R3'!F10) -> 4707.1807 | P10: Table summary | Y10: =A10 -> 42.5 | Z10: =AVERAGE(E10:G10) -> 48126.399 | AA10: =AVERAGE(H10:J10) -> 26583.209 | AB10: =AVERAGE(K10:M10) -> 54717.674
A11: ='0R1'!A11 -> 47.5 | B11: =AVERAGE('0R1'!B11,'0R1'!D11,'0R1'!F11) -> 57332.124 | C11: =AVERAGE('0R2'!B11,'0R2'!D11,'0R2'!F11) -> 101444.1 | D11: =AVERAGE('0R3'!B11,'0R3'!D11,'0R3'!F11) -> 12839.962 | E11: =AVERAGE('0.5R1'!B11,'0.5R1'!D11,'0.5R1'!F11) -> 58433.721 | F11: =AVERAGE('0.5R2'!B11,'0.5R2'!D11,'0.5R2'!F11) -> 97777.284 | G11: =AVERAGE('0.5R3'!B11,'0.5R3'!D11,'0.5R3'!F11) -> 44904.553 | H11: =AVERAGE('1R1'!B11,'1R1'!D11,'1R1'!F11) -> 8417.0357 | I11: =AVERAGE('1R2'!B11,'1R2'!D11,'1R2'!F11) -> 86022.078 | J11: =AVERAGE('1R3'!B11,'1R3'!D11,'1R3'!F11) -> 152151.63 | K11: =AVERAGE('3R1'!B11,'3R1'!D11,'3R1'!F11) -> 140496.17 | L11: =AVERAGE('3R2'!B11,'3R2'!D11,'3R2'!F11) -> 165216.18 | M11: =AVERAGE('3R3'!B11,'3R3'!D11,'3R3'!F11) -> 32495.064 | O11: Size (nm) | P11: stdev | Q11: Size average | R11: stdev | S11: Con | T11: Con stdev | U11: Average | V11: stdev | W11: Dilutions | Y11: =A11 -> 47.5 | Z11: =AVERAGE(E11:G11) -> 67038.519 | AA11: =AVERAGE(H11:J11) -> 82196.915 | AB11: =AVERAGE(K11:M11) -> 112735.81
A12: ='0R1'!A12 -> 52.5 | B12: =AVERAGE('0R1'!B12,'0R1'!D12,'0R1'!F12) -> 109610.62 | C12: =AVERAGE('0R2'!B12,'0R2'!D12,'0R2'!F12) -> 126051.23 | D12: =AVERAGE('0R3'!B12,'0R3'!D12,'0R3'!F12) -> 55242.031 | E12: =AVERAGE('0.5R1'!B12,'0.5R1'!D12,'0.5R1'!F12) -> 143702.72 | F12: =AVERAGE('0.5R2'!B12,'0.5R2'!D12,'0.5R2'!F12) -> 175646.04 | G12: =AVERAGE('0.5R3'!B12,'0.5R3'!D12,'0.5R3'!F12) -> 50782.019 | H12: =AVERAGE('1R1'!B12,'1R1'!D12,'1R1'!F12) -> 15551.216 | I12: =AVERAGE('1R2'!B12,'1R2'!D12,'1R2'!F12) -> 130979.98 | J12: =AVERAGE('1R3'!B12,'1R3'!D12,'1R3'!F12) -> 128889.87 | K12: =AVERAGE('3R1'!B12,'3R1'!D12,'3R1'!F12) -> 148819.04 | L12: =AVERAGE('3R2'!B12,'3R2'!D12,'3R2'!F12) -> 225584.47 | M12: =AVERAGE('3R3'!B12,'3R3'!D12,'3R3'!F12) -> 54696.26 | N12: 0R1 | O12: =SUM('0R1'!R25*'0R1'!R31,'0R1'!T25*'0R1'!T31,'0R1'!V25*'0R1'!V31)/('0R1'!R31+'0R1'!T31+'0R1'!V31) -> 267.89807 | P12: =SUM('0R1'!R26*'0R1'!R31,'0R1'!T26*'0R1'!T31,'0R1'!V26*'0R1'!V31)/('0R1'!R31+'0R1'!T31+'0R1'!V31) -> 122.66465 | S12: =SUM('0R1'!R27*'0R1'!R31,'0R1'!T27*'0R1'!T31,'0R1'!V27*'0R1'!V31)/('0R1'!R31+'0R1'!T31+'0R1'!V31) -> 1.5141977e+08 | T12: =SUM('0R1'!R32*'0R1'!R31,'0R1'!T32*'0R1'!T31,'0R1'!V32*'0R1'!V31)/('0R1'!R31+'0R1'!T31+'0R1'!V31) -> 15649634 | Y12: =A12 -> 52.5 | Z12: =AVERAGE(E12:G12) -> 123376.93 | AA12: =AVERAGE(H12:J12) -> 91807.025 | AB12: =AVERAGE(K12:M12) -> 143033.26
A13: ='0R1'!A13 -> 57.5 | B13: =AVERAGE('0R1'!B13,'0R1'!D13,'0R1'!F13) -> 124026.44 | C13: =AVERAGE('0R2'!B13,'0R2'!D13,'0R2'!F13) -> 153678.15 | D13: =AVERAGE('0R3'!B13,'0R3'!D13,'0R3'!F13) -> 83951.154 | E13: =AVERAGE('0.5R1'!B13,'0.5R1'!D13,'0.5R1'!F13) -> 190584.88 | F13: =AVERAGE('0.5R2'!B13,'0.5R2'!D13,'0.5R2'!F13) -> 240347.13 | G13: =AVERAGE('0.5R3'!B13,'0.5R3'!D13,'0.5R3'!F13) -> 86166.181 | H13: =AVERAGE('1R1'!B13,'1R1'!D13,'1R1'!F13) -> 21390.567 | I13: =AVERAGE('1R2'!B13,'1R2'!D13,'1R2'!F13) -> 207071.27 | J13: =AVERAGE('1R3'!B13,'1R3'!D13,'1R3'!F13) -> 165773.43 | K13: =AVERAGE('3R1'!B13,'3R1'!D13,'3R1'!F13) -> 224140.11 | L13: =AVERAGE('3R2'!B13,'3R2'!D13,'3R2'!F13) -> 285477.98 | M13: =AVERAGE('3R3'!B13,'3R3'!D13,'3R3'!F13) -> 62192.131 | N13: 0R2 | O13: =SUM('0R2'!R25*'0R2'!R31,'0R2'!T25*'0R2'!T31,'0R2'!V25*'0R2'!V31)/('0R2'!R31+'0R2'!T31+'0R2'!V31) -> 255.54226 | P13: =SUM('0R2'!R26*'0R2'!R31,'0R2'!T26*'0R2'!T31,'0R2'!V26*'0R2'!V31)/('0R2'!R31+'0R2'!T31+'0R2'!V31) -> 119.85109 | Q13: =AVERAGE(O12:O14) -> 270.67565 | R13: =STDEV(O12:O14) -> 16.696369 | S13: =SUM('0R2'!R27*'0R2'!R31,'0R2'!T27*'0R2'!T31,'0R2'!V27*'0R2'!V31)/('0R2'!R31+'0R2'!T31+'0R2'!V31) -> 1.5891144e+08 | T13: =SUM('0R2'!R32*'0R2'!R31,'0R2'!T32*'0R2'!T31,'0R2'!V32*'0R2'!V31)/('0R2'!R31+'0R2'!T31+'0R2'!V31) -> 20508639 | U13: =AVERAGE(S12:S14) -> 1.5667223e+08 | V13: =_xlfn.STDEV.S(S12:S14) -> 4565200.4 | W13: =S13/$S$13 -> 1 | Y13: =A13 -> 57.5 | Z13: =AVERAGE(E13:G13) -> 172366.06 | AA13: =AVERAGE(H13:J13) -> 131411.75 | AB13: =AVERAGE(K13:M13) -> 190603.41
A14: ='0R1'!A14 -> 62.5 | B14: =AVERAGE('0R1'!B14,'0R1'!D14,'0R1'!F14) -> 137193.62 | C14: =AVERAGE('0R2'!B14,'0R2'!D14,'0R2'!F14) -> 231907.18 | D14: =AVERAGE('0R3'!B14,'0R3'!D14,'0R3'!F14) -> 124209.07 | E14: =AVERAGE('0.5R1'!B14,'0.5R1'!D14,'0.5R1'!F14) -> 306447.95 | F14: =AVERAGE('0.5R2'!B14,'0.5R2'!D14,'0.5R2'!F14) -> 295788.39 | G14: =AVERAGE('0.5R3'!B14,'0.5R3'!D14,'0.5R3'!F14) -> 137879.11 | H14: =AVERAGE('1R1'!B14,'1R1'!D14,'1R1'!F14) -> 27893.704 | I14: =AVERAGE('1R2'!B14,'1R2'!D14,'1R2'!F14) -> 304678.62 | J14: =AVERAGE('1R3'!B14,'1R3'!D14,'1R3'!F14) -> 248006.93 | K14: =AVERAGE('3R1'!B14,'3R1'!D14,'3R1'!F14) -> 329095.78 | L14: =AVERAGE('3R2'!B14,'3R2'!D14,'3R2'!F14) -> 426433.9 | M14: =AVERAGE('3R3'!B14,'3R3'!D14,'3R3'!F14) -> 118235.84 | N14: 0R3 | O14: =SUM('0R3'!R25*'0R3'!R31,'0R3'!T25*'0R3'!T31,'0R3'!V25*'0R3'!V31)/('0R3'!R31+'0R3'!T31+'0R3'!V31) -> 288.58663 | P14: =SUM('0R3'!R26*'0R3'!R31,'0R3'!T26*'0R3'!T31,'0R3'!V26*'0R3'!V31)/('0R3'!R31+'0R3'!T31+'0R3'!V31) -> 126.0351 | S14: =SUM('0R3'!R27*'0R3'!R31,'0R3'!T27*'0R3'!T31,'0R3'!V27*'0R3'!V31)/('0R3'!R31+'0R3'!T31+'0R3'!V31) -> 1.5968548e+08 | T14: =SUM('0R3'!R32*'0R3'!R31,'0R3'!T32*'0R3'!T31,'0R3'!V32*'0R3'!V31)/('0R3'!R31+'0R3'!T31+'0R3'!V31) -> 19980486 | Y14: =A14 -> 62.5 | Z14: =AVERAGE(E14:G14) -> 246705.15 | AA14: =AVERAGE(H14:J14) -> 193526.42 | AB14: =AVERAGE(K14:M14) -> 291255.17
A15: ='0R1'!A15 -> 67.5 | B15: =AVERAGE('0R1'!B15,'0R1'!D15,'0R1'!F15) -> 214704.27 | C15: =AVERAGE('0R2'!B15,'0R2'!D15,'0R2'!F15) -> 311198.77 | D15: =AVERAGE('0R3'!B15,'0R3'!D15,'0R3'!F15) -> 154976.16 | E15: =AVERAGE('0.5R1'!B15,'0.5R1'!D15,'0.5R1'!F15) -> 435564.6 | F15: =AVERAGE('0.5R2'!B15,'0.5R2'!D15,'0.5R2'!F15) -> 461632.94 | G15: =AVERAGE('0.5R3'!B15,'0.5R3'!D15,'0.5R3'!F15) -> 141564.34 | H15: =AVERAGE('1R1'!B15,'1R1'!D15,'1R1'!F15) -> 40796.162 | I15: =AVERAGE('1R2'!B15,'1R2'!D15,'1R2'!F15) -> 429168.52 | J15: =AVERAGE('1R3'!B15,'1R3'!D15,'1R3'!F15) -> 271526.03 | K15: =AVERAGE('3R1'!B15,'3R1'!D15,'3R1'!F15) -> 485490.81 | L15: =AVERAGE('3R2'!B15,'3R2'!D15,'3R2'!F15) -> 585777.37 | M15: =AVERAGE('3R3'!B15,'3R3'!D15,'3R3'!F15) -> 180612.28 | N15: 0.5R1 | O15: =SUM('0.5R1'!R25*'0.5R1'!R31,'0.5R1'!T25*'0.5R1'!T31,'0.5R1'!V25*'0.5R1'!V31)/('0.5R1'!R31+'0.5R1'!T31+'0.5R1'!V31) -> 250.28581 | P15: =SUM('0.5R1'!R26*'0.5R1'!R31,'0.5R1'!T26*'0.5R1'!T31,'0.5R1'!V26*'0.5R1'!V31)/('0.5R1'!R31+'0.5R1'!T31+'0.5R1'!V31) -> 119.50876 | S15: =SUM('0.5R1'!R27*'0.5R1'!R31,'0.5R1'!T27*'0.5R1'!T31,'0.5R1'!V27*'0.5R1'!V31)/('0.5R1'!R31+'0.5R1'!T31+'0.5R1'!V31) -> 2.611851e+08 | T15: =SUM('0.5R1'!R32*'0.5R1'!R31,'0.5R1'!T32*'0.5R1'!T31,'0.5R1'!V32*'0.5R1'!V31)/('0.5R1'!R31+'0.5R1'!T31+'0.5R1'!V31) -> 18142373 | W15: =S15/$S$13 -> 1.643589 | Y15: =A15 -> 67.5 | Z15: =AVERAGE(E15:G15) -> 346253.96 | AA15: =AVERAGE(H15:J15) -> 247163.57 | AB15: =AVERAGE(K15:M15) -> 417293.49
A16: ='0R1'!A16 -> 72.5 | B16: =AVERAGE('0R1'!B16,'0R1'!D16,'0R1'!F16) -> 279633.26 | C16: =AVERAGE('0R2'!B16,'0R2'!D16,'0R2'!F16) -> 298012.67 | D16: =AVERAGE('0R3'!B16,'0R3'!D16,'0R3'!F16) -> 178419.34 | E16: =AVERAGE('0.5R1'!B16,'0.5R1'!D16,'0.5R1'!F16) -> 579608.34 | F16: =AVERAGE('0.5R2'!B16,'0.5R2'!D16,'0.5R2'!F16) -> 439423.76 | G16: =AVERAGE('0.5R3'!B16,'0.5R3'!D16,'0.5R3'!F16) -> 125012.93 | H16: =AVERAGE('1R1'!B16,'1R1'!D16,'1R1'!F16) -> 81541.349 | I16: =AVERAGE('1R2'!B16,'1R2'!D16,'1R2'!F16) -> 466658.21 | J16: =AVERAGE('1R3'!B16,'1R3'!D16,'1R3'!F16) -> 430243.84 | K16: =AVERAGE('3R1'!B16,'3R1'!D16,'3R1'!F16) -> 607295.13 | L16: =AVERAGE('3R2'!B16,'3R2'!D16,'3R2'!F16) -> 802512.6 | M16: =AVERAGE('3R3'!B16,'3R3'!D16,'3R3'!F16) -> 144752.5 | N16: 0.5R2 | O16: =SUM('0.5R2'!R25*'0.5R2'!R31,'0.5R2'!T25*'0.5R2'!T31,'0.5R2'!V25*'0.5R2'!V31)/('0.5R2'!R31+'0.5R2'!T31+'0.5R2'!V31) -> 231.61182 | P16: =SUM('0.5R2'!R26*'0.5R2'!R31,'0.5R2'!T26*'0.5R2'!T31,'0.5R2'!V26*'0.5R2'!V31)/('0.5R2'!R31+'0.5R2'!T31+'0.5R2'!V31) -> 126.50513 | Q16: =AVERAGE(O15:O17) -> 249.29492 | R16: =STDEV(O15:O17) -> 17.209062 | S16: =SUM('0.5R2'!R27*'0.5R2'!R31,'0.5R2'!T27*'0.5R2'!T31,'0.5R2'!V27*'0.5R2'!V31)/('0.5R2'!R31+'0.5R2'!T31+'0.5R2'!V31) -> 98150671 | T16: =SUM('0.5R2'!R32*'0.5R2'!R31,'0.5R2'!T32*'0.5R2'!T31,'0.5R2'!V32*'0.5R2'!V31)/('0.5R2'!R31+'0.5R2'!T31+'0.5R2'!V31) -> 15213337 | U16: =AVERAGE(S15:S17) -> 1.4464031e+08 | V16: =_xlfn.STDEV.S(S15:S17) -> 1.0161618e+08 | Y16: =A16 -> 72.5 | Z16: =AVERAGE(E16:G16) -> 381348.35 | AA16: =AVERAGE(H16:J16) -> 326147.8 | AB16: =AVERAGE(K16:M16) -> 518186.75
A17: ='0R1'!A17 -> 77.5 | B17: =AVERAGE('0R1'!B17,'0R1'!D17,'0R1'!F17) -> 320638.44 | C17: =AVERAGE('0R2'!B17,'0R2'!D17,'0R2'!F17) -> 490372.91 | D17: =AVERAGE('0R3'!B17,'0R3'!D17,'0R3'!F17) -> 234346.7 | E17: =AVERAGE('0.5R1'!B17,'0.5R1'!D17,'0.5R1'!F17) -> 724837.57 | F17: =AVERAGE('0.5R2'!B17,'0.5R2'!D17,'0.5R2'!F17) -> 569513.9 | G17: =AVERAGE('0.5R3'!B17,'0.5R3'!D17,'0.5R3'!F17) -> 228768.88 | H17: =AVERAGE('1R1'!B17,'1R1'!D17,'1R1'!F17) -> 71174.141 | I17: =AVERAGE('1R2'!B17,'1R2'!D17,'1R2'!F17) -> 718408.31 | J17: =AVERAGE('1R3'!B17,'1R3'!D17,'1R3'!F17) -> 451014.03 | K17: =AVERAGE('3R1'!B17,'3R1'!D17,'3R1'!F17) -> 835218.04 | L17: =AVERAGE('3R2'!B17,'3R2'!D17,'3R2'!F17) -> 1077912.2 | M17: =AVERAGE('3R3'!B17,'3R3'!D17,'3R3'!F17) -> 221796.78 | N17: 0.5R3 | O17: =SUM('0.5R3'!R25*'0.5R3'!R31,'0.5R3'!T25*'0.5R3'!T31,'0.5R3'!V25*'0.5R3'!V31)/('0.5R3'!R31+'0.5R3'!T31+'0.5R3'!V31) -> 265.98713 | P17: =SUM('0.5R3'!R26*'0.5R3'!R31,'0.5R3'!T26*'0.5R3'!T31,'0.5R3'!V26*'0.5R3'!V31)/('0.5R3'!R31+'0.5R3'!T31+'0.5R3'!V31) -> 130.07044 | S17: =SUM('0.5R3'!R27*'0.5R3'!R31,'0.5R3'!T27*'0.5R3'!T31,'0.5R3'!V27*'0.5R3'!V31)/('0.5R3'!R31+'0.5R3'!T31+'0.5R3'!V31) -> 74585168 | T17: =SUM('0.5R3'!R32*'0.5R3'!R31,'0.5R3'!T32*'0.5R3'!T31,'0.5R3'!V32*'0.5R3'!V31)/('0.5R3'!R31+'0.5R3'!T31+'0.5R3'!V31) -> 7926388.9 | Y17: =A17 -> 77.5 | Z17: =AVERAGE(E17:G17) -> 507706.78 | AA17: =AVERAGE(H17:J17) -> 413532.16 | AB17: =AVERAGE(K17:M17) -> 711642.33
A18: ='0R1'!A18 -> 82.5 | B18: =AVERAGE('0R1'!B18,'0R1'!D18,'0R1'!F18) -> 418029.06 | C18: =AVERAGE('0R2'!B18,'0R2'!D18,'0R2'!F18) -> 581104.36 | D18: =AVERAGE('0R3'!B18,'0R3'!D18,'0R3'!F18) -> 303688.74 | E18: =AVERAGE('0.5R1'!B18,'0.5R1'!D18,'0.5R1'!F18) -> 952679.38 | F18: =AVERAGE('0.5R2'!B18,'0.5R2'!D18,'0.5R2'!F18) -> 719933.79 | G18: =AVERAGE('0.5R3'!B18,'0.5R3'!D18,'0.5R3'!F18) -> 277736.82 | H18: =AVERAGE('1R1'!B18,'1R1'!D18,'1R1'!F18) -> 106057.61 | I18: =AVERAGE('1R2'!B18,'1R2'!D18,'1R2'!F18) -> 823262.74 | J18: =AVERAGE('1R3'!B18,'1R3'!D18,'1R3'!F18) -> 576776.42 | K18: =AVERAGE('3R1'!B18,'3R1'!D18,'3R1'!F18) -> 1066896.8 | L18: =AVERAGE('3R2'!B18,'3R2'!D18,'3R2'!F18) -> 1185474.9 | M18: =AVERAGE('3R3'!B18,'3R3'!D18,'3R3'!F18) -> 304239.99 | N18: 1R1 | O18: =SUM('1R1'!R25*'1R1'!R31,'1R1'!T25*'1R1'!T31,'1R1'!V25*'1R1'!V31)/('1R1'!R31+'1R1'!T31+'1R1'!V31) -> 300.2052 | P18: =SUM('1R1'!R26*'1R1'!R31,'1R1'!T26*'1R1'!T31,'1R1'!V26*'1R1'!V31)/('1R1'!R31+'1R1'!T31+'1R1'!V31) -> 120.74917 | S18: =SUM('1R1'!R27*'1R1'!R31,'1R1'!T27*'1R1'!T31,'1R1'!V27*'1R1'!V31)/('1R1'!R31+'1R1'!T31+'1R1'!V31) -> 1.2644349e+08 | T18: =SUM('1R1'!R32*'1R1'!R31,'1R1'!T32*'1R1'!T31,'1R1'!V32*'1R1'!V31)/('1R1'!R31+'1R1'!T31+'1R1'!V31) -> 12966001 | Y18: =A18 -> 82.5 | Z18: =AVERAGE(E18:G18) -> 650116.66 | AA18: =AVERAGE(H18:J18) -> 502032.26 | AB18: =AVERAGE(K18:M18) -> 852203.9
A19: ='0R1'!A19 -> 87.5 | B19: =AVERAGE('0R1'!B19,'0R1'!D19,'0R1'!F19) -> 477258.38 | C19: =AVERAGE('0R2'!B19,'0R2'!D19,'0R2'!F19) -> 823148.13 | D19: =AVERAGE('0R3'!B19,'0R3'!D19,'0R3'!F19) -> 382119.02 | E19: =AVERAGE('0.5R1'!B19,'0.5R1'!D19,'0.5R1'!F19) -> 1209009.8 | F19: =AVERAGE('0.5R2'!B19,'0.5R2'!D19,'0.5R2'!F19) -> 896378.57 | G19: =AVERAGE('0.5R3'!B19,'0.5R3'!D19,'0.5R3'!F19) -> 344630.19 | H19: =AVERAGE('1R1'!B19,'1R1'!D19,'1R1'!F19) -> 92167.284 | I19: =AVERAGE('1R2'!B19,'1R2'!D19,'1R2'!F19) -> 1131679.9 | J19: =AVERAGE('1R3'!B19,'1R3'!D19,'1R3'!F19) -> 657639.17 | K19: =AVERAGE('3R1'!B19,'3R1'!D19,'3R1'!F19) -> 1399173.9 | L19: =AVERAGE('3R2'!B19,'3R2'!D19,'3R2'!F19) -> 1275961.8 | M19: =AVERAGE('3R3'!B19,'3R3'!D19,'3R3'!F19) -> 255498.6 | N19: 1R2 | O19: =SUM('1R2'!R25*'1R2'!R31,'1R2'!T25*'1R2'!T31,'1R2'!V25*'1R2'!V31)/('1R2'!R31+'1R2'!T31+'1R2'!V31) -> 238.82203 | P19: =SUM('1R2'!R26*'1R2'!R31,'1R2'!T26*'1R2'!T31,'1R2'!V26*'1R2'!V31)/('1R2'!R31+'1R2'!T31+'1R2'!V31) -> 103.28479 | Q19: =AVERAGE(O18:O20) -> 252.83884 | R19: =STDEV(O18:O20) -> 42.144015 | S19: =SUM('1R2'!R27*'1R2'!R31,'1R2'!T27*'1R2'!T31,'1R2'!V27*'1R2'!V31)/('1R2'!R31+'1R2'!T31+'1R2'!V31) -> 2.052015e+08 | T19: =SUM('1R2'!R32*'1R2'!R31,'1R2'!T32*'1R2'!T31,'1R2'!V32*'1R2'!V31)/('1R2'!R31+'1R2'!T31+'1R2'!V31) -> 19736910 | U19: =AVERAGE(S18:S20) -> 1.3147974e+08 | V19: =_xlfn.STDEV.S(S18:S20) -> 71337089 | W19: =S19/$S$13 -> 1.2912947 | Y19: =A19 -> 87.5 | Z19: =AVERAGE(E19:G19) -> 816672.84 | AA19: =AVERAGE(H19:J19) -> 627162.13 | AB19: =AVERAGE(K19:M19) -> 976878.11
A20: ='0R1'!A20 -> 92.5 | B20: =AVERAGE('0R1'!B20,'0R1'!D20,'0R1'!F20) -> 547708.15 | C20: =AVERAGE('0R2'!B20,'0R2'!D20,'0R2'!F20) -> 816230.06 | D20: =AVERAGE('0R3'!B20,'0R3'!D20,'0R3'!F20) -> 498261.96 | E20: =AVERAGE('0.5R1'!B20,'0.5R1'!D20,'0.5R1'!F20) -> 1453042.5 | F20: =AVERAGE('0.5R2'!B20,'0.5R2'!D20,'0.5R2'!F20) -> 1069089.4 | G20: =AVERAGE('0.5R3'!B20,'0.5R3'!D20,'0.5R3'!F20) -> 338487.41 | H20: =AVERAGE('1R1'!B20,'1R1'!D20,'1R1'!F20) -> 162311.58 | I20: =AVERAGE('1R2'!B20,'1R2'!D20,'1R2'!F20) -> 1320511.1 | J20: =AVERAGE('1R3'!B20,'1R3'!D20,'1R3'!F20) -> 910668.81 | K20: =AVERAGE('3R1'!B20,'3R1'!D20,'3R1'!F20) -> 1436618.9 | L20: =AVERAGE('3R2'!B20,'3R2'!D20,'3R2'!F20) -> 1550368.4 | M20: =AVERAGE('3R3'!B20,'3R3'!D20,'3R3'!F20) -> 390621.6 | N20: 1R3 | O20: =SUM('1R3'!R25*'1R3'!R31,'1R3'!T25*'1R3'!T31,'1R3'!V25*'1R3'!V31)/('1R3'!R31+'1R3'!T31+'1R3'!V31) -> 219.48929 | P20: =SUM('1R3'!R26*'1R3'!R31,'1R3'!T26*'1R3'!T31,'1R3'!V26*'1R3'!V31)/('1R3'!R31+'1R3'!T31+'1R3'!V31) -> 124.14735 | S20: =SUM('1R3'!R27*'1R3'!R31,'1R3'!T27*'1R3'!T31,'1R3'!V27*'1R3'!V31)/('1R3'!R31+'1R3'!T31+'1R3'!V31) -> 62794228 | T20: =SUM('1R3'!R32*'1R3'!R31,'1R3'!T32*'1R3'!T31,'1R3'!V32*'1R3'!V31)/('1R3'!R31+'1R3'!T31+'1R3'!V31) -> 7608028 | Y20: =A20 -> 92.5 | Z20: =AVERAGE(E20:G20) -> 953539.75 | AA20: =AVERAGE(H20:J20) -> 797830.51 | AB20: =AVERAGE(K20:M20) -> 1125869.6
A21: ='0R1'!A21 -> 97.5 | B21: =AVERAGE('0R1'!B21,'0R1'!D21,'0R1'!F21) -> 704910.69 | C21: =AVERAGE('0R2'!B21,'0R2'!D21,'0R2'!F21) -> 1161314.5 | D21: =AVERAGE('0R3'!B21,'0R3'!D21,'0R3'!F21) -> 539812.92 | E21: =AVERAGE('0.5R1'!B21,'0.5R1'!D21,'0.5R1'!F21) -> 1507476.3 | F21: =AVERAGE('0.5R2'!B21,'0.5R2'!D21,'0.5R2'!F21) -> 1198413.6 | G21: =AVERAGE('0.5R3'!B21,'0.5R3'!D21,'0.5R3'!F21) -> 548404.15 | H21: =AVERAGE('1R1'!B21,'1R1'!D21,'1R1'!F21) -> 205980.31 | I21: =AVERAGE('1R2'!B21,'1R2'!D21,'1R2'!F21) -> 1590036.1 | J21: =AVERAGE('1R3'!B21,'1R3'!D21,'1R3'!F21) -> 921477.31 | K21: =AVERAGE('3R1'!B21,'3R1'!D21,'3R1'!F21) -> 2113732.9 | L21: =AVERAGE('3R2'!B21,'3R2'!D21,'3R2'!F21) -> 2050716.4 | M21: =AVERAGE('3R3'!B21,'3R3'!D21,'3R3'!F21) -> 546580.6 | N21: 3R1 | O21: =SUM('3R1'!R25*'3R1'!R31,'3R1'!T25*'3R1'!T31,'3R1'!V25*'3R1'!V31)/('3R1'!R31+'3R1'!T31+'3R1'!V31) -> 222.68971 | P21: =SUM('3R1'!R26*'3R1'!R31,'3R1'!T26*'3R1'!T31,'3R1'!V26*'3R1'!V31)/('3R1'!R31+'3R1'!T31+'3R1'!V31) -> 97.664603 | S21: =SUM('3R1'!R27*'3R1'!R31,'3R1'!T27*'3R1'!T31,'3R1'!V27*'3R1'!V31)/('3R1'!R31+'3R1'!T31+'3R1'!V31) -> 1.6237011e+08 | T21: =SUM('3R1'!R32*'3R1'!R31,'3R1'!T32*'3R1'!T31,'3R1'!V32*'3R1'!V31)/('3R1'!R31+'3R1'!T31+'3R1'!V31) -> 14460810 | W21: =S21/$S$13 -> 1.0217648 | Y21: =A21 -> 97.5 | Z21: =AVERAGE(E21:G21) -> 1084764.7 | AA21: =AVERAGE(H21:J21) -> 905831.25 | AB21: =AVERAGE(K21:M21) -> 1570343.3
A22: ='0R1'!A22 -> 102.5 | B22: =AVERAGE('0R1'!B22,'0R1'!D22,'0R1'!F22) -> 830767.74 | C22: =AVERAGE('0R2'!B22,'0R2'!D22,'0R2'!F22) -> 1442947.2 | D22: =AVERAGE('0R3'!B22,'0R3'!D22,'0R3'!F22) -> 703484.14 | E22: =AVERAGE('0.5R1'!B22,'0.5R1'!D22,'0.5R1'!F22) -> 1749573.6 | F22: =AVERAGE('0.5R2'!B22,'0.5R2'!D22,'0.5R2'!F22) -> 1266371.2 | G22: =AVERAGE('0.5R3'!B22,'0.5R3'!D22,'0.5R3'!F22) -> 610981.26 | H22: =AVERAGE('1R1'!B22,'1R1'!D22,'1R1'!F22) -> 230606.87 | I22: =AVERAGE('1R2'!B22,'1R2'!D22,'1R2'!F22) -> 1875391.5 | J22: =AVERAGE('1R3'!B22,'1R3'!D22,'1R3'!F22) -> 854228.45 | K22: =AVERAGE('3R1'!B22,'3R1'!D22,'3R1'!F22) -> 2147612.9 | L22: =AVERAGE('3R2'!B22,'3R2'!D22,'3R2'!F22) -> 2077333.6 | M22: =AVERAGE('3R3'!B22,'3R3'!D22,'3R3'!F22) -> 486089.97 | N22: 3R2 | O22: =SUM('3R2'!R25*'3R2'!R31,'3R2'!T25*'3R2'!T31,'3R2'!V25*'3R2'!V31)/('3R2'!R31+'3R2'!T31+'3R2'!V31) -> 214.12705 | P22: =SUM('3R2'!R26*'3R2'!R31,'3R2'!T26*'3R2'!T31,'3R2'!V26*'3R2'!V31)/('3R2'!R31+'3R2'!T31+'3R2'!V31) -> 104.80666 | Q22: =AVERAGE(O21:O23) -> 233.78385 | R22: =STDEV(O21:O23) -> 26.973039 | S22: =SUM('3R2'!R27*'3R2'!R31,'3R2'!T27*'3R2'!T31,'3R2'!V27*'3R2'!V31)/('3R2'!R31+'3R2'!T31+'3R2'!V31) -> 1.2372645e+08 | T22: =SUM('3R2'!R32*'3R2'!R31,'3R2'!T32*'3R2'!T31,'3R2'!V32*'3R2'!V31)/('3R2'!R31+'3R2'!T31+'3R2'!V31) -> 12482549 | U22: =AVERAGE(S21:S23) -> 1.1987409e+08 | V22: =_xlfn.STDEV.S(S21:S23) -> 44547308 | Y22: =A22 -> 102.5 | Z22: =AVERAGE(E22:G22) -> 1208975.3 | AA22: =AVERAGE(H22:J22) -> 986742.27 | AB22: =AVERAGE(K22:M22) -> 1570345.5
A23: ='0R1'!A23 -> 107.5 | B23: =AVERAGE('0R1'!B23,'0R1'!D23,'0R1'!F23) -> 974280.09 | C23: =AVERAGE('0R2'!B23,'0R2'!D23,'0R2'!F23) -> 1458780.4 | D23: =AVERAGE('0R3'!B23,'0R3'!D23,'0R3'!F23) -> 770137.8 | E23: =AVERAGE('0.5R1'!B23,'0.5R1'!D23,'0.5R1'!F23) -> 2106997.6 | F23: =AVERAGE('0.5R2'!B23,'0.5R2'!D23,'0.5R2'!F23) -> 1676599.4 | G23: =AVERAGE('0.5R3'!B23,'0.5R3'!D23,'0.5R3'!F23) -> 747845.74 | H23: =AVERAGE('1R1'!B23,'1R1'!D23,'1R1'!F23) -> 257559.66 | I23: =AVERAGE('1R2'!B23,'1R2'!D23,'1R2'!F23) -> 2207740.8 | J23: =AVERAGE('1R3'!B23,'1R3'!D23,'1R3'!F23) -> 1082798.8 | K23: =AVERAGE('3R1'!B23,'3R1'!D23,'3R1'!F23) -> 2620825.5 | L23: =AVERAGE('3R2'!B23,'3R2'!D23,'3R2'!F23) -> 1975730.2 | M23: =AVERAGE('3R3'!B23,'3R3'!D23,'3R3'!F23) -> 789851.33 | N23: 3R3 | O23: =SUM('3R3'!R25*'3R3'!R31,'3R3'!T25*'3R3'!T31,'3R3'!V25*'3R3'!V31)/('3R3'!R31+'3R3'!T31+'3R3'!V31) -> 264.53478 | P23: =SUM('3R3'!R26*'3R3'!R31,'3R3'!T26*'3R3'!T31,'3R3'!V26*'3R3'!V31)/('3R3'!R31+'3R3'!T31+'3R3'!V31) -> 144.12815 | S23: =SUM('3R3'!R27*'3R3'!R31,'3R3'!T27*'3R3'!T31,'3R3'!V27*'3R3'!V31)/('3R3'!R31+'3R3'!T31+'3R3'!V31) -> 73525707 | T23: =SUM('3R3'!R32*'3R3'!R31,'3R3'!T32*'3R3'!T31,'3R3'!V32*'3R3'!V31)/('3R3'!R31+'3R3'!T31+'3R3'!V31) -> 13725555 | Y23: =A23 -> 107.5 | Z23: =AVERAGE(E23:G23) -> 1510480.9 | AA23: =AVERAGE(H23:J23) -> 1182699.8 | AB23: =AVERAGE(K23:M23) -> 1795469
A24: ='0R1'!A24 -> 112.5 | B24: =AVERAGE('0R1'!B24,'0R1'!D24,'0R1'!F24) -> 1237976.1 | C24: =AVERAGE('0R2'!B24,'0R2'!D24,'0R2'!F24) -> 1672525.6 | D24: =AVERAGE('0R3'!B24,'0R3'!D24,'0R3'!F24) -> 745916.93 | E24: =AVERAGE('0.5R1'!B24,'0.5R1'!D24,'0.5R1'!F24) -> 2231557.5 | F24: =AVERAGE('0.5R2'!B24,'0.5R2'!D24,'0.5R2'!F24) -> 1742842 | G24: =AVERAGE('0.5R3'!B24,'0.5R3'!D24,'0.5R3'!F24) -> 772629.94 | H24: =AVERAGE('1R1'!B24,'1R1'!D24,'1R1'!F24) -> 317015.06 | I24: =AVERAGE('1R2'!B24,'1R2'!D24,'1R2'!F24) -> 2370796.8 | J24: =AVERAGE('1R3'!B24,'1R3'!D24,'1R3'!F24) -> 1191082.9 | K24: =AVERAGE('3R1'!B24,'3R1'!D24,'3R1'!F24) -> 2660040 | L24: =AVERAGE('3R2'!B24,'3R2'!D24,'3R2'!F24) -> 2566304.4 | M24: =AVERAGE('3R3'!B24,'3R3'!D24,'3R3'!F24) -> 779750.36 | N24: 5.7R1 | S24: =SUM('5.7R1'!R27*'5.7R1'!R31,'5.7R1'!T27*'5.7R1'!T31,'5.7R1'!V27*'5.7R1'!V31)/('5.7R1'!R31+'5.7R1'!T31+'5.7R1'!V31) -> 1.6128689e+08 | W24: =S24/$S$13 -> 1.0149483 | Y24: =A24 -> 112.5 | Z24: =AVERAGE(E24:G24) -> 1582343.2 | AA24: =AVERAGE(H24:J24) -> 1292964.9 | AB24: =AVERAGE(K24:M24) -> 2002031.6
A25: ='0R1'!A25 -> 117.5 | B25: =AVERAGE('0R1'!B25,'0R1'!D25,'0R1'!F25) -> 1218352.3 | C25: =AVERAGE('0R2'!B25,'0R2'!D25,'0R2'!F25) -> 1947343.8 | D25: =AVERAGE('0R3'!B25,'0R3'!D25,'0R3'!F25) -> 918353.65 | E25: =AVERAGE('0.5R1'!B25,'0.5R1'!D25,'0.5R1'!F25) -> 2818654 | F25: =AVERAGE('0.5R2'!B25,'0.5R2'!D25,'0.5R2'!F25) -> 1816220 | G25: =AVERAGE('0.5R3'!B25,'0.5R3'!D25,'0.5R3'!F25) -> 961275.82 | H25: =AVERAGE('1R1'!B25,'1R1'!D25,'1R1'!F25) -> 317753.87 | I25: =AVERAGE('1R2'!B25,'1R2'!D25,'1R2'!F25) -> 3082078.6 | J25: =AVERAGE('1R3'!B25,'1R3'!D25,'1R3'!F25) -> 1222979.2 | K25: =AVERAGE('3R1'!B25,'3R1'!D25,'3R1'!F25) -> 2945876.5 | L25: =AVERAGE('3R2'!B25,'3R2'!D25,'3R2'!F25) -> 2733263.3 | M25: =AVERAGE('3R3'!B25,'3R3'!D25,'3R3'!F25) -> 943181.7 | N25: 8.7R1 | S25: =SUM('8.7R1'!R27*'8.7R1'!R31,'8.7R1'!T27*'8.7R1'!T31,'8.7R1'!V27*'8.7R1'!V31)/('8.7R1'!R31+'8.7R1'!T31+'8.7R1'!V31) -> 1.6257897e+08 | W25: =S25/$S$13 -> 1.0230791 | Y25: =A25 -> 117.5 | Z25: =AVERAGE(E25:G25) -> 1865383.3 | AA25: =AVERAGE(H25:J25) -> 1540937.2 | AB25: =AVERAGE(K25:M25) -> 2207440.5
A26: ='0R1'!A26 -> 122.5 | B26: =AVERAGE('0R1'!B26,'0R1'!D26,'0R1'!F26) -> 1222315.1 | C26: =AVERAGE('0R2'!B26,'0R2'!D26,'0R2'!F26) -> 1888264.3 | D26: =AVERAGE('0R3'!B26,'0R3'!D26,'0R3'!F26) -> 1052066.4 | E26: =AVERAGE('0.5R1'!B26,'0.5R1'!D26,'0.5R1'!F26) -> 2989537.8 | F26: =AVERAGE('0.5R2'!B26,'0.5R2'!D26,'0.5R2'!F26) -> 1919824.7 | G26: =AVERAGE('0.5R3'!B26,'0.5R3'!D26,'0.5R3'!F26) -> 967979.85 | H26: =AVERAGE('1R1'!B26,'1R1'!D26,'1R1'!F26) -> 461848.18 | I26: =AVERAGE('1R2'!B26,'1R2'!D26,'1R2'!F26) -> 3449044.9 | J26: =AVERAGE('1R3'!B26,'1R3'!D26,'1R3'!F26) -> 1121248.9 | K26: =AVERAGE('3R1'!B26,'3R1'!D26,'3R1'!F26) -> 2870803.1 | L26: =AVERAGE('3R2'!B26,'3R2'!D26,'3R2'!F26) -> 3005133.7 | M26: =AVERAGE('3R3'!B26,'3R3'!D26,'3R3'!F26) -> 803139.74 | Y26: =A26 -> 122.5 | Z26: =AVERAGE(E26:G26) -> 1959114.1 | AA26: =AVERAGE(H26:J26) -> 1677380.7 | AB26: =AVERAGE(K26:M26) -> 2226358.8
A27: ='0R1'!A27 -> 127.5 | B27: =AVERAGE('0R1'!B27,'0R1'!D27,'0R1'!F27) -> 1639171.9 | C27: =AVERAGE('0R2'!B27,'0R2'!D27,'0R2'!F27) -> 2131878.8 | D27: =AVERAGE('0R3'!B27,'0R3'!D27,'0R3'!F27) -> 1275651.9 | E27: =AVERAGE('0.5R1'!B27,'0.5R1'!D27,'0.5R1'!F27) -> 3239910.2 | F27: =AVERAGE('0.5R2'!B27,'0.5R2'!D27,'0.5R2'!F27) -> 1599308.7 | G27: =AVERAGE('0.5R3'!B27,'0.5R3'!D27,'0.5R3'!F27) -> 1099385.7 | H27: =AVERAGE('1R1'!B27,'1R1'!D27,'1R1'!F27) -> 514410.67 | I27: =AVERAGE('1R2'!B27,'1R2'!D27,'1R2'!F27) -> 3399007.2 | J27: =AVERAGE('1R3'!B27,'1R3'!D27,'1R3'!F27) -> 1286577.8 | K27: =AVERAGE('3R1'!B27,'3R1'!D27,'3R1'!F27) -> 3455118.7 | L27: =AVERAGE('3R2'!B27,'3R2'!D27,'3R2'!F27) -> 3010006.1 | M27: =AVERAGE('3R3'!B27,'3R3'!D27,'3R3'!F27) -> 876820.15 | Y27: =A27 -> 127.5 | Z27: =AVERAGE(E27:G27) -> 1979534.9 | AA27: =AVERAGE(H27:J27) -> 1733331.9 | AB27: =AVERAGE(K27:M27) -> 2447315
A28: ='0R1'!A28 -> 132.5 | B28: =AVERAGE('0R1'!B28,'0R1'!D28,'0R1'!F28) -> 1735299.7 | C28: =AVERAGE('0R2'!B28,'0R2'!D28,'0R2'!F28) -> 2491043.4 | D28: =AVERAGE('0R3'!B28,'0R3'!D28,'0R3'!F28) -> 1418163.1 | E28: =AVERAGE('0.5R1'!B28,'0.5R1'!D28,'0.5R1'!F28) -> 3508555.9 | F28: =AVERAGE('0.5R2'!B28,'0.5R2'!D28,'0.5R2'!F28) -> 2091683.8 | G28: =AVERAGE('0.5R3'!B28,'0.5R3'!D28,'0.5R3'!F28) -> 997434.99 | H28: =AVERAGE('1R1'!B28,'1R1'!D28,'1R1'!F28) -> 603199.84 | I28: =AVERAGE('1R2'!B28,'1R2'!D28,'1R2'!F28) -> 3280910.9 | J28: =AVERAGE('1R3'!B28,'1R3'!D28,'1R3'!F28) -> 1548011 | K28: =AVERAGE('3R1'!B28,'3R1'!D28,'3R1'!F28) -> 3315833.4 | L28: =AVERAGE('3R2'!B28,'3R2'!D28,'3R2'!F28) -> 2938412.5 | M28: =AVERAGE('3R3'!B28,'3R3'!D28,'3R3'!F28) -> 1133798.2 | Y28: =A28 -> 132.5 | Z28: =AVERAGE(E28:G28) -> 2199224.9 | AA28: =AVERAGE(H28:J28) -> 1810707.3 | AB28: =AVERAGE(K28:M28) -> 2462681.3
A29: ='0R1'!A29 -> 137.5 | B29: =AVERAGE('0R1'!B29,'0R1'!D29,'0R1'!F29) -> 2072849.1 | C29: =AVERAGE('0R2'!B29,'0R2'!D29,'0R2'!F29) -> 2569276.8 | D29: =AVERAGE('0R3'!B29,'0R3'!D29,'0R3'!F29) -> 1616491.9 | E29: =AVERAGE('0.5R1'!B29,'0.5R1'!D29,'0.5R1'!F29) -> 3481481.9 | F29: =AVERAGE('0.5R2'!B29,'0.5R2'!D29,'0.5R2'!F29) -> 2195625.5 | G29: =AVERAGE('0.5R3'!B29,'0.5R3'!D29,'0.5R3'!F29) -> 1269014.5 | H29: =AVERAGE('1R1'!B29,'1R1'!D29,'1R1'!F29) -> 624448.94 | I29: =AVERAGE('1R2'!B29,'1R2'!D29,'1R2'!F29) -> 3934049.7 | J29: =AVERAGE('1R3'!B29,'1R3'!D29,'1R3'!F29) -> 1287917.3 | K29: =AVERAGE('3R1'!B29,'3R1'!D29,'3R1'!F29) -> 3242016.6 | L29: =AVERAGE('3R2'!B29,'3R2'!D29,'3R2'!F29) -> 3147914.9 | M29: =AVERAGE('3R3'!B29,'3R3'!D29,'3R3'!F29) -> 1152383 | Y29: =A29 -> 137.5 | Z29: =AVERAGE(E29:G29) -> 2315374 | AA29: =AVERAGE(H29:J29) -> 1948805.3 | AB29: =AVERAGE(K29:M29) -> 2514104.8
A30: ='0R1'!A30 -> 142.5 | B30: =AVERAGE('0R1'!B30,'0R1'!D30,'0R1'!F30) -> 2169866.6 | C30: =AVERAGE('0R2'!B30,'0R2'!D30,'0R2'!F30) -> 2807132.9 | D30: =AVERAGE('0R3'!B30,'0R3'!D30,'0R3'!F30) -> 1636731.2 | E30: =AVERAGE('0.5R1'!B30,'0.5R1'!D30,'0.5R1'!F30) -> 4093699.3 | F30: =AVERAGE('0.5R2'!B30,'0.5R2'!D30,'0.5R2'!F30) -> 1983466 | G30: =AVERAGE('0.5R3'!B30,'0.5R3'!D30,'0.5R3'!F30) -> 1047952.8 | H30: =AVERAGE('1R1'!B30,'1R1'!D30,'1R1'!F30) -> 815355.61 | I30: =AVERAGE('1R2'!B30,'1R2'!D30,'1R2'!F30) -> 3877701.1 | J30: =AVERAGE('1R3'!B30,'1R3'!D30,'1R3'!F30) -> 1461736 | K30: =AVERAGE('3R1'!B30,'3R1'!D30,'3R1'!F30) -> 3946674.2 | L30: =AVERAGE('3R2'!B30,'3R2'!D30,'3R2'!F30) -> 2837871.7 | M30: =AVERAGE('3R3'!B30,'3R3'!D30,'3R3'!F30) -> 1335540.4 | Y30: =A30 -> 142.5 | Z30: =AVERAGE(E30:G30) -> 2375039.4 | AA30: =AVERAGE(H30:J30) -> 2051597.6 | AB30: =AVERAGE(K30:M30) -> 2706695.4
A31: ='0R1'!A31 -> 147.5 | B31: =AVERAGE('0R1'!B31,'0R1'!D31,'0R1'!F31) -> 1986862.7 | C31: =AVERAGE('0R2'!B31,'0R2'!D31,'0R2'!F31) -> 2515859.2 | D31: =AVERAGE('0R3'!B31,'0R3'!D31,'0R3'!F31) -> 1720137.1 | E31: =AVERAGE('0.5R1'!B31,'0.5R1'!D31,'0.5R1'!F31) -> 5064850.9 | F31: =AVERAGE('0.5R2'!B31,'0.5R2'!D31,'0.5R2'!F31) -> 1749022.7 | G31: =AVERAGE('0.5R3'!B31,'0.5R3'!D31,'0.5R3'!F31) -> 1110363.9 | H31: =AVERAGE('1R1'!B31,'1R1'!D31,'1R1'!F31) -> 881947.7 | I31: =AVERAGE('1R2'!B31,'1R2'!D31,'1R2'!F31) -> 3903648.5 | J31: =AVERAGE('1R3'!B31,'1R3'!D31,'1R3'!F31) -> 1997956.5 | K31: =AVERAGE('3R1'!B31,'3R1'!D31,'3R1'!F31) -> 3983565.7 | L31: =AVERAGE('3R2'!B31,'3R2'!D31,'3R2'!F31) -> 2976027.5 | M31: =AVERAGE('3R3'!B31,'3R3'!D31,'3R3'!F31) -> 1115698.8 | Y31: =A31 -> 147.5 | Z31: =AVERAGE(E31:G31) -> 2641412.5 | AA31: =AVERAGE(H31:J31) -> 2261184.2 | AB31: =AVERAGE(K31:M31) -> 2691764
A32: ='0R1'!A32 -> 152.5 | B32: =AVERAGE('0R1'!B32,'0R1'!D32,'0R1'!F32) -> 2360340.2 | C32: =AVERAGE('0R2'!B32,'0R2'!D32,'0R2'!F32) -> 2814495.3 | D32: =AVERAGE('0R3'!B32,'0R3'!D32,'0R3'!F32) -> 1931853.4 | E32: =AVERAGE('0.5R1'!B32,'0.5R1'!D32,'0.5R1'!F32) -> 4845132.1 | F32: =AVERAGE('0.5R2'!B32,'0.5R2'!D32,'0.5R2'!F32) -> 1853962.3 | G32: =AVERAGE('0.5R3'!B32,'0.5R3'!D32,'0.5R3'!F32) -> 1174020.3 | H32: =AVERAGE('1R1'!B32,'1R1'!D32,'1R1'!F32) -> 859192.58 | I32: =AVERAGE('1R2'!B32,'1R2'!D32,'1R2'!F32) -> 3967640.6 | J32: =AVERAGE('1R3'!B32,'1R3'!D32,'1R3'!F32) -> 1544792.4 | K32: =AVERAGE('3R1'!B32,'3R1'!D32,'3R1'!F32) -> 3510169.7 | L32: =AVERAGE('3R2'!B32,'3R2'!D32,'3R2'!F32) -> 2771443.1 | M32: =AVERAGE('3R3'!B32,'3R3'!D32,'3R3'!F32) -> 1239163.2 | Y32: =A32 -> 152.5 | Z32: =AVERAGE(E32:G32) -> 2624371.6 | AA32: =AVERAGE(H32:J32) -> 2123875.2 | AB32: =AVERAGE(K32:M32) -> 2506925.3
A33: ='0R1'!A33 -> 157.5 | B33: =AVERAGE('0R1'!B33,'0R1'!D33,'0R1'!F33) -> 2369693.9 | C33: =AVERAGE('0R2'!B33,'0R2'!D33,'0R2'!F33) -> 2843989.5 | D33: =AVERAGE('0R3'!B33,'0R3'!D33,'0R3'!F33) -> 2243808.6 | E33: =AVERAGE('0.5R1'!B33,'0.5R1'!D33,'0.5R1'!F33) -> 5415568.5 | F33: =AVERAGE('0.5R2'!B33,'0.5R2'!D33,'0.5R2'!F33) -> 2328774.4 | G33: =AVERAGE('0.5R3'!B33,'0.5R3'!D33,'0.5R3'!F33) -> 1103776.8 | H33: =AVERAGE('1R1'!B33,'1R1'!D33,'1R1'!F33) -> 1164374.8 | I33: =AVERAGE('1R2'!B33,'1R2'!D33,'1R2'!F33) -> 4476877.4 | J33: =AVERAGE('1R3'!B33,'1R3'!D33,'1R3'!F33) -> 1561181.3 | K33: =AVERAGE('3R1'!B33,'3R1'!D33,'3R1'!F33) -> 3367579.8 | L33: =AVERAGE('3R2'!B33,'3R2'!D33,'3R2'!F33) -> 2702680 | M33: =AVERAGE('3R3'!B33,'3R3'!D33,'3R3'!F33) -> 1407434.9 | Y33: =A33 -> 157.5 | Z33: =AVERAGE(E33:G33) -> 2949373.2 | AA33: =AVERAGE(H33:J33) -> 2400811.2 | AB33: =AVERAGE(K33:M33) -> 2492564.9
A34: ='0R1'!A34 -> 162.5 | B34: =AVERAGE('0R1'!B34,'0R1'!D34,'0R1'!F34) -> 2678469.9 | C34: =AVERAGE('0R2'!B34,'0R2'!D34,'0R2'!F34) -> 3568188.1 | D34: =AVERAGE('0R3'!B34,'0R3'!D34,'0R3'!F34) -> 2219837.3 | E34: =AVERAGE('0.5R1'!B34,'0.5R1'!D34,'0.5R1'!F34) -> 5187978.1 | F34: =AVERAGE('0.5R2'!B34,'0.5R2'!D34,'0.5R2'!F34) -> 2418470.8 | G34: =AVERAGE('0.5R3'!B34,'0.5R3'!D34,'0.5R3'!F34) -> 1078304.4 | H34: =AVERAGE('1R1'!B34,'1R1'!D34,'1R1'!F34) -> 1256801.3 | I34: =AVERAGE('1R2'!B34,'1R2'!D34,'1R2'!F34) -> 4427088.2 | J34: =AVERAGE('1R3'!B34,'1R3'!D34,'1R3'!F34) -> 1552532.6 | K34: =AVERAGE('3R1'!B34,'3R1'!D34,'3R1'!F34) -> 4262279.5 | L34: =AVERAGE('3R2'!B34,'3R2'!D34,'3R2'!F34) -> 2776084 | M34: =AVERAGE('3R3'!B34,'3R3'!D34,'3R3'!F34) -> 1427696.5 | P34: C1 | Q34: C2 | R34: V1 | S34: V2 | Y34: =A34 -> 162.5 | Z34: =AVERAGE(E34:G34) -> 2894917.8 | AA34: =AVERAGE(H34:J34) -> 2412140.7 | AB34: =AVERAGE(K34:M34) -> 2822020
A35: ='0R1'!A35 -> 167.5 | B35: =AVERAGE('0R1'!B35,'0R1'!D35,'0R1'!F35) -> 2806065.4 | C35: =AVERAGE('0R2'!B35,'0R2'!D35,'0R2'!F35) -> 3000398.6 | D35: =AVERAGE('0R3'!B35,'0R3'!D35,'0R3'!F35) -> 2304861.3 | E35: =AVERAGE('0.5R1'!B35,'0.5R1'!D35,'0.5R1'!F35) -> 5522816.7 | F35: =AVERAGE('0.5R2'!B35,'0.5R2'!D35,'0.5R2'!F35) -> 2256348.9 | G35: =AVERAGE('0.5R3'!B35,'0.5R3'!D35,'0.5R3'!F35) -> 1089487.5 | H35: =AVERAGE('1R1'!B35,'1R1'!D35,'1R1'!F35) -> 1479592.9 | I35: =AVERAGE('1R2'!B35,'1R2'!D35,'1R2'!F35) -> 4480739 | J35: =AVERAGE('1R3'!B35,'1R3'!D35,'1R3'!F35) -> 1457277.3 | K35: =AVERAGE('3R1'!B35,'3R1'!D35,'3R1'!F35) -> 3861132.3 | L35: =AVERAGE('3R2'!B35,'3R2'!D35,'3R2'!F35) -> 2613875 | M35: =AVERAGE('3R3'!B35,'3R3'!D35,'3R3'!F35) -> 1604240.6 | O35: 0 | Y35: =A35 -> 167.5 | Z35: =AVERAGE(E35:G35) -> 2956217.7 | AA35: =AVERAGE(H35:J35) -> 2472536.4 | AB35: =AVERAGE(K35:M35) -> 2693082.6
A36: ='0R1'!A36 -> 172.5 | B36: =AVERAGE('0R1'!B36,'0R1'!D36,'0R1'!F36) -> 2820630.2 | C36: =AVERAGE('0R2'!B36,'0R2'!D36,'0R2'!F36) -> 3144468.9 | D36: =AVERAGE('0R3'!B36,'0R3'!D36,'0R3'!F36) -> 2311006.2 | E36: =AVERAGE('0.5R1'!B36,'0.5R1'!D36,'0.5R1'!F36) -> 5339479.5 | F36: =AVERAGE('0.5R2'!B36,'0.5R2'!D36,'0.5R2'!F36) -> 2002419.2 | G36: =AVERAGE('0.5R3'!B36,'0.5R3'!D36,'0.5R3'!F36) -> 1156096.2 | H36: =AVERAGE('1R1'!B36,'1R1'!D36,'1R1'!F36) -> 1559185.5 | I36: =AVERAGE('1R2'!B36,'1R2'!D36,'1R2'!F36) -> 4893600.9 | J36: =AVERAGE('1R3'!B36,'1R3'!D36,'1R3'!F36) -> 1511578.5 | K36: =AVERAGE('3R1'!B36,'3R1'!D36,'3R1'!F36) -> 3236627.7 | L36: =AVERAGE('3R2'!B36,'3R2'!D36,'3R2'!F36) -> 2619362.8 | M36: =AVERAGE('3R3'!B36,'3R3'!D36,'3R3'!F36) -> 1400607.8 | O36: 0.5 | P36: =S15 -> 2.611851e+08 | Q36: 1.5891144e+08 | R36: =S36*Q36/P36 -> 1.2168492 | S36: 2 | U36: =S36-R36+0.7843 -> 1.5674508 | V36: =R36/2 -> 0.6084246 | Y36: =A36 -> 172.5 | Z36: =AVERAGE(E36:G36) -> 2832665 | AA36: =AVERAGE(H36:J36) -> 2654788.3 | AB36: =AVERAGE(K36:M36) -> 2418866.1
A37: ='0R1'!A37 -> 177.5 | B37: =AVERAGE('0R1'!B37,'0R1'!D37,'0R1'!F37) -> 2771388.7 | C37: =AVERAGE('0R2'!B37,'0R2'!D37,'0R2'!F37) -> 3278921.6 | D37: =AVERAGE('0R3'!B37,'0R3'!D37,'0R3'!F37) -> 2136645.6 | E37: =AVERAGE('0.5R1'!B37,'0.5R1'!D37,'0.5R1'!F37) -> 5882396.4 | F37: =AVERAGE('0.5R2'!B37,'0.5R2'!D37,'0.5R2'!F37) -> 2330570.3 | G37: =AVERAGE('0.5R3'!B37,'0.5R3'!D37,'0.5R3'!F37) -> 1630136.4 | H37: =AVERAGE('1R1'!B37,'1R1'!D37,'1R1'!F37) -> 1658471.5 | I37: =AVERAGE('1R2'!B37,'1R2'!D37,'1R2'!F37) -> 4070833.2 | J37: =AVERAGE('1R3'!B37,'1R3'!D37,'1R3'!F37) -> 1491560.4 | K37: =AVERAGE('3R1'!B37,'3R1'!D37,'3R1'!F37) -> 3766103 | L37: =AVERAGE('3R2'!B37,'3R2'!D37,'3R2'!F37) -> 3083852.1 | M37: =AVERAGE('3R3'!B37,'3R3'!D37,'3R3'!F37) -> 1388426.1 | O37: 1 | P37: =S19 -> 2.052015e+08 | Q37: 1.5891144e+08 | R37: =S37*Q37/P37 -> 1.5488332 | S37: 2 | U37: =S37-R37 -> 0.45116684 | V37: =R37/2 -> 0.77441658 | Y37: =A37 -> 177.5 | Z37: =AVERAGE(E37:G37) -> 3281034.4 | AA37: =AVERAGE(H37:J37) -> 2406955 | AB37: =AVERAGE(K37:M37) -> 2746127.1
A38: ='0R1'!A38 -> 182.5 | B38: =AVERAGE('0R1'!B38,'0R1'!D38,'0R1'!F38) -> 2910024.1 | C38: =AVERAGE('0R2'!B38,'0R2'!D38,'0R2'!F38) -> 3163722.7 | D38: =AVERAGE('0R3'!B38,'0R3'!D38,'0R3'!F38) -> 2467246.9 | E38: =AVERAGE('0.5R1'!B38,'0.5R1'!D38,'0.5R1'!F38) -> 6210370 | F38: =AVERAGE('0.5R2'!B38,'0.5R2'!D38,'0.5R2'!F38) -> 2315823.8 | G38: =AVERAGE('0.5R3'!B38,'0.5R3'!D38,'0.5R3'!F38) -> 1546300.1 | H38: =AVERAGE('1R1'!B38,'1R1'!D38,'1R1'!F38) -> 2074258.9 | I38: =AVERAGE('1R2'!B38,'1R2'!D38,'1R2'!F38) -> 4455444.7 | J38: =AVERAGE('1R3'!B38,'1R3'!D38,'1R3'!F38) -> 1933805.1 | K38: =AVERAGE('3R1'!B38,'3R1'!D38,'3R1'!F38) -> 3773080.5 | L38: =AVERAGE('3R2'!B38,'3R2'!D38,'3R2'!F38) -> 2748699.5 | M38: =AVERAGE('3R3'!B38,'3R3'!D38,'3R3'!F38) -> 1191612.2 | O38: 1 | P38: 196000000 | Q38: 1.5891144e+08 | R38: =S38*Q38/P38 -> 1.6215453 | S38: 2 | T38: 1630.9 | U38: =S38-R38 -> 0.3784547 | V38: =R38/2 -> 0.81077265 | Y38: =A38 -> 182.5 | Z38: =AVERAGE(E38:G38) -> 3357498 | AA38: =AVERAGE(H38:J38) -> 2821169.6 | AB38: =AVERAGE(K38:M38) -> 2571130.7
A39: ='0R1'!A39 -> 187.5 | B39: =AVERAGE('0R1'!B39,'0R1'!D39,'0R1'!F39) -> 3272235.5 | C39: =AVERAGE('0R2'!B39,'0R2'!D39,'0R2'!F39) -> 3426144.6 | D39: =AVERAGE('0R3'!B39,'0R3'!D39,'0R3'!F39) -> 2488438.4 | E39: =AVERAGE('0.5R1'!B39,'0.5R1'!D39,'0.5R1'!F39) -> 6289551.6 | F39: =AVERAGE('0.5R2'!B39,'0.5R2'!D39,'0.5R2'!F39) -> 2099240.6 | G39: =AVERAGE('0.5R3'!B39,'0.5R3'!D39,'0.5R3'!F39) -> 1372700.5 | H39: =AVERAGE('1R1'!B39,'1R1'!D39,'1R1'!F39) -> 1807973.5 | I39: =AVERAGE('1R2'!B39,'1R2'!D39,'1R2'!F39) -> 4862394.6 | J39: =AVERAGE('1R3'!B39,'1R3'!D39,'1R3'!F39) -> 1846301.8 | K39: =AVERAGE('3R1'!B39,'3R1'!D39,'3R1'!F39) -> 3851315.3 | L39: =AVERAGE('3R2'!B39,'3R2'!D39,'3R2'!F39) -> 2669327.4 | M39: =AVERAGE('3R3'!B39,'3R3'!D39,'3R3'!F39) -> 1447476.8 | O39: 1 | P39: 180000000 | Q39: 1.5891144e+08 | R39: =S39*Q39/P39 -> 1.6924068 | S39: 1.917 | T39: 1692.4 | U39: =S39-R39 -> 0.22459317 | V39: =R39/2 -> 0.84620342 | Y39: =A39 -> 187.5 | Z39: =AVERAGE(E39:G39) -> 3253830.9 | AA39: =AVERAGE(H39:J39) -> 2838890 | AB39: =AVERAGE(K39:M39) -> 2656039.8
A40: ='0R1'!A40 -> 192.5 | B40: =AVERAGE('0R1'!B40,'0R1'!D40,'0R1'!F40) -> 3111355.9 | C40: =AVERAGE('0R2'!B40,'0R2'!D40,'0R2'!F40) -> 2839989.5 | D40: =AVERAGE('0R3'!B40,'0R3'!D40,'0R3'!F40) -> 2703478.3 | E40: =AVERAGE('0.5R1'!B40,'0.5R1'!D40,'0.5R1'!F40) -> 5770462.2 | F40: =AVERAGE('0.5R2'!B40,'0.5R2'!D40,'0.5R2'!F40) -> 2079443.7 | G40: =AVERAGE('0.5R3'!B40,'0.5R3'!D40,'0.5R3'!F40) -> 1496077.5 | H40: =AVERAGE('1R1'!B40,'1R1'!D40,'1R1'!F40) -> 2180111.8 | I40: =AVERAGE('1R2'!B40,'1R2'!D40,'1R2'!F40) -> 4444782 | J40: =AVERAGE('1R3'!B40,'1R3'!D40,'1R3'!F40) -> 1691683.5 | K40: =AVERAGE('3R1'!B40,'3R1'!D40,'3R1'!F40) -> 3571454.8 | L40: =AVERAGE('3R2'!B40,'3R2'!D40,'3R2'!F40) -> 2638513.6 | M40: =AVERAGE('3R3'!B40,'3R3'!D40,'3R3'!F40) -> 1385273.4 | Y40: =A40 -> 192.5 | Z40: =AVERAGE(E40:G40) -> 3115327.8 | AA40: =AVERAGE(H40:J40) -> 2772192.4 | AB40: =AVERAGE(K40:M40) -> 2531747.3
...

Sheet 0.5R1
A1: Size [nm] - 1. Th_0.5E_2xCen_1 | B1: Concentration [particles/ml] - 1. Th_0.5E_2xCen_1 | C1: Size [nm] - 1. Th_0.5E_2xCen_2 | D1: Concentration [particles/ml] - 1. Th_0.5E_2xCen_2 | E1: Size [nm] - 1. Th_0.5E_2xCen_3 | F1: Concentration [particles/ml] - 1. Th_0.5E_2xCen_3
A2: 2.5 | B2: 0 | C2: 2.5 | D2: 0 | E2: 2.5 | F2: 0
A3: 7.5 | B3: 0 | C3: 7.5 | D3: 0 | E3: 7.5 | F3: 0
A4: 12.5 | B4: 0 | C4: 12.5 | D4: 0 | E4: 12.5 | F4: 0
A5: 17.5 | B5: 0 | C5: 17.5 | D5: 0 | E5: 17.5 | F5: 0
A6: 22.5 | B6: 5530.5382 | C6: 22.5 | D6: 0 | E6: 22.5 | F6: 0
A7: 27.5 | B7: 0 | C7: 27.5 | D7: 0 | E7: 27.5 | F7: 0
A8: 32.5 | B8: 18803.83 | C8: 32.5 | D8: 0 | E8: 32.5 | F8: 5522.9056
A9: 37.5 | B9: 43138.198 | C9: 37.5 | D9: 11471.534 | E9: 37.5 | F9: 32032.852
A10: 42.5 | B10: 66366.459 | C10: 42.5 | D10: 5735.7671 | E10: 42.5 | F10: 24300.785
A11: 47.5 | B11: 66366.459 | C11: 47.5 | D11: 78006.432 | E11: 47.5 | F11: 30928.271
A12: 52.5 | B12: 258829.19 | C12: 52.5 | D12: 88330.813 | E12: 52.5 | F12: 83948.165
A13: 57.5 | B13: 211266.56 | C13: 57.5 | D13: 159454.32 | E13: 57.5 | F13: 201033.76
... A21: 97.5 | B21: 1527534.7 | C21: 97.5 | D21: 1557834.3 | E21: 97.5 | F21: 1437060
A22: 102.5 | B22: 1682389.7 | C22: 102.5 | D22: 1924923.4 | E22: 102.5 | F22: 1641407.5 | R22: Merged | T22: Merged | V22: Merged
A23: 107.5 | B23: 2298491.7 | C23: 107.5 | D23: 2192210.2 | E23: 107.5 | F23: 1830290.9 | Q23: Sample | R23: Th_0.5E_2xCen_1 | S23: Sample | T23: Th_0.5E_2xCen_2 | U23: Sample | V23: Th_0.5E_2xCen_3
A24: 112.5 | B24: 2423481.9 | C24: 112.5 | D24: 2047668.8 | E24: 112.5 | F24: 2223521.8 | Q24: Mode [nm] | R24: 202.5 | S24: Mode [nm] | T24: 202.5 | U24: Mode [nm] | V24: 187.5
A25: 117.5 | B25: 2692266 | C25: 117.5 | D25: 2648777.2 | E25: 117.5 | F25: 3114918.8 | Q25: Mean [nm] | R25: 253 | S25: Mean [nm] | T25: 250 | U25: Mean [nm] | V25: 248
A26: 122.5 | B26: 2409102.5 | C26: 122.5 | D26: 3287741.7 | E26: 122.5 | F26: 3271769.3 | Q26: Standard deviation [nm] | R26: 138 | S26: Standard deviation [nm] | T26: 111 | U26: Standard deviation [nm] | V26: 111
A27: 127.5 | B27: 3024098.3 | C27: 127.5 | D27: 3324450.6 | E27: 127.5 | F27: 3371181.6 | Q27: Concentration [particles/ml] | R27: 250000000 | S27: Concentration [particles/ml] | T27: 275000000 | U27: Concentration [particles/ml] | V27: 257000000
A28: 132.5 | B28: 3242001.5 | C28: 132.5 | D28: 3513730.9 | E28: 132.5 | F28: 3769935.4 | Q28: D10 [nm] | R28: 134 | S28: D10 [nm] | T28: 136 | U28: D10 [nm] | V28: 134
A29: 137.5 | B29: 2806195.1 | C29: 137.5 | D29: 3692686.8 | E29: 137.5 | F29: 3945563.8 | Q29: D50 [nm] | R29: 231 | S29: D50 [nm] | T29: 232 | U29: D50 [nm] | V29: 228
A30: 142.5 | B30: 3503042.9 | C30: 142.5 | D30: 4850164.6 | E30: 142.5 | F30: 3927890.5 | Q30: D90 [nm] | R30: 392 | S30: D90 [nm] | T30: 380 | U30: D90 [nm] | V30: 385
A31: 147.5 | B31: 4786127.8 | C31: 147.5 | D31: 4403922 | E31: 147.5 | F31: 6004503 | Q31: Valid tracks | R31: 9844 | S31: Valid tracks | T31: 11091 | U31: Valid tracks | V31: 10302
A32: 152.5 | B32: 4641227.7 | C32: 152.5 | D32: 5101391.2 | E32: 152.5 | F32: 4792777.5 | R32: 19000000 | T32: 20300000 | V32: 15000000
A33: 157.5 | B33: 5362409.9 | C33: 157.5 | D33: 5618757.4 | E33: 157.5 | F33: 5265538.2
A34: 162.5 | B34: 4567118.5 | C34: 162.5 | D34: 4811161.4 | E34: 162.5 | F34: 6185654.3
A35: 167.5 | B35: 5638936.8 | C35: 167.5 | D35: 5259698.4 | E35: 167.5 | F35: 5669814.9
A36: 172.5 | B36: 5296043.4 | C36: 172.5 | D36: 5691028.1 | E36: 172.5 | F36: 5031367
A37: 177.5 | B37: 5807065.2 | C37: 177.5 | D37: 5956020.5 | E37: 177.5 | F37: 5884103.6
A38: 182.5 | B38: 6250614.3 | C38: 182.5 | D38: 6200364.2 | E38: 182.5 | F38: 6180131.4
A39: 187.5 | B39: 5607965.8 | C39: 187.5 | D39: 6910452.2 | E39: 187.5 | F39: 6350236.8
A40: 192.5 | B40: 5456429 | C40: 192.5 | D40: 6593837.8 | E40: 192.5 | F40: 5261119.9
A41: 197.5 | B41: 5179902.1 | C41: 197.5 | D41: 6394233.1 | E41: 197.5 | F41: 5131883.9
A42: 202.5 | B42: 6376710.6 | C42: 202.5 | D42: 7509266.2 | E42: 202.5 | F42: 5976888.4
A43: 207.5 | B43: 5424351.9 | C43: 207.5 | D43: 5883749.9 | E43: 207.5 | F43: 5537265.1
A44: 212.5 | B44: 6260569.3 | C44: 212.5 | D44: 6222160.1 | E44: 212.5 | F44: 5581448.4
... A201: 997.5 | B201: 0 | C201: 997.5 | D201: 0 | E201: 997.5 | F201: 0

Sheet 0.5R2
