Workbook

Sheet Description
A1: NOTE
A2: This excel workbook provides Se-PS-NPs data analysis for DLS
A4: 1- Raw size data are included in "0.25 size, 0.7 size, 2.7 size"
A5: 2-Concentrations data are included in "0.25 conc, 0.7 conc, 2.3 conc" with plot which includes NTA and DLS data for Figure S8c
A6: "Summary" provides the plot for Figure S8b

Sheet Summary
E1: Size (d.nm) - 0.5E_S2_2xCen_20250514 [Steady state] | F1: 0.3R1 | G1: 0.3R2 | H1: 0.3R3 | I1: 1R1 | J1: 1R2 | K1: 1R3 | L1: 3R1 | M1: 3R2 | N1: 3R3 | P1: Size (d.nm) - 0.5E_S2_2xCen_20250514 [Steady state] | Q1: 0.3% w/w | R1: 0.7% w/w | S1: 2.3% w/w
E2: 0.3 | F2: 0 | G2: 0 | H2: 0 | I2: 0 | J2: 0 | K2: 0 | L2: 0 | M2: 0 | N2: 0 | P2: 0.3 | Q2: =AVERAGE(F2,G2,H2) -> 0 | R2: =AVERAGE(I2:K2) -> 0 | S2: =AVERAGE(L2:N2) -> 0
E3: 0.3489 | F3: 0 | G3: 0 | H3: 0 | I3: 0 | J3: 0 | K3: 0 | L3: 0 | M3: 0 | N3: 0 | P3: 0.3489 | Q3: =AVERAGE(F3,G3,H3) -> 0 | R3: =AVERAGE(I3:K3) -> 0 | S3: =AVERAGE(L3:N3) -> 0
E4: 0.4057 | F4: 0 | G4: 0 | H4: 0 | I4: 0 | J4: 0 | K4: 0 | L4: 0 | M4: 0 | N4: 0 | P4: 0.4057 | Q4: =AVERAGE(F4,G4,H4) -> 0 | R4: =AVERAGE(I4:K4) -> 0 | S4: =AVERAGE(L4:N4) -> 0
E5: 0.4718 | F5: 0 | G5: 0 | H5: 0 | I5: 0 | J5: 0 | K5: 0 | L5: 0 | M5: 0 | N5: 0 | P5: 0.4718 | Q5: =AVERAGE(F5,G5,H5) -> 0 | R5: =AVERAGE(I5:K5) -> 0 | S5: =AVERAGE(L5:N5) -> 0
E6: 0.5487 | F6: 0 | G6: 0 | H6: 0 | I6: 0 | J6: 0 | K6: 0 | L6: 0 | M6: 0 | N6: 0 | P6: 0.5487 | Q6: =AVERAGE(F6,G6,H6) -> 0 | R6: =AVERAGE(I6:K6) -> 0 | S6: =AVERAGE(L6:N6) -> 0
E7: 0.6381 | F7: 0 | G7: 0 | H7: 0 | I7: 0 | J7: 0 | K7: 0 | L7: 0 | M7: 0 | N7: 0 | P7: 0.6381 | Q7: =AVERAGE(F7,G7,H7) -> 0 | R7: =AVERAGE(I7:K7) -> 0 | S7: =AVERAGE(L7:N7) -> 0
E8: 0.742 | F8: 0 | G8: 0 | H8: 0 | I8: 0 | J8: 0 | K8: 0 | L8: 0 | M8: 0 | N8: 0 | P8: 0.742 | Q8: =AVERAGE(F8,G8,H8) -> 0 | R8: =AVERAGE(I8:K8) -> 0 | S8: =AVERAGE(L8:N8) -> 0
E9: 0.8629 | F9: 0 | G9: 0 | H9: 0 | I9: 0 | J9: 0 | K9: 0 | L9: 0 | M9: 0 | N9: 0 | P9: 0.8629 | Q9: =AVERAGE(F9,G9,H9) -> 0 | R9: =AVERAGE(I9:K9) -> 0 | S9: =AVERAGE(L9:N9) -> 0
E10: 1.003 | F10: 0 | G10: 0 | H10: 0 | I10: 0 | J10: 0 | K10: 0 | L10: 0 | M10: 0 | N10: 0 | P10: 1.003 | Q10: =AVERAGE(F10,G10,H10) -> 0 | R10: =AVERAGE(I10:K10) -> 0 | S10: =AVERAGE(L10:N10) -> 0
E11: 1.167 | F11: 0 | G11: 0 | H11: 0 | I11: 0 | J11: 0 | K11: 0 | L11: 0 | M11: 0 | N11: 0 | P11: 1.167 | Q11: =AVERAGE(F11,G11,H11) -> 0 | R11: =AVERAGE(I11:K11) -> 0 | S11: =AVERAGE(L11:N11) -> 0
E12: 1.357 | F12: 0 | G12: 0 | H12: 0 | I12: 0 | J12: 0 | K12: 0 | L12: 0 | M12: 0 | N12: 0 | P12: 1.357 | Q12: =AVERAGE(F12,G12,H12) -> 0 | R12: =AVERAGE(I12:K12) -> 0 | S12: =AVERAGE(L12:N12) -> 0
E13: 1.578 | F13: 0 | G13: 0 | H13: 0 | I13: 0 | J13: 0 | K13: 0 | L13: 0 | M13: 0 | N13: 0 | P13: 1.578 | Q13: =AVERAGE(F13,G13,H13) -> 0 | R13: =AVERAGE(I13:K13) -> 0 | S13: =AVERAGE(L13:N13) -> 0
... E71: 10000 | F71: 0 | G71: 0 | H71: 0 | I71: 0 | J71: 0 | K71: 0 | L71: 0 | M71: 0 | N71: 0 | P71: 10000 | Q71: =AVERAGE(F71,G71,H71) -> 0 | R71: =AVERAGE(I71:K71) -> 0 | S71: =AVERAGE(L71:N71) -> 0
D73: Size | E73: stdev | F73: Size | G73: stdev | H73: Size | I73: stdev
C74: Model | D74: R1 | F74: R2 | H74: R3
C75: 0.3 | D75: ='0.25 size'!B74 -> 251.4 | E75: ='0.25 size'!C74 -> 1.575 | F75: ='0.25 size'!B80 -> 295.2 | G75: ='0.25 size'!C80 -> 14.34 | H75: ='0.25 size'!B86 -> 344.8 | I75: ='0.25 size'!C86 -> 4.957
C76: 0.7 | D76: ='0.7 size'!J74 -> 301.8 | E76: ='0.7 size'!K74 -> 5.476 | F76: ='0.7 size'!J80 -> 249.7 | G76: ='0.7 size'!K80 -> 2.369 | H76: ='0.7 size'!J86 -> 280.2 | I76: ='0.7 size'!K86 -> 8.067
C77: 2.3 | D77: ='2.7 size'!F74 -> 230.6 | E77: ='2.7 size'!G74 -> 1.193 | F77: ='2.7 size'!F80 -> 283.6 | G77: ='2.7 size'!G80 -> 38.38 | H77: ='2.7 size'!F86 -> 416.8 | I77: ='2.7 size'!G86 -> 18.33
D80: NTA | H80: DLS | M80: DLS
D81: Size (nm) | E81: stdev | F81: Con | G81: Con stdev | H81: Z-average (nm) | I81: stdev | J81: Con | K81: Con stdev | M81: Size 0.5 | Q81: Reorganized 0.5 | R81: Reorg 0.7 | S81: reorg 2.3
C82: 0R1 | D82: 267.89807 | E82: 122.66465 | F82: 1.5141977e+08 | G82: 15649634 | M82: ='0.25 size'!H74 -> 251.8 | N82: ='0.25 size'!I74 -> 249.7 | O82: ='0.25 size'!J74 -> 252.8 | P82: =AVERAGE(M82:O84) -> 292.16667 | Q82: =M82 -> 251.8 | R82: =M87 -> 339.1 | S82: =M92 -> 231.5
C83: 0R2 | D83: 255.54226 | E83: 119.85109 | F83: 1.5891144e+08 | G83: 20508639 | M83: ='0.25 size'!H75 -> 273.3 | N83: ='0.25 size'!I75 -> 291.4 | O83: ='0.25 size'!J75 -> 276.1 | P83: =STDEV(M82:O84) -> 41.768529 | Q83: =N82 -> 249.7 | R83: =N87 -> 307.7 | S83: =N92 -> 231.1
C84: 0R3 | D84: 288.58663 | E84: 126.0351 | F84: 1.5968548e+08 | G84: 19980486 | M84: ='0.25 size'!H76 -> 347.8 | N84: ='0.25 size'!I76 -> 339.1 | O84: ='0.25 size'!J76 -> 347.5 | Q84: =O82 -> 252.8 | R84: =O87 -> 313.5 | S84: =O92 -> 229.3
C85: 0.5R1 | D85: 250.28581 | E85: 119.50876 | F85: 2.611851e+08 | G85: 18142373 | H85: =D75 -> 251.4 | I85: =E75 -> 1.575 | J85: ='0.25 Con'!B3 -> 259000000 | K85: ='0.25 Con'!C3 -> 39660000 | Q85: =M83 -> 273.3 | R85: =M88 -> 251.4 | S85: =M93 -> 245.4
C86: 0.5R2 | D86: 231.61182 | E86: 126.50513 | F86: 98150671 | G86: 15213337 | H86: =F75 -> 295.2 | I86: =E76 -> 5.476 | J86: ='0.25 Con'!B10 -> 116500000 | K86: ='0.25 Con'!C10 -> 21500000 | M86: Size 1 | Q86: =N83 -> 291.4 | R86: =N88 -> 247 | S86: =N93 -> 275.6
C87: 0.5R3 | D87: 265.98713 | E87: 130.07044 | F87: 74585168 | G87: 7926388.9 | H87: =H75 -> 344.8 | I87: =E77 -> 1.193 | J87: ='0.25 Con'!B17 -> 64790000 | K87: ='0.25 Con'!C17 -> 16930000 | M87: ='0.7 size'!P74 -> 339.1 | N87: ='0.7 size'!Q74 -> 307.7 | O87: ='0.7 size'!R74 -> 313.5 | P87: =AVERAGE(M87:O89) -> 291.56667 | Q87: =O83 -> 276.1 | R87: =O88 -> 250.8 | S87: =O93 -> 251.8
C88: 1R1 | D88: 300.2052 | E88: 120.74917 | F88: 1.2644349e+08 | G88: 12966001 | H88: =D76 -> 301.8 | I88: =G75 -> 14.34 | J88: ='0.7 Con'!B3 -> 141300000 | K88: ='0.7 Con'!C3 -> 20520000 | M88: ='0.7 size'!P75 -> 251.4 | N88: ='0.7 size'!Q75 -> 247 | O88: ='0.7 size'!R75 -> 250.8 | P88: =STDEV(M87:O89) -> 34.076238 | Q88: =M84 -> 347.8 | R88: =M89 -> 304.3 | S88: =M94 -> 432.5
C89: 1R2 | D89: 238.82203 | E89: 103.28479 | F89: 2.052015e+08 | G89: 19736910 | H89: =F76 -> 249.7 | I89: =G76 -> 2.369 | J89: ='0.7 Con'!B10 -> 197900000 | K89: ='0.7 Con'!C10 -> 7906000 | M89: ='0.7 size'!P76 -> 304.3 | N89: ='0.7 size'!Q76 -> 320.9 | O89: ='0.7 size'!R76 -> 289.4 | Q89: =N84 -> 339.1 | R89: =N89 -> 320.9 | S89: =N94 -> 396.7
C90: 1R3 | D90: 219.48929 | E90: 124.14735 | F90: 62794228 | G90: 7608028 | H90: =H76 -> 280.2 | I90: =G77 -> 38.38 | J90: ='0.7 Con'!B16 -> 81950000 | K90: ='0.7 Con'!C16 -> 10010000 | Q90: =O84 -> 347.5 | R90: =O89 -> 289.4 | S90: =O94 -> 421.3
C91: 3R1 | D91: 222.68971 | E91: 97.664603 | F91: 1.6237011e+08 | G91: 14460810 | H91: =D77 -> 230.6 | I91: =I75 -> 4.957 | J91: ='2.7 conc'!B3 -> 153400000 | K91: ='2.7 conc'!C3 -> 18230000 | M91: Size 2.3
C92: 3R2 | D92: 214.12705 | E92: 104.80666 | F92: 1.2372645e+08 | G92: 12482549 | H92: =F77 -> 283.6 | I92: =I76 -> 8.067 | J92: ='2.7 conc'!B10 -> 114900000 | K92: ='2.7 conc'!C10 -> 20400000 | M92: ='2.7 size'!L74 -> 231.5 | N92: ='2.7 size'!M74 -> 231.1 | O92: ='2.7 size'!N74 -> 229.3 | P92: =AVERAGE(M92:O94) -> 301.68889
C93: 3R3 | D93: 264.53478 | E93: 144.12815 | F93: 73525707 | G93: 13725555 | H93: =H77 -> 416.8 | I93: =I77 -> 18.33 | J93: ='2.7 conc'!B17 -> 69420000 | K93: ='2.7 conc'!C17 -> 7989000 | M93: ='2.7 size'!L75 -> 245.4 | N93: ='2.7 size'!M75 -> 275.6 | O93: ='2.7 size'!N75 -> 251.8 | P93: =STDEV(M92:O94) -> 87.986412
M94: ='2.7 size'!L76 -> 432.5 | N94: ='2.7 size'!M76 -> 396.7 | O94: ='2.7 size'!N76 -> 421.3
D96: NTA
E97: t-Test: Two-Sample Assuming Unequal Variances
F99: Variable 1 | G99: Variable 2 | I99: t-Test: Paired Two Sample for Means
E100: Mean | F100: 1.3199805e+08 | G100: 133240000
E101: Variance | F101: 4.4649802e+15 | G101: 4.0591906e+15 | J101: Variable 1 | K101: Variable 2
E102: Observations | F102: 9 | G102: 9 | I102: Mean | J102: 1.3199805e+08 | K102: 133240000
...

Sheet 0
A1: Size (d.nm) - 0B_S1_2xCen_20250516_isolated [Steady state] | B1: Intensity (Percent) - 0B_S1_2xCen_20250516_isolated [Steady state] | C1: Size (d.nm) - 0B_S1_2xCen_20250516_isolated [Steady state] | D1: Intensity (Percent) - 0B_S1_2xCen_20250516_isolated [Steady state] | E1: Size (d.nm) - 0B_S1_2xCen_20250516_isolated [Steady state] | F1: Intensity (Percent) - 0B_S1_2xCen_20250516_isolated [Steady state] | G1: Size (d.nm) - 0C_S1_2xCen_20250519 [Steady state] | H1: Intensity (Percent) - 0C_S1_2xCen_20250519 [Steady state] | I1: Size (d.nm) - 0C_S1_2xCen_20250519 [Steady state] | J1: Intensity (Percent) - 0C_S1_2xCen_20250519 [Steady state] | K1: Size (d.nm) - 0C_S1_2xCen_20250519 [Steady state] | L1: Intensity (Percent) - 0C_S1_2xCen_20250519 [Steady state] | M1: Size (d.nm) - 0D_S1_2xCen_20250519 [Steady state] | N1: Intensity (Percent) - 0D_S1_2xCen_20250519 [Steady state] | O1: Size (d.nm) - 0D_S1_2xCen_20250519 [Steady state] | P1: Intensity (Percent) - 0D_S1_2xCen_20250519 [Steady state] | Q1: Size (d.nm) - 0D_S1_2xCen_20250519 [Steady state] | R1: Intensity (Percent) - 0D_S1_2xCen_20250519 [Steady state] | T1: {=A1:A71} -> Size (d.nm) - 0B_S1_2xCen_20250516_isolated [Steady state] | U1: 1R1 | V1: 1R2 | W1: 1R3
A2: 0.3 | B2: 0 | C2: 0.3 | D2: 0 | E2: 0.3 | F2: 0 | G2: 0.3 | H2: 0 | I2: 0.3 | J2: 0 | K2: 0.3 | L2: 0 | M2: 0.3 | N2: 0 | O2: 0.3 | P2: 0 | Q2: 0.3 | R2: 0 | T2: 0.3 | U2: =AVERAGE(B2,D2,F2) -> 0 | V2: =AVERAGE(H2,J2,L2) -> 0 | W2: =AVERAGE(N2,P2,R2) -> 0
A3: 0.3489 | B3: 0 | C3: 0.3489 | D3: 0 | E3: 0.3489 | F3: 0 | G3: 0.3489 | H3: 0 | I3: 0.3489 | J3: 0 | K3: 0.3489 | L3: 0 | M3: 0.3489 | N3: 0 | O3: 0.3489 | P3: 0 | Q3: 0.3489 | R3: 0 | T3: 0.3489 | U3: =AVERAGE(B3,D3,F3) -> 0 | V3: =AVERAGE(H3,J3,L3) -> 0 | W3: =AVERAGE(N3,P3,R3) -> 0
A4: 0.4057 | B4: 0 | C4: 0.4057 | D4: 0 | E4: 0.4057 | F4: 0 | G4: 0.4057 | H4: 0 | I4: 0.4057 | J4: 0 | K4: 0.4057 | L4: 0 | M4: 0.4057 | N4: 0 | O4: 0.4057 | P4: 0 | Q4: 0.4057 | R4: 0 | T4: 0.4057 | U4: =AVERAGE(B4,D4,F4) -> 0 | V4: =AVERAGE(H4,J4,L4) -> 0 | W4: =AVERAGE(N4,P4,R4) -> 0
A5: 0.4718 | B5: 0 | C5: 0.4718 | D5: 0 | E5: 0.4718 | F5: 0 | G5: 0.4718 | H5: 0 | I5: 0.4718 | J5: 0 | K5: 0.4718 | L5: 0 | M5: 0.4718 | N5: 0 | O5: 0.4718 | P5: 0 | Q5: 0.4718 | R5: 0 | T5: 0.4718 | U5: =AVERAGE(B5,D5,F5) -> 0 | V5: =AVERAGE(H5,J5,L5) -> 0 | W5: =AVERAGE(N5,P5,R5) -> 0
A6: 0.5487 | B6: 0 | C6: 0.5487 | D6: 0 | E6: 0.5487 | F6: 0 | G6: 0.5487 | H6: 0 | I6: 0.5487 | J6: 0 | K6: 0.5487 | L6: 0 | M6: 0.5487 | N6: 0 | O6: 0.5487 | P6: 0 | Q6: 0.5487 | R6: 0 | T6: 0.5487 | U6: =AVERAGE(B6,D6,F6) -> 0 | V6: =AVERAGE(H6,J6,L6) -> 0 | W6: =AVERAGE(N6,P6,R6) -> 0
A7: 0.6381 | B7: 0 | C7: 0.6381 | D7: 0 | E7: 0.6381 | F7: 0 | G7: 0.6381 | H7: 0 | I7: 0.6381 | J7: 0 | K7: 0.6381 | L7: 0 | M7: 0.6381 | N7: 0 | O7: 0.6381 | P7: 0 | Q7: 0.6381 | R7: 0 | T7: 0.6381 | U7: =AVERAGE(B7,D7,F7) -> 0 | V7: =AVERAGE(H7,J7,L7) -> 0 | W7: =AVERAGE(N7,P7,R7) -> 0
A8: 0.742 | B8: 0 | C8: 0.742 | D8: 0 | E8: 0.742 | F8: 0 | G8: 0.742 | H8: 0 | I8: 0.742 | J8: 0 | K8: 0.742 | L8: 0 | M8: 0.742 | N8: 0 | O8: 0.742 | P8: 0 | Q8: 0.742 | R8: 0 | T8: 0.742 | U8: =AVERAGE(B8,D8,F8) -> 0 | V8: =AVERAGE(H8,J8,L8) -> 0 | W8: =AVERAGE(N8,P8,R8) -> 0
A9: 0.8629 | B9: 0 | C9: 0.8629 | D9: 0 | E9: 0.8629 | F9: 0 | G9: 0.8629 | H9: 0 | I9: 0.8629 | J9: 0 | K9: 0.8629 | L9: 0 | M9: 0.8629 | N9: 0 | O9: 0.8629 | P9: 0 | Q9: 0.8629 | R9: 0 | T9: 0.8629 | U9: =AVERAGE(B9,D9,F9) -> 0 | V9: =AVERAGE(H9,J9,L9) -> 0 | W9: =AVERAGE(N9,P9,R9) -> 0
A10: 1.003 | B10: 0 | C10: 1.003 | D10: 0 | E10: 1.003 | F10: 0 | G10: 1.003 | H10: 0 | I10: 1.003 | J10: 0 | K10: 1.003 | L10: 0 | M10: 1.003 | N10: 0 | O10: 1.003 | P10: 0 | Q10: 1.003 | R10: 0 | T10: 1.003 | U10: =AVERAGE(B10,D10,F10) -> 0 | V10: =AVERAGE(H10,J10,L10) -> 0 | W10: =AVERAGE(N10,P10,R10) -> 0
A11: 1.167 | B11: 0 | C11: 1.167 | D11: 0 | E11: 1.167 | F11: 0 | G11: 1.167 | H11: 0 | I11: 1.167 | J11: 0 | K11: 1.167 | L11: 0 | M11: 1.167 | N11: 0 | O11: 1.167 | P11: 0 | Q11: 1.167 | R11: 0 | T11: 1.167 | U11: =AVERAGE(B11,D11,F11) -> 0 | V11: =AVERAGE(H11,J11,L11) -> 0 | W11: =AVERAGE(N11,P11,R11) -> 0
A12: 1.357 | B12: 0 | C12: 1.357 | D12: 0 | E12: 1.357 | F12: 0 | G12: 1.357 | H12: 0 | I12: 1.357 | J12: 0 | K12: 1.357 | L12: 0 | M12: 1.357 | N12: 0 | O12: 1.357 | P12: 0 | Q12: 1.357 | R12: 0 | T12: 1.357 | U12: =AVERAGE(B12,D12,F12) -> 0 | V12: =AVERAGE(H12,J12,L12) -> 0 | W12: =AVERAGE(N12,P12,R12) -> 0
A13: 1.578 | B13: 0 | C13: 1.578 | D13: 0 | E13: 1.578 | F13: 0 | G13: 1.578 | H13: 0 | I13: 1.578 | J13: 0 | K13: 1.578 | L13: 0 | M13: 1.578 | N13: 0 | O13: 1.578 | P13: 0 | Q13: 1.578 | R13: 0 | T13: 1.578 | U13: =AVERAGE(B13,D13,F13) -> 0 | V13: =AVERAGE(H13,J13,L13) -> 0 | W13: =AVERAGE(N13,P13,R13) -> 0
... A71: 10000 | B71: 0 | C71: 10000 | D71: 0 | E71: 10000 | F71: 0 | G71: 10000 | H71: 0 | I71: 10000 | J71: 0 | K71: 10000 | L71: 0 | M71: 10000 | N71: 0 | O71: 10000 | P71: 0 | Q71: 10000 | R71: 0 | T71: 10000 | U71: =AVERAGE(B71,D71,F71) -> 0 | V71: =AVERAGE(H71,J71,L71) -> 0 | W71: =AVERAGE(N71,P71,R71) -> 0

Sheet 0.25 Con
A1: 0.3R1 | H1: Overlay | M1: NTA Conc
A2: Name | B2: Mean | C2: Standard Deviation | D2: RSD | E2: Minimum | F2: Maximum | H2: R1_DLS | I2: 213200000 | J2: 282900000 | K2: 281000000
A3: Total Number Concentration (particles/ml) | B3: 259000000 | C3: 39660000 | D3: 15.31 | E3: 213200000 | F3: 282900000 | H3: R1_NTA | I3: ='[1]0.5R1'!$R$27 -> 250000000 | J3: ='[1]0.5R1'!$T$27 -> 275000000 | K3: ='[1]0.5R1'!$V$27 -> 257000000
A4: Particle Concentration Peak One (particles/ml) | B4: 229200000 | C4: 47560000 | D4: 20.75 | E4: 192200000 | F4: 282900000
A5: Particle Concentration Peak Two (particles/ml) | B5: 44730000 | C5: 33560000 | D5: 75.02 | E5: 21000000 | F5: 68460000 | H5: R2_DLS | I5: 140800000 | J5: 99760000 | K5: 109000000
A6: Size Concentration Peak One | B6: 204.7 | C6: 16.12 | D6: 7.874 | E6: 186.1 | F6: 214 | H6: R2_NTA | I6: ='[1]0.5R2'!$R$27 -> 100000000 | J6: ='[1]0.5R2'!$T$27 -> 95200000 | K6: ='[1]0.5R2'!$V$27 -> 99200000
A7: Size Concentration Peak Two | B7: 387.9 | C7: 19.17 | D7: 4.94 | E7: 374.4 | F7: 401.5
H8: R3_DLS | I8: 84190000 | J8: 57240000 | K8: 52950000
A9: 0.3R2 | H9: R3_NTA | I9: ='[1]0.5R3'!$R$27 -> 65500000 | J9: ='[1]0.5R3'!$T$27 -> 77100000 | K9: ='[1]0.5R3'!$V$27 -> 79700000
A10: Total Number Concentration (particles/ml) | B10: 116500000 | C10: 21500000 | D10: 18.46 | E10: 99760000 | F10: 140800000
A11: Particle Concentration Peak One (particles/ml) | B11: 101700000 | C11: 19880000 | D11: 19.54 | E11: 82520000 | F11: 1222000 | I11: 0 | J11: 0 | K11: 0
A12: Particle Concentration Peak Two (particles/ml) | B12: 14760000 | C12: 5457000 | D12: 36.96 | E12: 8506000 | F12: 18540000 | H12: stdev | I12: ='[1]0.5R1'!$R$32 -> 19000000 | J12: ='[1]0.5R1'!$T$32 -> 20300000 | K12: ='[1]0.5R1'!$V$32 -> 15000000
A13: Size Concentration Peak One | B13: 162.1 | C13: 11.32 | D13: 6.985 | E13: 150.9 | F13: 173.5 | I13: 0 | J13: 0 | K13: 0
A14: Size Concentration Peak Two | B14: 413.8 | C14: 58.15 | D14: 14.05 | E14: 349.1 | F14: 461.7 | I14: 0 | J14: 0 | K14: 0
I15: ='[1]0.5R2'!$R$32 -> 11700000 | J15: ='[1]0.5R2'!$T$32 -> 19200000 | K15: ='[1]0.5R2'!$V$32 -> 14800000
A16: 0.3R3 | I16: 0 | J16: 0 | K16: 0
A17: Total Number Concentration (particles/ml) | B17: 64790000 | C17: 16930000 | I17: 0 | J17: 0 | K17: 0
A18: Particle Concentration Peak One (particles/ml) | I18: ='[1]0.5R3'!$R$32 -> 15300000 | J18: ='[1]0.5R3'!$T$32 -> 6420000 | K18: ='[1]0.5R3'!$V$32 -> 3270000
A19: Particle Concentration Peak Two (particles/ml)
A20: Size Concentration Peak One
A21: Size Concentration Peak Two

Sheet 0.7 Con
A1: 0.7R1 | H1: Overlay
A2: Name | B2: Mean | C2: Standard Deviation | D2: RSD | E2: Minimum | F2: Maximum | H2: R1_DLS | I2: =D25 -> 164100000 | J2: =D26 -> 124300000 | K2: =D27 -> 135500000
A3: Total Number Concentration (particles/ml) | B3: 141300000 | C3: 20520000 | D3: 14.52 | E3: 124300000 | F3: 164000000 | H3: R1_NTA | I3: =E25 -> 113000000 | J3: =E26 -> 136000000 | K3: =E27 -> 129000000
A4: Particle Concentration Peak One (particles/ml) | B4: 88470000 | C4: 9443000 | D4: 10.67 | E4: 77560000 | F4: 94000000
A5: Particle Concentration Peak Two (particles/ml) | B5: 52850000 | C5: 15160000 | D5: 28.69 | E5: 41690000 | F5: 70110000 | H5: R2_DLS | I5: =D28 -> 197600000 | J5: =D29 -> 190100000 | K5: =D30 -> 205900000
A6: Size Concentration Peak One | B6: 195.4 | C6: 16.12 | D6: 8.25 | E6: 186.1 | F6: 214 | H6: R2_NTA | I6: =E28 -> 180000000 | J6: =E29 -> 209000000 | K6: =E30 -> 221000000
A7: Size Concentration Peak Two | B7: 384 | C7: 30.24 | D7: 7.874 | E7: 349.1 | F7: 401.5
H8: R3_DLS | I8: =D31 -> 49460000 | J8: =D32 -> 125500000 | K8: =D33 -> 94710000
A9: 0.7R2 | H9: R3_NTA | I9: =E31 -> 72400000 | J9: =E32 -> 59700000 | K9: =E33 -> 56900000
A10: Total Number Concentration (particles/ml) | B10: 197900000 | C10: 7906000
A11: Particle Concentration Peak One (particles/ml) | H11: stdev | I11: 0 | J11: 0 | K11: 0
A12: Particle Concentration Peak Two (particles/ml) | I12: ='[1]1R1'!$R$32 -> 16600000 | J12: ='[1]1R1'!$T$32 -> 11100000 | K12: ='[1]1R1'!$V$32 -> 11500000
A13: Size Concentration Peak One | I13: 0 | J13: 0 | K13: 0
A14: Size Concentration Peak Two | I14: 0 | J14: 0 | K14: 0
I15: ='[1]1R2'!$R$32 -> 10300000 | J15: ='[1]1R2'!$T$32 -> 21000000 | K15: ='[1]1R2'!$V$32 -> 25800000
A16: 0.7R3 | B16: 81950000 | C16: 10010000 | I16: 0 | J16: 0 | K16: 0
A17: Total Number Concentration (particles/ml) | I17: 0 | J17: 0 | K17: 0
A18: Particle Concentration Peak One (particles/ml) | I18: ='[1]1R3'!$R$32 -> 10000000 | J18: ='[1]1R3'!$T$32 -> 8690000 | K18: ='[1]1R3'!$V$32 -> 4140000
A19: Particle Concentration Peak Two (particles/ml)
A20: Size Concentration Peak One
A21: Size Concentration Peak Two
C24: Overlay | D24: DLS | E24: NTA
C25: 0.7R1 | D25: 164100000 | E25: ='[1]1R1'!$R$27 -> 113000000
C26: 0.7R1 | D26: 124300000 | E26: ='[1]1R1'!$T$27 -> 136000000
C27: 0.7R1 | D27: 135500000 | E27: ='[1]1R1'!$V$27 -> 129000000
C28: 0.7R2 | D28: 197600000 | E28: ='[1]1R2'!$R$27 -> 180000000
C29: 0.7R2 | D29: 190100000 | E29: ='[1]1R2'!$T$27 -> 209000000
C30: 0.7R2 | D30: 205900000 | E30: ='[1]1R2'!$V$27 -> 221000000
C31: 0.7R3 | D31: 49460000 | E31: ='[1]1R3'!$R$27 -> 72400000
C32: 0.7R3 | D32: 125500000 | E32: ='[1]1R3'!$T$27 -> 59700000
C33: 0.7R3 | D33: 94710000 | E33: ='[1]1R3'!$V$27 -> 56900000
C34: 0.7R1_NTA
C35: 0.7R1_NTA
C36: 0.7R1_NTA
C37: 0.7R2_NTA
C38: 0.7R2_NTA
C39: 0.7R2_NTA
C40: 0.7R3_NTA
C41: 0.7R3_NTA
C42: 0.7R3_NTA

Sheet 2.7 conc
A1: 2.3R1
A2: Name | B2: Mean | C2: Standard Deviation | D2: RSD | E2: Minimum | F2: Maximum | H2: R1_DLS | I2: =E28 -> 138900000 | J2: =E29 -> 147300000 | K2: =E30 -> 173900000
A3: Total Number Concentration (particles/ml) | B3: 153400000 | C3: 18230000 | H3: R1_NTA | I3: =F28 -> 163000000 | J3: =F29 -> 158000000 | K3: =F30 -> 166000000
A4: Particle Concentration Peak One (particles/ml)
A5: Particle Concentration Peak Two (particles/ml) | H5: R2_DLS | I5: =E31 -> 123800000 | J5: =E32 -> 91560000 | K5: =E33 -> 129400000
A6: Size Concentration Peak One | H6: R2_NTA | I6: =F31 -> 127000000 | J6: =F32 -> 120000000 | K6: =F33 -> 124000000
A7: Size Concentration Peak Two
H8: R3_DLS | I8: =E34 -> 77740000 | J8: =E35 -> 68700000 | K8: =E36 -> 61810000
A9: 2.3R2 | H9: R3_NTA | I9: =F34 -> 71200000 | J9: =F35 -> 77800000 | K9: =F36 -> 70900000
A10: Total Number Concentration (particles/ml) | B10: 114900000 | C10: 20400000
A11: Particle Concentration Peak One (particles/ml) | H11: stdev | I11: 0 | J11: 0 | K11: 0
A12: Particle Concentration Peak Two (particles/ml) | I12: ='[1]3R1'!$R$32 -> 8270000 | J12: ='[1]3R1'!$T$32 -> 14400000 | K12: ='[1]3R1'!$V$32 -> 20800000
A13: Size Concentration Peak One | I13: 0 | J13: 0 | K13: 0
A14: Size Concentration Peak Two | I14: 0 | J14: 0 | K14: 0
I15: ='[1]3R2'!$R$32 -> 11700000 | J15: ='[1]3R2'!$T$32 -> 16100000 | K15: ='[1]3R2'!$V$32 -> 9860000
A16: 2.3R3 | I16: 0 | J16: 0 | K16: 0
A17: Total Number Concentration (particles/ml) | B17: 69420000 | C17: 7989000 | D17: 11.51 | E17: 61810000 | F17: 77740000 | I17: 0 | J17: 0 | K17: 0
A18: Particle Concentration Peak One (particles/ml) | B18: 64350000 | C18: 12630000 | D18: 19.63 | E18: 52640000 | F18: 77740000 | I18: ='[1]3R3'!$R$32 -> 12100000 | J18: ='[1]3R3'!$T$32 -> 6370000 | K18: ='[1]3R3'!$V$32 -> 24500000
A19: Particle Concentration Peak Two (particles/ml) | B19: 7478000000 | C19: 2046000 | D19: 27.36 | E19: 6031000 | F19: 8925000
A20: Size Concentration Peak One | B20: 192.2 | C20: 32.32 | D20: 16.82 | E20: 173.5 | F20: 229.5
A21: Size Concentration Peak Two | B21: 430.6 | C21: 0 | D21: 0 | E21: 430.6 | F21: 430.6
D27: overlay | E27: DLS | F27: NTA | I27: t-Test: Paired Two Sample for Means | M27: t-Test: Paired Two Sample for Means
D28: 2.3R1 | E28: 138900000 | F28: ='[1]3R1'!$R$27 -> 163000000
E29: 147300000 | F29: ='[1]3R1'!$T$27 -> 158000000 | J29: Variable 1 | K29: Variable 2 | N29: Variable 1 | O29: Variable 2
E30: 173900000 | F30: ='[1]3R1'!$V$27 -> 166000000 | I30: Mean | J30: 114920000 | K30: 1.2366667e+08 | M30: Mean | N30: 69416667 | O30: 73300000
D31: 2.3R2 | E31: 123800000 | F31: ='[1]3R2'!$R$27 -> 127000000 | I31: Variance | J31: 417107200000000 | K31: 1.2333333e+13 | M31: Variance | N31: 6.3826433e+13 | O31: 15210000000000
E32: 91560000 | F32: ='[1]3R2'!$T$27 -> 120000000 | I32: Observations | J32: 3 | K32: 3 | M32: Observations | N32: 3 | O32: 3
E33: 129400000 | F33: ='[1]3R2'!$V$27 -> 124000000 | I33: Pearson Correlation | J33: 0.83709858 | M33: Pearson Correlation | N33: -0.039284074
D34: 2.3R3 | E34: 77740000 | F34: ='[1]3R3'!$R$27 -> 71200000 | I34: Hypothesized Mean Difference | J34: 0 | M34: Hypothesized Mean Difference | N34: 0
E35: 68700000 | F35: ='[1]3R3'!$T$27 -> 77800000 | I35: df | J35: 2 | M35: df | N35: 2
E36: 61810000 | F36: ='[1]3R3'!$V$27 -> 70900000 | I36: t Stat | J36: -0.86133233 | M36: t Stat | N36: -0.74512301
I37: P(T<=t) one-tail | J37: 0.2399149 | M37: P(T<=t) one-tail | N37: 0.26693083
I38: t Critical one-tail | J38: 2.9199856 | M38: t Critical one-tail | N38: 2.9199856
I39: P(T<=t) two-tail | J39: 0.4798298 | M39: P(T<=t) two-tail | N39: 0.53386167
I40: t Critical two-tail | J40: 4.3026527 | M40: t Critical two-tail | N40: 4.3026527
I42: t-Test: Paired Two Sample for Means
J44: Variable 1 | K44: Variable 2
I45: Mean | J45: 1.5336667e+08 | K45: 1.6233333e+08
I46: Variance | J46: 3.3385333e+14 | K46: 1.6333333e+13
I47: Observations | J47: 3 | K47: 3
...

Sheet 0.25 size
A1: Size (d.nm) - 0.5E_S2_2xCen_20250514 [Steady state] | B1: Intensity (Percent) - 0.5E_S2_2xCen_20250514 [Steady state] | C1: Size (d.nm) - 0.5E_S2_2xCen_20250514 [Steady state] | D1: Intensity (Percent) - 0.5E_S2_2xCen_20250514 [Steady state] | E1: Size (d.nm) - 0.5E_S2_2xCen_20250514 [Steady state] | F1: Intensity (Percent) - 0.5E_S2_2xCen_20250514 [Steady state] | G1: Size (d.nm) - 0.5F_S2_2xCen_20250514 [Steady state] | H1: Intensity (Percent) - 0.5F_S2_2xCen_20250514 [Steady state] | I1: Size (d.nm) - 0.5F_S2_2xCen_20250514 [Steady state] | J1: Intensity (Percent) - 0.5F_S2_2xCen_20250514 [Steady state] | K1: Size (d.nm) - 0.5F_S2_2xCen_20250514 [Steady state] | L1: Intensity (Percent) - 0.5F_S2_2xCen_20250514 [Steady state] | M1: Size (d.nm) - 0.5E(2)_S1_2xCen_20250519 [Steady state] | N1: Intensity (Percent) - 0.5E(2)_S1_2xCen_20250519 [Steady state] | O1: Size (d.nm) - 0.5E(2)_S1_2xCen_20250519 [Steady state] | P1: Intensity (Percent) - 0.5E(2)_S1_2xCen_20250519 [Steady state] | Q1: Size (d.nm) - 0.5E(2)_S1_2xCen_20250519 [Steady state] | R1: Intensity (Percent) - 0.5E(2)_S1_2xCen_20250519 [Steady state] | T1: {=A1:A71} -> Size (d.nm) - 0.5E_S2_2xCen_20250514 [Steady state] | U1: R1 | V1: R2 | W1: R3
A2: 0.3 | B2: 0 | C2: 0.3 | D2: 0 | E2: 0.3 | F2: 0 | G2: 0.3 | H2: 0 | I2: 0.3 | J2: 0 | K2: 0.3 | L2: 0 | M2: 0.3 | N2: 0 | O2: 0.3 | P2: 0 | Q2: 0.3 | R2: 0 | T2: 0.3 | U2: =AVERAGE(B2,D2,F2) -> 0 | V2: =AVERAGE(H2,J2,L2) -> 0 | W2: =AVERAGE(N2,P2,R2) -> 0
A3: 0.3489 | B3: 0 | C3: 0.3489 | D3: 0 | E3: 0.3489 | F3: 0 | G3: 0.3489 | H3: 0 | I3: 0.3489 | J3: 0 | K3: 0.3489 | L3: 0 | M3: 0.3489 | N3: 0 | O3: 0.3489 | P3: 0 | Q3: 0.3489 | R3: 0 | T3: 0.3489 | U3: =AVERAGE(B3,D3,F3) -> 0 | V3: =AVERAGE(H3,J3,L3) -> 0 | W3: =AVERAGE(N3,P3,R3) -> 0
A4: 0.4057 | B4: 0 | C4: 0.4057 | D4: 0 | E4: 0.4057 | F4: 0 | G4: 0.4057 | H4: 0 | I4: 0.4057 | J4: 0 | K4: 0.4057 | L4: 0 | M4: 0.4057 | N4: 0 | O4: 0.4057 | P4: 0 | Q4: 0.4057 | R4: 0 | T4: 0.4057 | U4: =AVERAGE(B4,D4,F4) -> 0 | V4: =AVERAGE(H4,J4,L4) -> 0 | W4: =AVERAGE(N4,P4,R4) -> 0
A5: 0.4718 | B5: 0 | C5: 0.4718 | D5: 0 | E5: 0.4718 | F5: 0 | G5: 0.4718 | H5: 0 | I5: 0.4718 | J5: 0 | K5: 0.4718 | L5: 0 | M5: 0.4718 | N5: 0 | O5: 0.4718 | P5: 0 | Q5: 0.4718 | R5: 0 | T5: 0.4718 | U5: =AVERAGE(B5,D5,F5) -> 0 | V5: =AVERAGE(H5,J5,L5) -> 0 | W5: =AVERAGE(N5,P5,R5) -> 0
A6: 0.5487 | B6: 0 | C6: 0.5487 | D6: 0 | E6: 0.5487 | F6: 0 | G6: 0.5487 | H6: 0 | I6: 0.5487 | J6: 0 | K6: 0.5487 | L6: 0 | M6: 0.5487 | N6: 0 | O6: 0.5487 | P6: 0 | Q6: 0.5487 | R6: 0 | T6: 0.5487 | U6: =AVERAGE(B6,D6,F6) -> 0 | V6: =AVERAGE(H6,J6,L6) -> 0 | W6: =AVERAGE(N6,P6,R6) -> 0
A7: 0.6381 | B7: 0 | C7: 0.6381 | D7: 0 | E7: 0.6381 | F7: 0 | G7: 0.6381 | H7: 0 | I7: 0.6381 | J7: 0 | K7: 0.6381 | L7: 0 | M7: 0.6381 | N7: 0 | O7: 0.6381 | P7: 0 | Q7: 0.6381 | R7: 0 | T7: 0.6381 | U7: =AVERAGE(B7,D7,F7) -> 0 | V7: =AVERAGE(H7,J7,L7) -> 0 | W7: =AVERAGE(N7,P7,R7) -> 0
A8: 0.742 | B8: 0 | C8: 0.742 | D8: 0 | E8: 0.742 | F8: 0 | G8: 0.742 | H8: 0 | I8: 0.742 | J8: 0 | K8: 0.742 | L8: 0 | M8: 0.742 | N8: 0 | O8: 0.742 | P8: 0 | Q8: 0.742 | R8: 0 | T8: 0.742 | U8: =AVERAGE(B8,D8,F8) -> 0 | V8: =AVERAGE(H8,J8,L8) -> 0 | W8: =AVERAGE(N8,P8,R8) -> 0
A9: 0.8629 | B9: 0 | C9: 0.8629 | D9: 0 | E9: 0.8629 | F9: 0 | G9: 0.8629 | H9: 0 | I9: 0.8629 | J9: 0 | K9: 0.8629 | L9: 0 | M9: 0.8629 | N9: 0 | O9: 0.8629 | P9: 0 | Q9: 0.8629 | R9: 0 | T9: 0.8629 | U9: =AVERAGE(B9,D9,F9) -> 0 | V9: =AVERAGE(H9,J9,L9) -> 0 | W9: =AVERAGE(N9,P9,R9) -> 0
A10: 1.003 | B10: 0 | C10: 1.003 | D10: 0 | E10: 1.003 | F10: 0 | G10: 1.003 | H10: 0 | I10: 1.003 | J10: 0 | K10: 1.003 | L10: 0 | M10: 1.003 | N10: 0 | O10: 1.003 | P10: 0 | Q10: 1.003 | R10: 0 | T10: 1.003 | U10: =AVERAGE(B10,D10,F10) -> 0 | V10: =AVERAGE(H10,J10,L10) -> 0 | W10: =AVERAGE(N10,P10,R10) -> 0
A11: 1.167 | B11: 0 | C11: 1.167 | D11: 0 | E11: 1.167 | F11: 0 | G11: 1.167 | H11: 0 | I11: 1.167 | J11: 0 | K11: 1.167 | L11: 0 | M11: 1.167 | N11: 0 | O11: 1.167 | P11: 0 | Q11: 1.167 | R11: 0 | T11: 1.167 | U11: =AVERAGE(B11,D11,F11) -> 0 | V11: =AVERAGE(H11,J11,L11) -> 0 | W11: =AVERAGE(N11,P11,R11) -> 0
A12: 1.357 | B12: 0 | C12: 1.357 | D12: 0 | E12: 1.357 | F12: 0 | G12: 1.357 | H12: 0 | I12: 1.357 | J12: 0 | K12: 1.357 | L12: 0 | M12: 1.357 | N12: 0 | O12: 1.357 | P12: 0 | Q12: 1.357 | R12: 0 | T12: 1.357 | U12: =AVERAGE(B12,D12,F12) -> 0 | V12: =AVERAGE(H12,J12,L12) -> 0 | W12: =AVERAGE(N12,P12,R12) -> 0
A13: 1.578 | B13: 0 | C13: 1.578 | D13: 0 | E13: 1.578 | F13: 0 | G13: 1.578 | H13: 0 | I13: 1.578 | J13: 0 | K13: 1.578 | L13: 0 | M13: 1.578 | N13: 0 | O13: 1.578 | P13: 0 | Q13: 1.578 | R13: 0 | T13: 1.578 | U13: =AVERAGE(B13,D13,F13) -> 0 | V13: =AVERAGE(H13,J13,L13) -> 0 | W13: =AVERAGE(N13,P13,R13) -> 0
... A71: 10000 | B71: 0 | C71: 10000 | D71: 0 | E71: 10000 | F71: 0 | G71: 10000 | H71: 0 | I71: 10000 | J71: 0 | K71: 10000 | L71: 0 | M71: 10000 | N71: 0 | O71: 10000 | P71: 0 | Q71: 10000 | R71: 0 | T71: 10000 | U71: =AVERAGE(B71,D71,F71) -> 0 | V71: =AVERAGE(H71,J71,L71) -> 0 | W71: =AVERAGE(N71,P71,R71) -> 0
A73: 0.5R1 | H73: S1 | I73: S2 | J73: S3
A74: Z-Average (nm) | B74: 251.4 | C74: 1.575 | D74: 0.6263 | E74: 249.7 | F74: 252.8 | H74: 251.8 | I74: 249.7 | J74: 252.8
A75: Polydispersity Index (PI) | B75: 0.1889 | C75: 0.005546 | D75: 2.937 | E75: 0.1829 | F75: 0.1938 | H75: 273.3 | I75: 291.4 | J75: 276.1
A76: Peak One Mean by Intensity (nm) | B76: 253.2 | C76: 2.177 | D76: 0.8597 | E76: 250.7 | F76: 254.8 | H76: 347.8 | I76: 339.1 | J76: 347.5
A77: Peak One Area by Intensity (%) | B77: 100 | C77: 0 | D77: 0 | E77: 100 | F77: 100
A79: 0.5R2
A80: Z-Average (nm) | B80: 295.2 | C80: 14.34 | D80: 4.857 | E80: 278.8 | F80: 305.3
A81: Polydispersity Index (PI) | B81: 0.3876 | C81: 0.02875 | D81: 7.418 | E81: 0.3548 | F81: 0.4082
A82: Peak One Mean by Intensity (nm) | B82: 208.7 | C82: 9.986 | D82: 4.784 | E82: 197.5 | F82: 216.4
A83: Peak One Area by Intensity (%) | B83: 100 | C83: 0 | D83: 0 | E83: 100 | F83: 100
A85: 0.5R3
A86: Z-Average (nm) | B86: 344.8 | C86: 4.957 | D86: 1.438 | E86: 339.1 | F86: 347.8
A87: Polydispersity Index (PI) | B87: 0.4237 | C87: 0.02512 | D87: 5.929 | E87: 0.3947 | F87: 0.4396
A88: Peak One Mean by Intensity (nm) | B88: 255.1 | C88: 5.261 | D88: 2.062 | E88: 249.1 | F88: 258.8
A89: Peak One Area by Intensity (%) | B89: 100 | C89: 0 | D89: 0 | E89: 100 | F89: 100

Sheet 0.7 size
A1: Size (d.nm) - 1G_S1_2xCen_20250516_true [Steady state] | B1: Intensity (Percent) - 1G_S1_2xCen_20250516_true [Steady state] | C1: Size (d.nm) - 1G_S1_2xCen_20250516_true [Steady state] | D1: Intensity (Percent) - 1G_S1_2xCen_20250516_true [Steady state] | E1: Size (d.nm) - 1G_S1_2xCen_20250516_true [Steady state] | F1: Intensity (Percent) - 1G_S1_2xCen_20250516_true [Steady state] | G1: Size (d.nm) - 1H_S2_2xCen_20250514 [Steady state] | H1: Intensity (Percent) - 1H_S2_2xCen_20250514 [Steady state] | I1: Size (d.nm) - 1H_S2_2xCen_20250514 [Steady state] | J1: Intensity (Percent) - 1H_S2_2xCen_20250514 [Steady state] | K1: Size (d.nm) - 1H_S2_2xCen_20250514 [Steady state] | L1: Intensity (Percent) - 1H_S2_2xCen_20250514 [Steady state] | M1: Size (d.nm) - 1J_S1_2xCen_20250514_R [Steady state] | N1: Intensity (Percent) - 1J_S1_2xCen_20250514_R [Steady state] | O1: Size (d.nm) - 1J_S1_2xCen_20250514_R [Steady state] | P1: Intensity (Percent) - 1J_S1_2xCen_20250514_R [Steady state] | Q1: Size (d.nm) - 1J_S1_2xCen_20250514_R [Steady state] | R1: Intensity (Percent) - 1J_S1_2xCen_20250514_R [Steady state] | T1: {=A1:A71} -> Size (d.nm) - 1G_S1_2xCen_20250516_true [Steady state] | U1: R1 | V1: R2 | W1: R3
A2: 0.3 | B2: 0 | C2: 0.3 | D2: 0 | E2: 0.3 | F2: 0 | G2: 0.3 | H2: 0 | I2: 0.3 | J2: 0 | K2: 0.3 | L2: 0 | M2: 0.3 | N2: 0 | O2: 0.3 | P2: 0 | Q2: 0.3 | R2: 0 | T2: 0.3 | U2: =AVERAGE(B2,D2,F2) -> 0 | V2: =AVERAGE(H2,J2,L2) -> 0 | W2: =AVERAGE(N2,P2,R2) -> 0
A3: 0.3489 | B3: 0 | C3: 0.3489 | D3: 0 | E3: 0.3489 | F3: 0 | G3: 0.3489 | H3: 0 | I3: 0.3489 | J3: 0 | K3: 0.3489 | L3: 0 | M3: 0.3489 | N3: 0 | O3: 0.3489 | P3: 0 | Q3: 0.3489 | R3: 0 | T3: 0.3489 | U3: =AVERAGE(B3,D3,F3) -> 0 | V3: =AVERAGE(H3,J3,L3) -> 0 | W3: =AVERAGE(N3,P3,R3) -> 0
A4: 0.4057 | B4: 0 | C4: 0.4057 | D4: 0 | E4: 0.4057 | F4: 0 | G4: 0.4057 | H4: 0 | I4: 0.4057 | J4: 0 | K4: 0.4057 | L4: 0 | M4: 0.4057 | N4: 0 | O4: 0.4057 | P4: 0 | Q4: 0.4057 | R4: 0 | T4: 0.4057 | U4: =AVERAGE(B4,D4,F4) -> 0 | V4: =AVERAGE(H4,J4,L4) -> 0 | W4: =AVERAGE(N4,P4,R4) -> 0
A5: 0.4718 | B5: 0 | C5: 0.4718 | D5: 0 | E5: 0.4718 | F5: 0 | G5: 0.4718 | H5: 0 | I5: 0.4718 | J5: 0 | K5: 0.4718 | L5: 0 | M5: 0.4718 | N5: 0 | O5: 0.4718 | P5: 0 | Q5: 0.4718 | R5: 0 | T5: 0.4718 | U5: =AVERAGE(B5,D5,F5) -> 0 | V5: =AVERAGE(H5,J5,L5) -> 0 | W5: =AVERAGE(N5,P5,R5) -> 0
A6: 0.5487 | B6: 0 | C6: 0.5487 | D6: 0 | E6: 0.5487 | F6: 0 | G6: 0.5487 | H6: 0 | I6: 0.5487 | J6: 0 | K6: 0.5487 | L6: 0 | M6: 0.5487 | N6: 0 | O6: 0.5487 | P6: 0 | Q6: 0.5487 | R6: 0 | T6: 0.5487 | U6: =AVERAGE(B6,D6,F6) -> 0 | V6: =AVERAGE(H6,J6,L6) -> 0 | W6: =AVERAGE(N6,P6,R6) -> 0
A7: 0.6381 | B7: 0 | C7: 0.6381 | D7: 0 | E7: 0.6381 | F7: 0 | G7: 0.6381 | H7: 0 | I7: 0.6381 | J7: 0 | K7: 0.6381 | L7: 0 | M7: 0.6381 | N7: 0 | O7: 0.6381 | P7: 0 | Q7: 0.6381 | R7: 0 | T7: 0.6381 | U7: =AVERAGE(B7,D7,F7) -> 0 | V7: =AVERAGE(H7,J7,L7) -> 0 | W7: =AVERAGE(N7,P7,R7) -> 0
A8: 0.742 | B8: 0 | C8: 0.742 | D8: 0 | E8: 0.742 | F8: 0 | G8: 0.742 | H8: 0 | I8: 0.742 | J8: 0 | K8: 0.742 | L8: 0 | M8: 0.742 | N8: 0 | O8: 0.742 | P8: 0 | Q8: 0.742 | R8: 0 | T8: 0.742 | U8: =AVERAGE(B8,D8,F8) -> 0 | V8: =AVERAGE(H8,J8,L8) -> 0 | W8: =AVERAGE(N8,P8,R8) -> 0
A9: 0.8629 | B9: 0 | C9: 0.8629 | D9: 0 | E9: 0.8629 | F9: 0 | G9: 0.8629 | H9: 0 | I9: 0.8629 | J9: 0 | K9: 0.8629 | L9: 0 | M9: 0.8629 | N9: 0 | O9: 0.8629 | P9: 0 | Q9: 0.8629 | R9: 0 | T9: 0.8629 | U9: =AVERAGE(B9,D9,F9) -> 0 | V9: =AVERAGE(H9,J9,L9) -> 0 | W9: =AVERAGE(N9,P9,R9) -> 0
A10: 1.003 | B10: 0 | C10: 1.003 | D10: 0 | E10: 1.003 | F10: 0 | G10: 1.003 | H10: 0 | I10: 1.003 | J10: 0 | K10: 1.003 | L10: 0 | M10: 1.003 | N10: 0 | O10: 1.003 | P10: 0 | Q10: 1.003 | R10: 0 | T10: 1.003 | U10: =AVERAGE(B10,D10,F10) -> 0 | V10: =AVERAGE(H10,J10,L10) -> 0 | W10: =AVERAGE(N10,P10,R10) -> 0
A11: 1.167 | B11: 0 | C11: 1.167 | D11: 0 | E11: 1.167 | F11: 0 | G11: 1.167 | H11: 0 | I11: 1.167 | J11: 0 | K11: 1.167 | L11: 0 | M11: 1.167 | N11: 0 | O11: 1.167 | P11: 0 | Q11: 1.167 | R11: 0 | T11: 1.167 | U11: =AVERAGE(B11,D11,F11) -> 0 | V11: =AVERAGE(H11,J11,L11) -> 0 | W11: =AVERAGE(N11,P11,R11) -> 0
A12: 1.357 | B12: 0 | C12: 1.357 | D12: 0 | E12: 1.357 | F12: 0 | G12: 1.357 | H12: 0 | I12: 1.357 | J12: 0 | K12: 1.357 | L12: 0 | M12: 1.357 | N12: 0 | O12: 1.357 | P12: 0 | Q12: 1.357 | R12: 0 | T12: 1.357 | U12: =AVERAGE(B12,D12,F12) -> 0 | V12: =AVERAGE(H12,J12,L12) -> 0 | W12: =AVERAGE(N12,P12,R12) -> 0
A13: 1.578 | B13: 0 | C13: 1.578 | D13: 0 | E13: 1.578 | F13: 0 | G13: 1.578 | H13: 0 | I13: 1.578 | J13: 0 | K13: 1.578 | L13: 0 | M13: 1.578 | N13: 0 | O13: 1.578 | P13: 0 | Q13: 1.578 | R13: 0 | T13: 1.578 | U13: =AVERAGE(B13,D13,F13) -> 0 | V13: =AVERAGE(H13,J13,L13) -> 0 | W13: =AVERAGE(N13,P13,R13) -> 0
... A71: 10000 | B71: 0 | C71: 10000 | D71: 0 | E71: 10000 | F71: 0 | G71: 10000 | H71: 0 | I71: 10000 | J71: 0 | K71: 10000 | L71: 0 | M71: 10000 | N71: 0 | O71: 10000 | P71: 0 | Q71: 10000 | R71: 0 | T71: 10000 | U71: =AVERAGE(B71,D71,F71) -> 0 | V71: =AVERAGE(H71,J71,L71) -> 0 | W71: =AVERAGE(N71,P71,R71) -> 0
I73: 0.7R1 | P73: S1 | Q73: S2 | R73: S3
I74: Z-Average (nm) | J74: 301.8 | K74: 5.476 | L74: 1.815 | M74: 296.9 | N74: 307.7 | P74: 339.1 | Q74: 307.7 | R74: 313.5
I75: Polydispersity Index (PI) | J75: 0.1929 | K75: 0.07923 | L75: 41.07 | M75: 0.1014 | N75: 0.2387 | P75: 251.4 | Q75: 247 | R75: 250.8
I76: Peak One Mean by Intensity (nm) | J76: 300.3 | K76: 18.01 | L76: 5.996 | M76: 288.8 | N76: 321.1 | P76: 304.3 | Q76: 320.9 | R76: 289.4
I77: Peak One Area by Intensity (%) | J77: 100 | K77: 0 | L77: 0 | M77: 100 | N77: 100
I79: 0.7R2
I80: Z-Average (nm) | J80: 249.7 | K80: 2.369 | L80: 0.9487 | M80: 247 | N80: 251.4
I81: Polydispersity Index (PI) | J81: 0.1626 | K81: 0.04237 | L81: 26.05 | M81: 0.1137 | N81: 0.1879
I82: Peak One Mean by Intensity (nm) | J82: 254.6 | K82: 13.15 | L82: 5.166 | M82: 246.7 | N82: 269.7
I83: Peak One Area by Intensity (%) | J83: 100 | K83: 0 | L83: 0 | M83: 100 | N83: 100
I85: 0.7R3
I86: Z-Average (nm) | J86: 280.2 | K86: 8.067 | L86: 2.88 | M86: 274.6 | N86: 289.4
I87: Polydispersity Index (PI) | J87: 0.359 | K87: 0.02468 | L87: 6.875 | M87: 0.3306 | N87: 0.3754
I88: Peak One Mean by Intensity (nm) | J88: 233.1 | K88: 11.02 | L88: 4.725 | M88: 220.4 | N88: 239.7
I89: Peak One Area by Intensity (%) | J89: 100 | K89: 0 | L89: 0 | M89: 100 | N89: 100

Sheet 2.7 size
A1: Size (d.nm) - 3E_S2_2xCen_20250514 [Steady state] | B1: Intensity (Percent) - 3E_S2_2xCen_20250514 [Steady state] | C1: Size (d.nm) - 3E_S2_2xCen_20250514 [Steady state] | D1: Intensity (Percent) - 3E_S2_2xCen_20250514 [Steady state] | E1: Size (d.nm) - 3E_S2_2xCen_20250514 [Steady state] | F1: Intensity (Percent) - 3E_S2_2xCen_20250514 [Steady state] | G1: Size (d.nm) - 3E_S2_2xCen_20250514 [Steady state] | H1: Intensity (Percent) - 3E_S2_2xCen_20250514 [Steady state] | I1: Size (d.nm) - 3E_S2_2xCen_20250514 [Steady state] | J1: Intensity (Percent) - 3E_S2_2xCen_20250514 [Steady state] | K1: Size (d.nm) - 3F_S2_2xCen_20250514 [Steady state] | L1: Intensity (Percent) - 3F_S2_2xCen_20250514 [Steady state] | M1: Size (d.nm) - 3F_S2_2xCen_20250514 [Steady state] | N1: Intensity (Percent) - 3F_S2_2xCen_20250514 [Steady state] | O1: Size (d.nm) - 3F(2)_S1_2xCen_20250519 [Steady state] | P1: Intensity (Percent) - 3F(2)_S1_2xCen_20250519 [Steady state] | Q1: Size (d.nm) - 3F(2)_S1_2xCen_20250519 [Steady state] | R1: Intensity (Percent) - 3F(2)_S1_2xCen_20250519 [Steady state] | S1: Size (d.nm) - 3F(2)_S1_2xCen_20250519 [Steady state] | T1: Intensity (Percent) - 3F(2)_S1_2xCen_20250519 [Steady state] | U1: Size (d.nm) - 3F(2)_S1_2xCen_20250519 [Steady state] | V1: Intensity (Percent) - 3F(2)_S1_2xCen_20250519 [Steady state] | Y1: {=A1:A71} -> Size (d.nm) - 3E_S2_2xCen_20250514 [Steady state] | Z1: R1 | AA1: R2 | AB1: R3
A2: 0.3 | B2: 0 | C2: 0.3 | D2: 0 | E2: 0.3 | F2: 0 | G2: 0.3 | H2: 0 | I2: 0.3 | J2: 0 | K2: 0.3 | L2: 0 | M2: 0.3 | N2: 0 | O2: 0.3 | P2: 0 | Q2: 0.3 | R2: 0 | S2: 0.3 | T2: 0 | U2: 0.3 | V2: 0 | Y2: 0.3 | Z2: =AVERAGE(B2,D2,F2) -> 0 | AA2: =AVERAGE(H2,J2,L2) -> 0 | AB2: =AVERAGE(N2,P2,V2) -> 0
A3: 0.3489 | B3: 0 | C3: 0.3489 | D3: 0 | E3: 0.3489 | F3: 0 | G3: 0.3489 | H3: 0 | I3: 0.3489 | J3: 0 | K3: 0.3489 | L3: 0 | M3: 0.3489 | N3: 0 | O3: 0.3489 | P3: 0 | Q3: 0.3489 | R3: 0 | S3: 0.3489 | T3: 0 | U3: 0.3489 | V3: 0 | Y3: 0.3489 | Z3: =AVERAGE(B3,D3,F3) -> 0 | AA3: =AVERAGE(H3,J3,L3) -> 0 | AB3: =AVERAGE(N3,P3,V3) -> 0
A4: 0.4057 | B4: 0 | C4: 0.4057 | D4: 0 | E4: 0.4057 | F4: 0 | G4: 0.4057 | H4: 0 | I4: 0.4057 | J4: 0 | K4: 0.4057 | L4: 0 | M4: 0.4057 | N4: 0 | O4: 0.4057 | P4: 0 | Q4: 0.4057 | R4: 0 | S4: 0.4057 | T4: 0 | U4: 0.4057 | V4: 0 | Y4: 0.4057 | Z4: =AVERAGE(B4,D4,F4) -> 0 | AA4: =AVERAGE(H4,J4,L4) -> 0 | AB4: =AVERAGE(N4,P4,V4) -> 0
A5: 0.4718 | B5: 0 | C5: 0.4718 | D5: 0 | E5: 0.4718 | F5: 0 | G5: 0.4718 | H5: 0 | I5: 0.4718 | J5: 0 | K5: 0.4718 | L5: 0 | M5: 0.4718 | N5: 0 | O5: 0.4718 | P5: 0 | Q5: 0.4718 | R5: 0 | S5: 0.4718 | T5: 0 | U5: 0.4718 | V5: 0 | Y5: 0.4718 | Z5: =AVERAGE(B5,D5,F5) -> 0 | AA5: =AVERAGE(H5,J5,L5) -> 0 | AB5: =AVERAGE(N5,P5,V5) -> 0
A6: 0.5487 | B6: 0 | C6: 0.5487 | D6: 0 | E6: 0.5487 | F6: 0 | G6: 0.5487 | H6: 0 | I6: 0.5487 | J6: 0 | K6: 0.5487 | L6: 0 | M6: 0.5487 | N6: 0 | O6: 0.5487 | P6: 0 | Q6: 0.5487 | R6: 0 | S6: 0.5487 | T6: 0 | U6: 0.5487 | V6: 0 | Y6: 0.5487 | Z6: =AVERAGE(B6,D6,F6) -> 0 | AA6: =AVERAGE(H6,J6,L6) -> 0 | AB6: =AVERAGE(N6,P6,V6) -> 0
A7: 0.6381 | B7: 0 | C7: 0.6381 | D7: 0 | E7: 0.6381 | F7: 0 | G7: 0.6381 | H7: 0 | I7: 0.6381 | J7: 0 | K7: 0.6381 | L7: 0 | M7: 0.6381 | N7: 0 | O7: 0.6381 | P7: 0 | Q7: 0.6381 | R7: 0 | S7: 0.6381 | T7: 0 | U7: 0.6381 | V7: 0 | Y7: 0.6381 | Z7: =AVERAGE(B7,D7,F7) -> 0 | AA7: =AVERAGE(H7,J7,L7) -> 0 | AB7: =AVERAGE(N7,P7,V7) -> 0
A8: 0.742 | B8: 0 | C8: 0.742 | D8: 0 | E8: 0.742 | F8: 0 | G8: 0.742 | H8: 0 | I8: 0.742 | J8: 0 | K8: 0.742 | L8: 0 | M8: 0.742 | N8: 0 | O8: 0.742 | P8: 0 | Q8: 0.742 | R8: 0 | S8: 0.742 | T8: 0 | U8: 0.742 | V8: 0 | Y8: 0.742 | Z8: =AVERAGE(B8,D8,F8) -> 0 | AA8: =AVERAGE(H8,J8,L8) -> 0 | AB8: =AVERAGE(N8,P8,V8) -> 0
A9: 0.8629 | B9: 0 | C9: 0.8629 | D9: 0 | E9: 0.8629 | F9: 0 | G9: 0.8629 | H9: 0 | I9: 0.8629 | J9: 0 | K9: 0.8629 | L9: 0 | M9: 0.8629 | N9: 0 | O9: 0.8629 | P9: 0 | Q9: 0.8629 | R9: 0 | S9: 0.8629 | T9: 0 | U9: 0.8629 | V9: 0 | Y9: 0.8629 | Z9: =AVERAGE(B9,D9,F9) -> 0 | AA9: =AVERAGE(H9,J9,L9) -> 0 | AB9: =AVERAGE(N9,P9,V9) -> 0
A10: 1.003 | B10: 0 | C10: 1.003 | D10: 0 | E10: 1.003 | F10: 0 | G10: 1.003 | H10: 0 | I10: 1.003 | J10: 0 | K10: 1.003 | L10: 0 | M10: 1.003 | N10: 0 | O10: 1.003 | P10: 0 | Q10: 1.003 | R10: 0 | S10: 1.003 | T10: 0 | U10: 1.003 | V10: 0 | Y10: 1.003 | Z10: =AVERAGE(B10,D10,F10) -> 0 | AA10: =AVERAGE(H10,J10,L10) -> 0 | AB10: =AVERAGE(N10,P10,V10) -> 0
A11: 1.167 | B11: 0 | C11: 1.167 | D11: 0 | E11: 1.167 | F11: 0 | G11: 1.167 | H11: 0 | I11: 1.167 | J11: 0 | K11: 1.167 | L11: 0 | M11: 1.167 | N11: 0 | O11: 1.167 | P11: 0 | Q11: 1.167 | R11: 0 | S11: 1.167 | T11: 0 | U11: 1.167 | V11: 0 | Y11: 1.167 | Z11: =AVERAGE(B11,D11,F11) -> 0 | AA11: =AVERAGE(H11,J11,L11) -> 0 | AB11: =AVERAGE(N11,P11,V11) -> 0
A12: 1.357 | B12: 0 | C12: 1.357 | D12: 0 | E12: 1.357 | F12: 0 | G12: 1.357 | H12: 0 | I12: 1.357 | J12: 0 | K12: 1.357 | L12: 0 | M12: 1.357 | N12: 0 | O12: 1.357 | P12: 0 | Q12: 1.357 | R12: 0 | S12: 1.357 | T12: 0 | U12: 1.357 | V12: 0 | Y12: 1.357 | Z12: =AVERAGE(B12,D12,F12) -> 0 | AA12: =AVERAGE(H12,J12,L12) -> 0 | AB12: =AVERAGE(N12,P12,V12) -> 0
A13: 1.578 | B13: 0 | C13: 1.578 | D13: 0 | E13: 1.578 | F13: 0 | G13: 1.578 | H13: 0 | I13: 1.578 | J13: 0 | K13: 1.578 | L13: 0 | M13: 1.578 | N13: 0 | O13: 1.578 | P13: 0 | Q13: 1.578 | R13: 0 | S13: 1.578 | T13: 0 | U13: 1.578 | V13: 0 | Y13: 1.578 | Z13: =AVERAGE(B13,D13,F13) -> 0 | AA13: =AVERAGE(H13,J13,L13) -> 0 | AB13: =AVERAGE(N13,P13,V13) -> 0
... A71: 10000 | B71: 0 | C71: 10000 | D71: 0 | E71: 10000 | F71: 0 | G71: 10000 | H71: 0 | I71: 10000 | J71: 0 | K71: 10000 | L71: 0 | M71: 10000 | N71: 0 | O71: 10000 | P71: 0 | Q71: 10000 | R71: 0 | S71: 10000 | T71: 0 | U71: 10000 | V71: 0 | Y71: 10000 | Z71: =AVERAGE(B71,D71,F71) -> 0 | AA71: =AVERAGE(H71,J71,L71) -> 0 | AB71: =AVERAGE(N71,P71,V71) -> 0
E73: 2.3R1 | L73: S1 | M73: S2 | N73: S3
E74: Z-Average (nm) | F74: 230.6 | G74: 1.193 | H74: 0.5173 | I74: 229.3 | J74: 231.5 | L74: 231.5 | M74: 231.1 | N74: 229.3
E75: Polydispersity Index (PI) | F75: 0.1991 | G75: 0.01348 | H75: 6.77 | I75: 0.1838 | J75: 0.2092 | L75: 245.4 | M75: 275.6 | N75: 251.8
E76: Peak One Mean by Intensity (nm) | F76: 226.2 | G76: 0.6757 | H76: 0.2986 | I76: 225.5 | J76: 226.9 | L76: 432.5 | M76: 396.7 | N76: 421.3
E77: Peak One Area by Intensity (%) | F77: 100 | G77: 0 | H77: 0 | I77: 100 | J77: 100
E79: 2.3R2
E80: Z-Average (nm) | F80: 283.6 | G80: 38.38 | H80: 13.53 | I80: 249.8 | J80: 325.3
E81: Polydispersity Index (PI) | F81: 0.3262 | G81: 0.2287 | H81: 70.09 | I81: 0.07043 | J81: 0.5108
E82: Peak One Mean by Intensity (nm) | F82: 224.8 | G82: 34.58 | H82: 15.39 | I82: 195.6 | J82: 263
E83: Peak One Area by Intensity (%) | F83: 100 | G83: 0 | H83: 0 | I83: 100 | J83: 100
E85: 2.3R3
E86: Z-Average (nm) | F86: 416.8 | G86: 18.33 | H86: 4.397 | I86: 396.7 | J86: 432.5
E87: Polydispersity Index (PI) | F87: 0.5085 | G87: 0.07083 | H87: 13.93 | I87: 0.4376 | J87: 0.5793
E88: Peak One Mean by Intensity (nm) | F88: 235.1 | G88: 10.03 | H88: 4.268 | I88: 223.5 | J88: 241.7
E89: Peak One Area by Intensity (%) | F89: 100 | G89: 0 | H89: 0 | I89: 100 | J89: 100
